Workbook
Name \a: #REF!
Name \a: #REF!
Name \a: #REF!
Name \a: #REF!
Name \a: #REF!
Name \a: #REF!
Name \a: #REF!
Name \a: #REF!
Name \a: #REF!
Name \a: #REF!
Name \a: #REF!
Name \a: #REF!
Name \a: #REF!
Name \a: #REF!
Name \a: #REF!
Name \a: #REF!
Name \a: #REF!
Name \a: #REF!
Name \a: #REF!
Name \b: #REF!
Name \b: #REF!
Name \b: #REF!
Name \b: #REF!
Name \b: #REF!
Name \b: #REF!
Name \b: #REF!
Name \b: #REF!
Name \b: #REF!
Name \b: #REF!
Name \b: #REF!
Name \b: #REF!
Name \b: #REF!
Name \b: #REF!
Name \b: #REF!
Name \b: #REF!
Name \b: #REF!
Name \b: #REF!
Name \b: #REF!
Name \c: #REF!
Name \c: #REF!
Name \c: #REF!
Name \c: #REF!
Name \c: #REF!
Name \c: #REF!
Name \c: #REF!
Name \c: #REF!
Name \c: #REF!
Name \c: #REF!
Name \c: #REF!
Name \c: #REF!
Name \c: #REF!
Name \c: #REF!
Name \c: #REF!
Name \c: #REF!
Name \c: #REF!
Name \c: #REF!
Name \c: #REF!
Name \d: #REF!
Name \d: #REF!
Name \d: #REF!

Sheet Equibase
C1: Input | D1: =IF(SUM(B3:B5023)=0,"✓","×") -> ✓ | E1: 7 | H1: 37316 | I1: 37681 | J1: 38047 | K1: 38412 | L1: 38777 | M1: 39142 | N1: 39508 | O1: 39873 | P1: 40238 | Q1: 40603 | R1: 40969 | S1: 41334 | T1: 41699 | U1: 42064 | V1: 42430 | W1: 42795 | X1: 43160 | Y1: 43525 | Z1: 43891 | AA1: 44256 | AB1: 44621 | AC1: 44986 | AD1: 45352 | AE1: 45717 | AF1: 46082 | AG1: 46447 | AH1: 46813 | AI1: 47178 | AJ1: 47543
A2: Item Codes | C2: Calculated | E2: Actual/Estimate | F2: UNITS | H2: =IF(H1<=$G$21,"A","E") -> A | I2: =IF(I1<=$G$21,"A","E") -> A | J2: =IF(J1<=$G$21,"A","E") -> A | K2: =IF(K1<=$G$21,"A","E") -> A | L2: =IF(L1<=$G$21,"A","E") -> A | M2: =IF(M1<=$G$21,"A","E") -> A | N2: =IF(N1<=$G$21,"A","E") -> A | O2: =IF(O1<=$G$21,"A","E") -> A | ... AE2: =IF(AE1<=$G$21,"A","E") -> A | AF2: A | AG2: =IF(AG1<=$G$21,"A","E") -> E | AH2: =IF(AH1<=$G$21,"A","E") -> E | AI2: =IF(AI1<=$G$21,"A","E") -> E | AJ2: =IF(AJ1<=$G$21,"A","E") -> E
C3: Input | E3: Months | H3: 12 | I3: 12 | J3: 12 | K3: 12 | L3: 12 | M3: 12 | N3: 12 | O3: 12 | P3: 12 | Q3: 12 | R3: 12 | S3: 12 | T3: 12 | U3: 12 | V3: 12 | W3: 12 | X3: 12 | Y3: 12 | Z3: 12 | AA3: 12 | AB3: 12 | AC3: 12 | AD3: 12 | AE3: 12 | AF3: 12 | AG3: 12 | AH3: 12 | AI3: 12 | AJ3: 12
C4: Input | E4: Period Type | H4: Annual | I4: Annual | J4: Annual | K4: Annual | L4: Annual | M4: Annual | N4: Annual | O4: Annual | P4: Annual | Q4: Annual | R4: Annual | S4: Annual | T4: Annual | U4: Annual | V4: Annual | W4: Annual | X4: Annual | Y4: Annual | Z4: Annual | AA4: Annual | AB4: Annual | AC4: Annual | AD4: Annual | AE4: Annual | AF4: Annual | AG4: Annual | AH4: Annual | AI4: Annual | AJ4: Annual
C5: Input | E5: Year End | H5: =H1 -> 37316 | I5: =I1 -> 37681 | J5: =J1 -> 38047 | K5: =K1 -> 38412 | L5: =L1 -> 38777 | M5: =M1 -> 39142 | N5: =N1 -> 39508 | O5: =O1 -> 39873 | ... AJ5: =AJ1 -> 47543
C6: Calculated | E6: Year Label | H6: =IF(MONTH(H1)=12,"CY"&TEXT(H1,"YY"),"FY"&TEXT(H1,"YY"))&H2 -> FY02A | I6: =IF(MONTH(I1)=12,"CY"&TEXT(I1,"YY"),"FY"&TEXT(I1,"YY"))&I2 -> FY03A | J6: =IF(MONTH(J1)=12,"CY"&TEXT(J1,"YY"),"FY"&TEXT(J1,"YY"))&J2 -> FY04A | K6: =IF(MONTH(K1)=12,"CY"&TEXT(K1,"YY"),"FY"&TEXT(K1,"YY"))&K2 -> FY05A | L6: =IF(MONTH(L1)=12,"CY"&TEXT(L1,"YY"),"FY"&TEXT(L1,"YY"))&L2 -> FY06A | M6: =IF(MONTH(M1)=12,"CY"&TEXT(M1,"YY"),"FY"&TEXT(M1,"YY"))&M2 -> FY07A | N6: =IF(MONTH(N1)=12,"CY"&TEXT(N1,"YY"),"FY"&TEXT(N1,"YY"))&N2 -> FY08A | O6: =IF(MONTH(O1)=12,"CY"&TEXT(O1,"YY"),"FY"&TEXT(O1,"YY"))&O2 -> FY09A | ... AJ6: =IF(MONTH(AJ1)=12,"CY"&TEXT(AJ1,"YY"),"FY"&TEXT(AJ1,"YY"))&AJ2 -> FY30E
A7: EQ_COMPANY_NAME | C7: Calculated | E7: Full Name Of Company | G7: JSW Infrastructure | H7: <-- Use EQUIDATA
A8: COMPANY_SHORT_NAME | C8: Calculated | E8: Short Name For Company | G8: JSW Infra | H8: <-- Use EQUIDATA
A9: EQ_SECTOR_NAME | C9: Calculated | E9: Sector | G9: Infrastructure | H9: <-- Use EQUIDATA
A10: EQ_INDUSTRY_NAME | C10: Calculated | E10: Industry | H10: <-- Use EQUIDATA
A11: EQ_SUBINDUSTRY_NAME | C11: Calculated | E11: Sub-Industry | H11: <-- Use EQUIDATA
A12: BB | C12: Input | E12: Bloomberg code | G12: JSWINFRA IN EQUITY | H12: <-- Analyst to enter
A13: RATING | C13: Input | E13: Recommendation | G13: ADD | H13: <-- Analyst to enter
A14: PRIOR_RATING | C14: Calculated | E14: Prior Rating | H14: <-- Use EQUIDATA
A15: DATE_RATING_CHG | C15: Input | E15: Date of Recommendation Change | H15: <-- Analyst to enter
A16: FREE_FLOAT | C16: Calculated | E16: Free Float | F16: % | H16: <-- Use EQUIDATA
A17: CMP | C17: Calculated | E17: Share Price (Rs) | G17: 310 | H17: <-- Use EQUIDATA
A18: EQ_PXDT | C18: Calculated | E18: Price Date | G18: 46168 | H18: <-- Use EQUIDATA
A19: PRICE_TARGET | C19: Input | E19: Target Price (Rs) | G19: 290 | H19: <-- Analyst to enter
A20: SHARES_OS_CUR | C20: Input | E20: Current Shares Out (m) | F20: mn | G20: {=_xll.EQUIDATA($G$12,$A20,"private")} -> 2100.002 | H20: <-- Analyst to enter
A21: LAST_REPORT_DATE | C21: Input | E21: Last Reported Result Date | G21: 46021 | H21: <-- Analyst to enter
A22: FISCAL_YEAR_END | C22: Input | E22: Fiscal Year End | H22: <-- Analyst to enter
A23: COMPANY_TYPE | C23: Input | E23: Consolidated/Standalone | H23: <-- Analyst to enter
A24: BSE_SENSEX | C24: Calculated | E24: BSE Sensex | H24: <-- Use EQUIDATA
A25: INR CURNCY | C25: Calculated | E25: Exchange rate (Rs:USD) | H25: <-- Use EQUIDATA
A26: FIFTY_TWO_WEEK_HIGH | C26: Calculated | E26: 52-week High | G26: {=_xll.EQUIDATA($G$12,$A26,"private")} -> 349 | H26: <-- Use EQUIDATA
A27: FIFTY_TWO_WEEK_LOW | C27: Calculated | E27: 52-week Low | G27: {=_xll.EQUIDATA($G$12,$A27,"private")} -> 233.42 | H27: <-- Use EQUIDATA
A28: CURR_MKT_CAP_RS | C28: Calculated | E28: Current Market cap | G28: =NewFinSumm!I76 -> 731745 | H28: <-- Use EQUIDATA
A29: CURR_MKT_CAP_USD | C29: Calculated | E29: Current Market cap USD | G29: {=_xll.EQUIDATA($G$12,$A29,"private")} -> 6982.3877 | H29: <-- Use EQUIDATA
A30: TABLE1_SCALE | C30: Input | E30: Financial Summary (scale) | G30: Rs mn
A31: TABLE2_SCALE | C31: Input | E31: Income Statement (scale) | G31: Rs mn
A32: TABLE3_SCALE | C32: Input | E32: Balance Sheet (scale) | G32: Rs mn
A33: TABLE4_SCALE | C33: Input | E33: Cash Flow (scale) | G33: Rs mn
A34: TABLE5_SCALE | C34: Input | E34: Old vs. New Table (scale) | G34: Rs mn
E37: Profit & Loss statement
A38: IS_GR_SALES | B38: =IF(IF(D38="+",MIN(H38:IU38)>=0,IF(D38="-",MAX(H38:IU38)<=0,TRUE)),"",1) | C38: Input | D38: + | E38: Gross Sales | F38: mn
A39: IS_DUTIES | B39: =IF(IF(D39="+",MIN(H39:IU39)>=0,IF(D39="-",MAX(H39:IU39)<=0,TRUE)),"",1) | C39: Input | D39: + | E39: Less: Duties | F39: mn
A40: IS_NET_SALES | C40: Calculated | D40: ● | E40: Net Sales | F40: mn | X40: =Consol!G16 -> 9980.936 | Y40: =Consol!H16 -> 10802.602 | Z40: =Consol!I16 -> 11431.453 | AA40: =Consol!J16 -> 16035.705 | AB40: =Consol!K16 -> 22730.588 | AC40: =Consol!L16 -> 31947.396 | AD40: =Consol!M16 -> 37628.9 | AE40: =Consol!N16 -> 44761.4 | ... AJ40: =Consol!S16 -> 188550.74
A41: IS_NET_SALES_USD | B41: =IF(IF(D41="+",MIN(H41:IU41)>=0,IF(D41="-",MAX(H41:IU41)<=0,TRUE)),"",1) | C41: Input | D41: + | E41: Net Sales ($) | F41: mn
A42: IS_OOP_INC | B42: =IF(IF(D42="+",MIN(H42:IU42)>=0,IF(D42="-",MAX(H42:IU42)<=0,TRUE)),"",1) | C42: Input | D42: + | E42: Other Operating Income | F42: mn
...

Sheet EquibaseQTR
C1: Input | D1: =IF(SUM(B3:B5023)=0,"✓","×") -> ✓ | E1: 7 | H1: 41791 | I1: =EOMONTH(H1,2)+1 -> 41883 | J1: =EOMONTH(I1,2)+1 -> 41974 | K1: =EOMONTH(J1,2)+1 -> 42064 | L1: =EOMONTH(K1,2)+1 -> 42156 | M1: =EOMONTH(L1,2)+1 -> 42248 | N1: =EOMONTH(M1,2)+1 -> 42339 | O1: =EOMONTH(N1,2)+1 -> 42430 | P1: =EOMONTH(O1,2)+1 -> 42522 | ... BB1: =EOMONTH(BA1,2)+1 -> 45992
A2: Item Codes | C2: Calculated | E2: Actual/Estimate | F2: UNITS | H2: =IF(H1<=$G$21,"A","E") -> A | I2: =IF(I1<=$G$21,"A","E") -> A | J2: =IF(J1<=$G$21,"A","E") -> A | K2: =IF(K1<=$G$21,"A","E") -> A | L2: =IF(L1<=$G$21,"A","E") -> A | M2: =IF(M1<=$G$21,"A","E") -> A | N2: =IF(N1<=$G$21,"A","E") -> A | O2: =IF(O1<=$G$21,"A","E") -> A | ... AZ2: =IF(AZ1<=$G$21,"A","E") -> A | BA2: A | BB2: A
C3: Input | E3: Months | H3: 3 | I3: 3 | J3: 3 | K3: 3 | L3: 3 | M3: 3 | N3: 3 | O3: 3 | P3: 3 | Q3: 3 | R3: 3 | S3: 3 | T3: 3 | U3: 3 | V3: 3 | W3: 3 | X3: 3 | Y3: 3 | Z3: 3 | AA3: 3 | AB3: 3 | AC3: 3 | AD3: 3 | AE3: 3 | AF3: 3 | AG3: 3 | AH3: 3 | AI3: 3 | AJ3: 3 | AK3: 3 | AL3: 3 | AM3: 3 | AN3: 3 | AO3: 3 | AP3: 3 | AQ3: 3 | AR3: 3 | AS3: 3 | AT3: 3 | AU3: 3 | AV3: 3 | AW3: 3 | AX3: 3 | AY3: 3 | AZ3: 3 | BA3: 3 | BB3: 3
C4: Input | E4: Period Type | H4: Quarterly | I4: Quarterly | J4: Quarterly | K4: Quarterly | L4: Quarterly | M4: Quarterly | N4: Quarterly | O4: Quarterly | P4: Quarterly | Q4: Quarterly | R4: Quarterly | S4: Quarterly | T4: Quarterly | U4: Quarterly | V4: Quarterly | W4: Quarterly | X4: Quarterly | Y4: Quarterly | Z4: Quarterly | AA4: Quarterly | AB4: Quarterly | AC4: Quarterly | AD4: Quarterly | AE4: Quarterly | AF4: Quarterly | AG4: Quarterly | AH4: Quarterly | AI4: Quarterly | AJ4: Quarterly | AK4: Quarterly | AL4: Quarterly | AM4: Quarterly | AN4: Quarterly | AO4: Quarterly | AP4: Quarterly | AQ4: Quarterly | AR4: Quarterly | AS4: Quarterly | AT4: Quarterly | AU4: Quarterly | AV4: Quarterly | AW4: Quarterly | AX4: Quarterly | AY4: Quarterly | AZ4: Quarterly | BA4: Quarterly | BB4: Quarterly
C5: Input | E5: Year End | H5: =H1 -> 41791 | I5: =I1 -> 41883 | J5: =J1 -> 41974 | K5: =K1 -> 42064 | L5: =L1 -> 42156 | M5: =M1 -> 42248 | N5: =N1 -> 42339 | O5: =O1 -> 42430 | ... BB5: =BB1 -> 45992
C6: Calculated | E6: Year Label | H6: =_xlfn.CONCAT((IF(MONTH(H1)=3,4,IF(MONTH(H1)=6,1,IF(MONTH(H1)=9,2,3)))),"Q",IF(MONTH(H1)=12,"FY"&TEXT(DATE(YEAR(H1)+1,1,1),"YY"),"FY"&TEXT(DATE(YEAR(H1)+IF(MONTH(H1)>=4,1,0),1,1),"YY"))&H2) -> 1QFY15A | I6: =_xlfn.CONCAT((IF(MONTH(I1)=3,4,IF(MONTH(I1)=6,1,IF(MONTH(I1)=9,2,3)))),"Q",IF(MONTH(I1)=12,"FY"&TEXT(DATE(YEAR(I1)+1,1,1),"YY"),"FY"&TEXT(DATE(YEAR(I1)+IF(MONTH(I1)>=4,1,0),1,1),"YY"))&I2) -> 2QFY15A | J6: =_xlfn.CONCAT((IF(MONTH(J1)=3,4,IF(MONTH(J1)=6,1,IF(MONTH(J1)=9,2,3)))),"Q",IF(MONTH(J1)=12,"FY"&TEXT(DATE(YEAR(J1)+1,1,1),"YY"),"FY"&TEXT(DATE(YEAR(J1)+IF(MONTH(J1)>=4,1,0),1,1),"YY"))&J2) -> 3QFY15A | K6: =_xlfn.CONCAT((IF(MONTH(K1)=3,4,IF(MONTH(K1)=6,1,IF(MONTH(K1)=9,2,3)))),"Q",IF(MONTH(K1)=12,"FY"&TEXT(DATE(YEAR(K1)+1,1,1),"YY"),"FY"&TEXT(DATE(YEAR(K1)+IF(MONTH(K1)>=4,1,0),1,1),"YY"))&K2) -> 4QFY15A | L6: =_xlfn.CONCAT((IF(MONTH(L1)=3,4,IF(MONTH(L1)=6,1,IF(MONTH(L1)=9,2,3)))),"Q",IF(MONTH(L1)=12,"FY"&TEXT(DATE(YEAR(L1)+1,1,1),"YY"),"FY"&TEXT(DATE(YEAR(L1)+IF(MONTH(L1)>=4,1,0),1,1),"YY"))&L2) -> 1QFY16A | M6: =_xlfn.CONCAT((IF(MONTH(M1)=3,4,IF(MONTH(M1)=6,1,IF(MONTH(M1)=9,2,3)))),"Q",IF(MONTH(M1)=12,"FY"&TEXT(DATE(YEAR(M1)+1,1,1),"YY"),"FY"&TEXT(DATE(YEAR(M1)+IF(MONTH(M1)>=4,1,0),1,1),"YY"))&M2) -> 2QFY16A | N6: =_xlfn.CONCAT((IF(MONTH(N1)=3,4,IF(MONTH(N1)=6,1,IF(MONTH(N1)=9,2,3)))),"Q",IF(MONTH(N1)=12,"FY"&TEXT(DATE(YEAR(N1)+1,1,1),"YY"),"FY"&TEXT(DATE(YEAR(N1)+IF(MONTH(N1)>=4,1,0),1,1),"YY"))&N2) -> 3QFY16A | O6: =_xlfn.CONCAT((IF(MONTH(O1)=3,4,IF(MONTH(O1)=6,1,IF(MONTH(O1)=9,2,3)))),"Q",IF(MONTH(O1)=12,"FY"&TEXT(DATE(YEAR(O1)+1,1,1),"YY"),"FY"&TEXT(DATE(YEAR(O1)+IF(MONTH(O1)>=4,1,0),1,1),"YY"))&O2) -> 4QFY16A | ... BB6: =_xlfn.CONCAT((IF(MONTH(BB1)=3,4,IF(MONTH(BB1)=6,1,IF(MONTH(BB1)=9,2,3)))),"Q",IF(MONTH(BB1)=12,"FY"&TEXT(DATE(YEAR(BB1)+1,1,1),"YY"),"FY"&TEXT(DATE(YEAR(BB1)+IF(MONTH(BB1)>=4,1,0),1,1),"YY"))&BB2) -> 3QFY26A
A7: EQ_COMPANY_NAME | C7: Calculated | E7: Full Name Of Company | G7: JSW Infrastructure | H7: <-- Use EQUIDATA
A8: COMPANY_SHORT_NAME | C8: Calculated | E8: Short Name For Company | G8: JSW Infra | H8: <-- Use EQUIDATA
A9: EQ_SECTOR_NAME | C9: Calculated | E9: Sector | G9: Infrastructure | H9: <-- Use EQUIDATA
A10: EQ_INDUSTRY_NAME | C10: Calculated | E10: Industry | H10: <-- Use EQUIDATA
A11: EQ_SUBINDUSTRY_NAME | C11: Calculated | E11: Sub-Industry | H11: <-- Use EQUIDATA
A12: BB | C12: Input | E12: Bloomberg code | G12: JSWINFRA IN EQUITY | H12: <-- Analyst to enter
A13: RATING | C13: Input | E13: Recommendation | G13: ADD | H13: <-- Analyst to enter
A14: PRIOR_RATING | C14: Calculated | E14: Prior Rating | H14: <-- Use EQUIDATA
A15: DATE_RATING_CHG | C15: Input | E15: Date of Recommendation Change | H15: <-- Analyst to enter
A16: FREE_FLOAT | C16: Calculated | E16: Free Float | F16: % | H16: <-- Use EQUIDATA
A17: CMP | C17: Calculated | E17: Share Price (Rs) | G17: 310 | H17: <-- Use EQUIDATA
A18: EQ_PXDT | C18: Calculated | E18: Price Date | G18: 46038 | H18: <-- Use EQUIDATA
A19: PRICE_TARGET | C19: Input | E19: Target Price (Rs) | G19: 290 | H19: <-- Analyst to enter
A20: SHARES_OS_CUR | C20: Input | E20: Current Shares Out (m) | F20: mn | G20: {=_xll.EQUIDATA($G$12,$A20,"private")} -> 2100.002 | H20: <-- Analyst to enter
A21: LAST_REPORT_DATE | C21: Input | E21: Last Reported Result Date | G21: 45930 | H21: <-- Analyst to enter
A22: FISCAL_YEAR_END | C22: Input | E22: Fiscal Year End | H22: <-- Analyst to enter
A23: COMPANY_TYPE | C23: Input | E23: Consolidated/Standalone | H23: <-- Analyst to enter
A24: BSE_SENSEX | C24: Calculated | E24: BSE Sensex | H24: <-- Use EQUIDATA
A25: INR CURNCY | C25: Calculated | E25: Exchange rate (Rs:USD) | H25: <-- Use EQUIDATA
A26: FIFTY_TWO_WEEK_HIGH | C26: Calculated | E26: 52-week High | G26: {=_xll.EQUIDATA($G$12,$A26,"private")} -> 349 | H26: <-- Use EQUIDATA
A27: FIFTY_TWO_WEEK_LOW | C27: Calculated | E27: 52-week Low | G27: {=_xll.EQUIDATA($G$12,$A27,"private")} -> 233.42 | H27: <-- Use EQUIDATA
A28: CURR_MKT_CAP_RS | C28: Calculated | E28: Current Market cap | G28: =NewFinSumm!I76 -> 731745 | H28: <-- Use EQUIDATA
A29: CURR_MKT_CAP_USD | C29: Calculated | E29: Current Market cap USD | G29: {=_xll.EQUIDATA($G$12,$A29,"private")} -> 6982.3877 | H29: <-- Use EQUIDATA
A30: TABLE1_SCALE | C30: Input | E30: Financial Summary (scale) | G30: Rs mn
A31: TABLE2_SCALE | C31: Input | E31: Income Statement (scale) | G31: Rs mn
A32: TABLE3_SCALE | C32: Input | E32: Balance Sheet (scale) | G32: Rs mn
A33: TABLE4_SCALE | C33: Input | E33: Cash Flow (scale) | G33: Rs mn
A34: TABLE5_SCALE | C34: Input | E34: Old vs. New Table (scale) | G34: Rs mn
E37: Profit & Loss statement
A38: IS_GR_SALES | B38: =IF(IF(D38="+",MIN(H38:IU38)>=0,IF(D38="-",MAX(H38:IU38)<=0,TRUE)),"",1) | C38: Input | D38: + | E38: Gross Sales | F38: mn
A39: IS_DUTIES | B39: =IF(IF(D39="+",MIN(H39:IU39)>=0,IF(D39="-",MAX(H39:IU39)<=0,TRUE)),"",1) | C39: Input | D39: + | E39: Less: Duties | F39: mn
A40: IS_NET_SALES | C40: Calculated | D40: ● | E40: Net Sales | F40: mn
A41: IS_NET_SALES_USD | B41: =IF(IF(D41="+",MIN(H41:IU41)>=0,IF(D41="-",MAX(H41:IU41)<=0,TRUE)),"",1) | C41: Input | D41: + | E41: Net Sales ($) | F41: mn
A42: IS_OOP_INC | B42: =IF(IF(D42="+",MIN(H42:IU42)>=0,IF(D42="-",MAX(H42:IU42)<=0,TRUE)),"",1) | C42: Input | D42: + | E42: Other Operating Income | F42: mn
...

Sheet NewFinSumm
B2: Consolidated Financial Statements
B3: Rs. mn | C3: FY18 | D3: FY19 | E3: FY20 | F3: FY21 | G3: FY22 | H3: FY23 | I3: FY24 | J3: FY25 | K3: FY26 | L3: FY27E | M3: FY28E | N3: FY29E | O3: FY30E
B4: Profit & Loss
B5: Revenue | C5: =Consol!G16 -> 9980.936 | D5: =Consol!H16 -> 10802.602 | E5: =Consol!I16 -> 11431.453 | F5: =Consol!J16 -> 16035.705 | G5: =Consol!K16 -> 22730.588 | H5: =Consol!L16 -> 31947.396 | I5: =Consol!M16 -> 37628.9 | J5: =Consol!N16 -> 44761.4 | ... O5: =Consol!S16 -> 188550.74 | P5: =(N5/J5)^(1/4)-1 -> 0.34007521
B6: Gross profit
B7: EBITDA | C7: =Consol!G23 -> 5878.356 | D7: =Consol!H23 -> 6121.407 | E7: =Consol!I23 -> 6191.962 | F7: =Consol!J23 -> 8164.395 | G7: =Consol!K23 -> 11094.308 | H7: =Consol!L23 -> 16201.896 | I7: =Consol!M23 -> 19645.6 | J7: =Consol!N23 -> 22621.8 | ... O7: =Consol!S23 -> 75506.814 | P7: =(N7/J7)^(1/4)-1 -> 0.26520921
B8: Depreciation | C8: =Consol!G28 -> 1571.402 | D8: =Consol!H28 -> 2524.951 | E8: =Consol!I28 -> 2018.573 | F8: =Consol!J28 -> 2706.55 | G8: =Consol!K28 -> 3695.05 | H8: =Consol!L28 -> 3912.23 | I8: =Consol!M28 -> 4364.8 | J8: =Consol!N28 -> 5465.5 | ... O8: =Consol!S28 -> 24495.596
B9: EBIT | C9: =C7-C8 -> 4306.954 | D9: =D7-D8 -> 3596.456 | E9: =E7-E8 -> 4173.389 | F9: =F7-F8 -> 5457.845 | G9: =G7-G8 -> 7399.258 | H9: =H7-H8 -> 12289.666 | I9: =I7-I8 -> 15280.8 | J9: =J7-J8 -> 17156.3 | ... O9: =O7-O8 -> 51011.218
B10: Other Income | C10: =Consol!G27 -> 766.755 | D10: =Consol!H27 -> 1013.331 | E10: =Consol!I27 -> 942.207 | F10: =Consol!J27 -> 746.93 | G10: =Consol!K27 -> 1056.79 | H10: =Consol!L27 -> 1781.13 | I10: =Consol!M27 -> 2694.1 | J10: =Consol!N27 -> 3529.5 | ... O10: =Consol!S27 -> 1594.2853
B11: Interest expense | C11: =Consol!G32 -> 1298.942 | D11: =Consol!H32 -> 1771.365 | E11: =Consol!I32 -> 2774.583 | F11: =Consol!J32 -> 2278.57 | G11: =Consol!K32 -> 4196.22 | H11: =Consol!L32 -> 5960.8 | I11: =Consol!M32 -> 3324.6 | J11: =Consol!N32 -> 2657.4 | ... O11: =Consol!S32 -> 15540.225 | P11: =(N11/J11)^(1/4)-1 -> 0.42414851
B12: Exceptional items | C12: =Consol!G33 -> 0 | D12: =Consol!H33 -> 0 | E12: =Consol!I33 -> 0 | F12: =Consol!J33 -> 0 | G12: =Consol!K33 -> 0 | H12: =Consol!L33 -> 0 | I12: =Consol!M33 -> 0 | J12: =Consol!N33 -> 0 | ... O12: =Consol!S33 -> 0
B13: PBT | C13: =Consol!G35 -> 3774.767 | D13: =Consol!H35 -> 2838.422 | E13: =Consol!I35 -> 2341.013 | F13: =Consol!J35 -> 3926.205 | G13: =Consol!K35 -> 4259.828 | H13: =Consol!L35 -> 8109.996 | I13: =Consol!M35 -> 14650.3 | J13: =Consol!N35 -> 18028.4 | ... O13: =Consol!S35 -> 37065.278
B14: Reported PAT (after minority interest) | C14: =Consol!G49 -> 2808.137 | D14: =Consol!H49 -> 2667.244 | E14: =Consol!I49 -> 1904.241 | F14: =Consol!J49 -> 2913.855 | G14: =Consol!K49 -> 3279.458 | H14: =Consol!L49 -> 7398.376 | I14: =Consol!M49 -> 11559.1 | J14: =Consol!N49 -> 15030.8 | ... O14: =Consol!S49 -> 27948.574
B15: Adj PAT | C15: =C14+C12 -> 2808.137 | D15: =D14+D12 -> 2667.244 | E15: =E14+E12 -> 1904.241 | F15: =F14+F12 -> 2913.855 | G15: =G14+G12 -> 3279.458 | H15: =H14+H12 -> 7398.376 | I15: =I14+I12 -> 11559.1 | J15: =J14+J12 -> 15030.8 | ... O15: =O14+O12 -> 27948.574
B16: EPS (Rs.) | C16: =C15/C75 -> 1.3372081 | D16: =D15/D75 -> 1.2701162 | E16: =E15/E75 -> 0.90678143 | F16: =F15/F75 -> 1.38755 | G16: =G15/G75 -> 1.5616467 | H16: =H15/H75 -> 3.5230362 | I16: =I15/I75 -> 5.5043333 | J16: =J15/J75 -> 7.1575238 | ... O16: =O15/O75 -> 11.995096 | P16: =(N16/J16)^(1/4)-1 -> 0.1003218
B17: Balance Sheet | I17: =+I15/H15-1 -> 0.56238342 | J17: =+J16/I16-1 -> 0.30034345 | K17: =+K16/J16-1 -> 0.066503446 | S17: Total Share count (Mn) | T17: =Valuation!$C$3 -> 2330
B18: Net Worth | C18: =Consol!G65+Consol!G66+Consol!G69 -> 28048.97 | D18: =Consol!H65+Consol!H66+Consol!H69 -> 30847.183 | E18: =Consol!I65+Consol!I66+Consol!I69 -> 27513.163 | F18: =Consol!J65+Consol!J66+Consol!J69 -> 30884.31 | G18: =Consol!K65+Consol!K66+Consol!K69 -> 34718.77 | H18: =Consol!L65+Consol!L66+Consol!L69 -> 40888.73 | I18: =Consol!M65+Consol!M66+Consol!M69 -> 82310.2 | J18: =Consol!N65+Consol!N66+Consol!N69 -> 104887 | ... O18: =Consol!S65+Consol!S66+Consol!S69 -> 267222.74
B19: Total debt | C19: =Consol!G78 -> 16799.911 | D19: =Consol!H78 -> 20001.206 | E19: =Consol!I78 -> 27167.16 | F19: =Consol!J78 -> 39458.18 | G19: =Consol!K78 -> 44086.94 | H19: =Consol!L78 -> 42436.98 | I19: =Consol!M78 -> 43806.8 | J19: =Consol!N78 -> 46588.3 | ... O19: =Consol!S78 -> 153554.57
B20: Other liabilities and provisions | C20: =Consol!G79+Consol!G80+Consol!G81+Consol!G111+Consol!G112 -> 6182.269 | D20: =Consol!H79+Consol!H80+Consol!H81+Consol!H111+Consol!H112 -> 7355.923 | E20: =Consol!I79+Consol!I80+Consol!I81+Consol!I111+Consol!I112 -> 13119.782 | F20: =Consol!J79+Consol!J80+Consol!J81+Consol!J111+Consol!J112 -> 10051.65 | G20: =Consol!K79+Consol!K80+Consol!K81+Consol!K111+Consol!K112 -> 12741 | H20: =Consol!L79+Consol!L80+Consol!L81+Consol!L111+Consol!L112 -> 8165.01 | I20: =Consol!M79+Consol!M80+Consol!M81+Consol!M111+Consol!M112 -> 8596.4 | J20: =Consol!N79+Consol!N80+Consol!N81+Consol!N111+Consol!N112 -> 14316.1 | ... O20: =Consol!S79+Consol!S80+Consol!S81+Consol!S111+Consol!S112 -> 18813.7 | S20: CRYSTAL BALL GAZING
B21: Total Networth and liabilities | C21: =SUM(C18:C20) -> 51031.15 | D21: =SUM(D18:D20) -> 58204.312 | E21: =SUM(E18:E20) -> 67800.105 | F21: =SUM(F18:F20) -> 80394.14 | G21: =SUM(G18:G20) -> 91546.71 | H21: =SUM(H18:H20) -> 91490.72 | I21: =SUM(I18:I20) -> 134713.4 | J21: =SUM(J18:J20) -> 165791.4 | ... O21: =SUM(O18:O20) -> 439591.01
B22: Gross Fixed assets | C22: =Consol!G87 -> 29525.534 | D22: =Consol!H87 -> 32684.214 | E22: =Consol!I87 -> 41579.557 | F22: =Consol!J87 -> 44786.871 | G22: =Consol!K87 -> 47405.001 | H22: =Consol!L87 -> 48886.498 | I22: =Consol!M87 -> 64231 | J22: =Consol!N87 -> 84934.2 | ... O22: =Consol!S87 -> 438250.33 | S22: Consolidated | V22: FY20-FY25 | W22: FY25-FY30E | AB22: Valuation Table
B23: Net fixed assets | C23: =Consol!G89 -> 27368.261 | D23: =Consol!H89 -> 29180.329 | E23: =Consol!I89 -> 36437.466 | F23: =Consol!J89 -> 36938.23 | G23: =Consol!K89 -> 38712.123 | H23: =Consol!L89 -> 38451.017 | I23: =Consol!M89 -> 51128.1 | J23: =Consol!N89 -> 68131.7 | ... O23: =Consol!S89 -> 352488.2 | S23: Revenues CAGR | V23: =(J5/E5)^(1/5)-1 -> 0.31389435 | W23: =(O5/J5)^(1/5)-1 -> 0.3332295 | AB23: Business | AC23: EV/EBITDA Multiple | AD23: FY29E EBITDA (Rs. bn) | AE23: Equity Value (Rs/share)
B24: Capital work-in-progress | C24: =Consol!G90+Consol!G94 -> 6326.228 | D24: =Consol!H90+Consol!H94 -> 8619.909 | E24: =Consol!I90+Consol!I94 -> 7515.751 | F24: =Consol!J90+Consol!J94 -> 11250.46 | G24: =Consol!K90+Consol!K94 -> 796.81 | H24: =Consol!L90+Consol!L94 -> 460.13 | I24: =Consol!M90+Consol!M94 -> 1320.4 | J24: =Consol!N90+Consol!N94 -> 20202.4 | ... O24: =Consol!S90+Consol!S94 -> 410.2 | S24: EBITDA CAGR | V24: =(J7/E7)^(1/5)-1 -> 0.29580537 | W24: =(O7/J7)^(1/5)-1 -> 0.27259964 | AB24: Ports | AC24: 15 | AD24: =Consol!$S$23/1000 -> 75.506814 | AE24: =AD24*AC24*1000/$T$17 -> 486.09537
B25: Intangible Assets | C25: =Consol!G93 -> 3671.532 | D25: =Consol!H93 -> 3384.563 | E25: =Consol!I93 -> 3042.448 | F25: =Consol!J93 -> 12301.71 | G25: =Consol!K93 -> 22626.79 | H25: =Consol!L93 -> 21294.55 | I25: =Consol!M93 -> 26446.4 | J25: =Consol!N93 -> 25797.6 | ... O25: =Consol!S93 -> 30357.4 | S25: EBITDA margin | V25: =AVERAGE(E57:J57) -> 0.51224905 | W25: =AVERAGE(J57:O57) -> 0.43907948 | AB25: Ports | AC25: 20 | AD25: =Consol!$S$23/1000 -> 75.506814 | AE25: =AD25*AC25*1000/$T$17 -> 648.12716
B26: Investments | C26: =Consol!G96+Consol!G102 -> 283.762 | D26: =Consol!H96+Consol!H102 -> 2297.624 | E26: =Consol!I96+Consol!I102 -> 3764.403 | F26: =Consol!J96+Consol!J102 -> 2955.08 | G26: =Consol!K96+Consol!K102 -> 2830.08 | H26: =Consol!L96+Consol!L102 -> 3070.28 | I26: =Consol!M96+Consol!M102 -> 2444.9 | J26: =Consol!N96+Consol!N102 -> 3127.6 | ... O26: =Consol!S96+Consol!S102 -> 1218.4 | S26: EPS CAGR | V26: =(J15/E15)^(1/5)-1 -> 0.51165274 | W26: =(O16/J16)^(1/5)-1 -> 0.10878716
B27: Cash and bank balances | C27: =Consol!G105 -> 3284.496 | D27: =Consol!H105 -> 1017.636 | E27: =Consol!I105 -> 1626.074 | F27: =Consol!J105 -> 2648.4 | G27: =Consol!K105 -> 10382.35 | H27: =Consol!L105 -> 16316.43 | I27: =Consol!M105 -> 40902.2 | J27: =Consol!N105 -> 24820.7 | ... O27: =Consol!S105 -> 3310.0258 | S27: Total Asset Turnover (x) | V27: =AVERAGE(E67:J67) -> 0.27365789 | W27: =AVERAGE(J67:O67) -> 0.33530143
B28: Loans & advances and other assets | C28: =Consol!G97+Consol!G98+Consol!G99+Consol!G106+Consol!G107 -> 8212.357 | D28: =Consol!H97+Consol!H98+Consol!H99+Consol!H106+Consol!H107 -> 9113.039 | E28: =Consol!I97+Consol!I98+Consol!I99+Consol!I106+Consol!I107 -> 9939.229 | F28: =Consol!J97+Consol!J98+Consol!J99+Consol!J106+Consol!J107 -> 10642.21 | G28: =Consol!K97+Consol!K98+Consol!K99+Consol!K106+Consol!K107 -> 12079.01 | H28: =Consol!L97+Consol!L98+Consol!L99+Consol!L106+Consol!L107 -> 9868.85 | I28: =Consol!M97+Consol!M98+Consol!M99+Consol!M106+Consol!M107 -> 8148.2 | J28: =Consol!N97+Consol!N98+Consol!N99+Consol!N106+Consol!N107 -> 17776.6 | ... O28: =Consol!S97+Consol!S98+Consol!S99+Consol!S106+Consol!S107 -> 30945.4 | S28: Total WC days | V28: =AVERAGE(E73:J73) -> 72.955676 | W28: =AVERAGE(J73:O73) -> 52.700473 | AB28: Upside calculation
B29: Net working capital | C29: =Consol!G103+Consol!G104-Consol!G110 -> 1884.514 | D29: =Consol!H103+Consol!H104-Consol!H110 -> 4591.213 | E29: =Consol!I103+Consol!I104-Consol!I110 -> 5474.736 | F29: =Consol!J103+Consol!J104-Consol!J110 -> 3658.04 | G29: =Consol!K103+Consol!K104-Consol!K110 -> 4119.6 | H29: =Consol!L103+Consol!L104-Consol!L110 -> 2029.47 | I29: =Consol!M103+Consol!M104-Consol!M110 -> 4323.1 | J29: =Consol!N103+Consol!N104-Consol!N110 -> 5934.7 | ... O29: =Consol!S103+Consol!S104-Consol!S110 -> 20861.383 | S29: Pre-tax OCF/EBITDA (%) | V29: =AVERAGE(E60:J60) -> 1.0424607 | W29: =AVERAGE(J60:O60) -> 0.99781384 | AB29: Entry Price (CMP) | AC29: Rs/share | AD29: =Valuation!C2 -> 348.45
B30: Total assets | C30: =SUM(C23:C29) -> 51031.15 | D30: =SUM(D23:D29) -> 58204.313 | E30: =SUM(E23:E29) -> 67800.107 | F30: =SUM(F23:F29) -> 80394.13 | G30: =SUM(G23:G29) -> 91546.763 | H30: =SUM(H23:H29) -> 91490.727 | I30: =SUM(I23:I29) -> 134713.3 | J30: =SUM(J23:J29) -> 165791.3 | ... O30: =SUM(O23:O29) -> 439591.01 | S30: OCF as a % of IC | V30: =AVERAGE(E61:J61) -> 0.18517911 | W30: =AVERAGE(J61:O61) -> 0.16715751
B31: Capital Employed | C31: =C30-C20 -> 44848.881 | D31: =D30-D20 -> 50848.39 | E31: =E30-E20 -> 54680.325 | F31: =F30-F20 -> 70342.48 | G31: =G30-G20 -> 78805.763 | H31: =H30-H20 -> 83325.717 | I31: =I30-I20 -> 126116.9 | J31: =J30-J20 -> 151475.2 | ... O31: =O30-O20 -> 420777.31 | S31: Net Debt/EBITDA | V31: =AVERAGE(E70:J70) -> 2.3989567 | W31: =AVERAGE(J70:O70) -> 1.5850449 | AB31: Target Price | AC31: Rs/share | AD31: =AE24 -> 486.09537
B32: Invested Capital (CE - cash - CWIP) | C32: =C31-C42-C24 -> 34954.395 | D32: =D31-D42-D24 -> 38913.221 | E32: =E31-E42-E24 -> 44864.097 | F32: =F31-F42-F24 -> 56443.62 | G32: =G31-G42-G24 -> 67626.603 | H32: =H31-H42-H24 -> 63504.247 | I32: =I31-I42-I24 -> 81695.9 | J32: =J31-J42-J24 -> 104854.3 | ... O32: =O31-O42-O24 -> 417036.98 | AB32: Cumulative Dividends | AC32: Rs/share | AD32: =SUM(Consol!P58:R58) -> 3.2854403
B33: Net debt | C33: =C19-C27 -> 13515.415 | D33: =D19-D27 -> 18983.57 | E33: =E19-E27 -> 25541.086 | F33: =F19-F27 -> 36809.78 | G33: =G19-G27 -> 33704.59 | H33: =H19-H27 -> 26120.55 | I33: =I19-I27 -> 2904.6 | J33: =J19-J27 -> 21767.6 | ... O33: =O19-O27 -> 150244.55 | AB33: Total Return | AC33: Rs/share | AD33: =AD31+AD32 -> 489.38081
B34: Cash Flows | S34: Consolidated | V34: =V22 -> FY20-FY25 | W34: =W22 -> FY25-FY30E | AB34: Upside/(Downside) | AC34: % | AD34: =(AD33/AD29-1) -> 0.4044506
B35: Cash flows from Operations (Pre-tax) | C35: =Consol!G138 -> 7018.043 | D35: =Consol!H138 -> 3578.053 | E35: =Consol!I138 -> 2950.405 | F35: =Consol!J138 -> 10562.76 | G35: =Consol!K138 -> 12984.77 | H35: =Consol!L138 -> 19778.84 | I35: =Consol!M138 -> 20507.6 | J35: =Consol!N138 -> 23740.8 | ... O35: =Consol!S138 -> 73742.646 | S35: RoE (%) | V35: =AVERAGE(E62:J62) -> 0.14152918 | W35: =AVERAGE(J62:O62) -> 0.12781053
B36: Cash flows from Operations (post-tax) | C36: =Consol!G141 -> 5999.008 | D36: =Consol!H141 -> 3280.213 | E36: =Consol!I141 -> 2587.043 | F36: =Consol!J141 -> 9901.88 | G36: =Consol!K141 -> 11762.3 | H36: =Consol!L141 -> 17972.27 | I36: =Consol!M141 -> 18032.1 | J36: =Consol!N141 -> 21004.4 | ... O36: =Consol!S141 -> 65588.285 | S36: RoCE (%) | V36: =AVERAGE(E63:J63) -> 0.094519019 | W36: =AVERAGE(J63:O63) -> 0.091140632 | AC36: Mar'24 | AD36: Jun'24 | AE36: Sep'24
B37: Capex + Acquisitions | C37: =Consol!G147+Consol!G151 -> -9378.02 | D37: =Consol!H147+Consol!H151 -> -5518.759 | E37: =Consol!I147+Consol!I151 -> -6737.866 | F37: =Consol!J147+Consol!J151 -> -17226.12 | G37: =Consol!K147+Consol!K151 -> -5090.77 | H37: =Consol!L147+Consol!L151 -> -2793.56 | I37: =Consol!M147+Consol!M151 -> -20711.6 | J37: =Consol!N147+Consol!N151 -> -30400.1 | ... O37: =Consol!S147+Consol!S151 -> -67266.454 | S37: RoIC (%) | V37: =AVERAGE(E64:J64) -> 0.13397606 | W37: =AVERAGE(J64:O64) -> 0.12741382 | AB37: Promoters | AC37: 85.61 | AD37: 85.61 | AE37: 85.61
B38: Free cashflows | C38: =C36+C37 -> -3379.012 | D38: =D36+D37 -> -2238.546 | E38: =E36+E37 -> -4150.823 | F38: =F36+F37 -> -7324.24 | G38: =G36+G37 -> 6671.53 | H38: =H36+H37 -> 15178.71 | I38: =I36+I37 -> -2679.5 | J38: =J36+J37 -> -9395.7 | ... O38: =O36+O37 -> -1678.1693 | S38: Average 1 yr fwd | X38: <From Bloomberg Crystal Ball Gazing file | AB38: FII | AC38: 2.34 | AD38: 4.15 | AE38: 4.2
B39: Free cashflows (post interest costs) | C39: =C38+Consol!G165 -> -4573.664 | D39: =D38+Consol!H165 -> -3460.104 | E39: =E38+Consol!I165 -> -6306.892 | F39: =F38+Consol!J165 -> -9573.66 | G39: =G38+Consol!K165 -> 3050.87 | H39: =H38+Consol!L165 -> 12451.8 | I39: =I38+Consol!M165 -> -5158.4 | J39: =J38+Consol!N165 -> -12460.4 | ... O39: =O38+Consol!S165 -> -17218.394 | S39: PE (x) | AB39: DII | AC39: 3.59 | AD39: 2.74 | AE39: 2.5
B40: Cash flows from Investing | C40: =Consol!G154 -> -10983.644 | D40: =Consol!H154 -> -4948.901 | E40: =Consol!I154 -> -3930.804 | F40: =Consol!J154 -> -16367.94 | G40: =Consol!K154 -> -8013.22 | H40: =Consol!L154 -> -6207.92 | I40: =Consol!M154 -> -42046.8 | J40: =Consol!N154 -> -16968.8 | ... O40: =Consol!S154 -> -67266.454 | S40: EV/EBITDA (x) | AB40: Public | AC40: 6.14 | AD40: 5.79 | AE40: 6.32
B41: Cash flows from Financing | C41: =Consol!G169 -> 5397.38 | D41: =Consol!H169 -> 1398.918 | E41: =Consol!I169 -> 2407.796 | F41: =Consol!J169 -> 6408.57 | G41: =Consol!K169 -> 25.53 | H41: =Consol!L169 -> -10865.62 | I41: =Consol!M169 -> 25038.8 | J41: =Consol!N169 -> -5213.4 | ... O41: =Consol!S169 -> -2404.6212 | S41: PB (x)
...

Sheet Key
B2: Operational Capacity
B3: Port Asset | C3: Entity | D3: Stake, % | E3: Acquired or Created? | F3: Acquiried From? | G3: Acq Consideration, Rs. mn | H3: Asset Type | I3: Type of Agreement (Concession/Lease/License/O&M) | J3: State | K3: Capacity, MT | L3: Draft, m | M3: Cargo Type | N3: Major Cargoes Handled | O3: Expansion Plans, MTPA | P3: Expansion - Cargo type | Q3: Hinterland | R3: Key Customers | S3: Evacuation Plan/ Infrastructure | T3: CoD | U3: Concession, years | V3: Concession Expiry | W3: Concession With | X3: Guaranteed Throughput | Y3: No of Berths | Z3: Berth Length, mtrs | AA3: Annual/Lease charges (Rs. mn) | AB3: Tariff | AC3: Revenue Share | AD3: CAPEX, Rs. mn | AE3: Concession Years Left | AF3: Customer | AG3: Check in RHP Once
B4: Dharamtar | C4: JSW Dharmatar Port Private Ltd | D4: 1 | E4: Created | F4: - | G4: - | H4: Port | I4: Lease | J4: Maharashtra | K4: 34 | L4: 3.5 | M4: Bulk | N4: limestone, dolomite, iron ore, coal, and scrap | O4: NA | P4: NA | R4: JSW Steel and JSW Cement | S4: The Dharamtar Port is located in close proximity to the Mumbai and Jawaharlal Nehru Port Trust (Nhava Sheva harbors), NH-66 and the Konkan railway network and almost all the cargo is evacuated through its conveyor system. It is also directly connected to the premises of JSW Steel’s manufacturing facility through a mechanized conveyor system. | T4: 2012 | U4: NA | V4: 2044 | W4: Maharashtra Maritime Board | X4: None | Y4: 5 | Z4: 771 | AA4: NA | AB4: Negotiated | AC4: As per Maharashtra Maritime Board | AE4: =V4-2026 -> 18 | AF4: All group | AG4: Exclusive to Steel | AH4: Dolvi plant
B5: Jaigarh | C5: JSW Jaigarh Port Ltd | D5: 1 | E5: Created | F5: - | G5: - | H5: Port | I5: Concession | J5: Maharashtra | K5: 55 | L5: 17.5 | M5: Multi-Cargo | N5: multi-purpose, all weather port. LNG, LPG, molasses, sugar, steel coil, bauxite, fly ash, thermal coal, coking coal, iron ore, limestone, fertilizers, coated pipes, rock phosphate, sulphur, steel coil, containers, gypsum, and edible oil | O5: 2 | P5: LPG | Q5: parts of northern Goa, southern and western Maharashtra, and Northern and central Karnataka | R5: JSW Energy, JSW Steel | S5: Jaigarh Port is connected to NH-66 (Mumbai-Goa) at Nivali through SH 106. The Jaigarh Port is at a distance of about 55 kilometres from Ratnagiri on the Konkan railway network. Trans-ship cargo from the Jaigarh Port to other locations including the Dharamtar Port through mini bulk carriers. | T5: 2010 | U5: 50 | V5: 2058 | W5: Maharashtra Maritime Board | X5: None | Y5: 7 | Z5: 2319 | AA5: =25.2+6.4 -> 31.6 | AB5: Negotiated | AC5: JSW Energy: 15 per MMT in the first year of operations, subject to revisions by the Maharashtra Maritime Board Other customers: ₹3 per MMT in the first year of operations, escalated by 20% annually till the 15th year of operation; and from the 16th year of operations, escalated by 3% every fifth financial year | AE5: =V5-2026 -> 32 | AF5: 70% is group | AG5: JSW Steel biggest customer, H Energy | AJ5: Trans Shipment to Dharamtar
B6: South West (Goa) | C6: South West Port Limited | D6: 0.9 | E6: Acquired | H6: Terminal | I6: License | J6: Goa | K6: 11 | L6: 14 | M6: Bulk | N6: Coal, Steel and Limestone | O6: NA | P6: NA | R6: JSW Steel | S6: The South West Port is connected to both NH 66 and NH 748, with NH 748 providing connectivity to NH 566, a major highway that connects Mumbai and Bengaluru. The South West Port has a railway connection with the Southwest Railway rail head entering the harbor to touch the terminal, allowing for smooth transportation of goods by rail. The Zuari and Mandovi rivers provide inland waterway transport facilities, connecting the Mormugao Harbor – and the South West Port – with mines and manufacturing plants in the hinterland. | T6: 2004 | U6: 30 | V6: 2029 | W6: Mormugao Port | X6: 5 MMT | Y6: 2 | Z6: 450 | AA6: 15.22 | AB6: Until Fiscal 2022 – regulated Post 2022 – WPI linked | AC6: 18% of gross revenue excludin g berth hire income | AE6: =V6-2026 -> 3 | AF6: All group | AG6: Largely JSW Steel | AH6: Vijaynagar Steel Plant | AJ6: Company can operate if the shed is made with capex of 100crs - should complete by year end
B7: New Mangalore Coal | C7: Mangalore Coal Terminal Pvt Ltd | D7: 1 | E7: Acquired | H7: Terminal | I7: Concession | J7: Karnataka | K7: 8.1 | L7: 14 | M7: Bulk | N7: Coal, Limestone, and dolomite cargo | O7: NA | P7: NA | Q7: New Mangalore Coal Terminal is located in NMPT and is a modern all-weather terminal situated at Panambur, Mangalore on the west coast of India, 170 nautical miles south of Mormugao Port and 191 nautical miles north of Cochin Port. | R7: The terminal’s key customers are the power plants located around the hinterland belts of Karnataka and Tamil Nadu. | S7: New Mangalore Port is connected to NH 75, NH 66, NH 52, NH 50 and NH 275, which permits our terminals to connect with all of Karnataka, Goa and other parts of southern part of India through Mangalore, Kerala, Chennai. | T7: 2020 | U7: 30 | V7: 2047 | W7: New Mangalore Port Authority | X7: 3.7 MMT | Y7: 1 | Z7: 315 | AA7: MCTPL is required to pay to the Board of Trustees for NMPT certain license fees. License fee for land area being equivalent to the product of extent of land area in square meter and license fee per square meter per year (derived with 2% compounded annual increment) corresponding to a base license fee of ₹19.21 square meter per month, with an additional 10% surcharge on custom notified areas. License fee for water area being equivalent to the product of extent of water area in square meter and license fee per square meter per year (derived with 2% compounded annual increment) corresponding to a base license fee of ₹9.61 per square meter per month, with an additional 10% surcharge on custom notified areas. | AB7: Fixed at bidding and WPI linked | AC7: 31% of Gross Revenue | AE7: =V7-2026 -> 21 | AF7: 70% is group | AG7: Largely JSW Steel
B8: New Mangalore Container | C8: JSW Mangalore Container Terminal Pvt Ltd | D8: 1 | E8: Created | F8: - | G8: - | H8: Terminal | I8: Concession | J8: Karnataka | K8: =4.2 -> 4.2 | L8: 14 | M8: Container | N8: Containers and other bulk | O8: =6.02-K8 -> 1.82 | P8: To further our diversification strategy with focus on expanding footprint in containers cargo, pursuing opportunities in synergistic businesses and increasing our third-party customer base, we are in the process of expanding our existing facilities at Mangalore Container Terminal by developing an additional yard and procure additional equipment | S8: connectivity to NH-75, NH-66, NH-52, NH-50 and NH-275, which permits our terminals to connect with all of Karnataka, Goa and other parts of southern India through Mangalore, Kerala and Chennai | T8: 2022 | U8: 30 | V8: 2050 | W8: New Mangalore Port Authority - to mechanization of berth 14 for providing equipment for handling containers and other cargoes at New Mangalore Port on DBFOT basis | X8: minimum 91,000 TEU | Y8: 1 | Z8: 350 | AA8: MTPL’s payment obligations comprise (i) license fee equal to the product of extent of land area in square meter and license fee per square meter per year (derived with 2% compounded annual increment) corresponding to base license fee of ₹24.83 per square meter per month, with an additional 10% surcharge on custom notified areas; | AB8: Fixed at bidding and WPI linked | AC8: INR 951 per TEU | AE8: =V8-2026 -> 24 | AF8: All third Party
B9: Ennore Coal | C9: Ennore Coal Terminal Pvt Ltd | D9: 1 | E9: Acquired | H9: Terminal | I9: License | J9: Tamil Nadu | K9: 11 | L9: 16 | M9: Bulk | N9: Coal | O9: NA | P9: NA | S9: Ennore Port is connected to NH 4, NH 5 and NH 45 and a dedicated freight corridor between Chennai and Bangalore/Mumbai and Delhi/Kolkata. Our terminals are connected by rail to the Chennai-Gudur Section (North- East Line) of the Southern Railway. The connection involves two lines – the South Connectivity Line and the North Connectivity Line, both located in the terminal area, and another a 6 km rail line connecting to the Chennai- Kolkata line. | T9: 2020 | U9: 30 | V9: 2038 | W9: Kamarajar Port Ltd | X9: Rs. 50mn | Y9: 1 | Z9: 348 | AA9: NA | AB9: Fixed by the operator for various services across customers | AC9: 52.52% of Gross Revenue | AE9: =V9-2026 -> 12 | AF9: Third Party and Group | AG9: JSW Steel
B10: Ennore Bulk | C10: Ennore Bulk Terminal Pvt Ltd | D10: 1 | E10: Acquired | H10: Terminal | I10: Concession | J10: Tamil Nadu | K10: 2 | L10: 14.5 | M10: Bulk | N10: Dry Bulk (Clean cargo other than coal,iron ore, POL and automobile) | O10: NA | P10: NA | S10: Ennore Port is connected to NH 4, NH 5 and NH 45 and a dedicated freight corridor between Chennai and Bangalore/Mumbai and Delhi/Kolkata. Our terminals are connected by rail to the Chennai-Gudur Section (North- East Line) of the Southern Railway. The connection involves two lines – the South Connectivity Line and the North Connectivity Line, both located in the terminal area, and another a 6 km rail line connecting to the Chennai- Kolkata line. | T10: 2020 | U10: 30 | V10: 2045 | W10: Kamarajar Port Ltd | X10: 1.4 MMT | Y10: 1 | Z10: 270 | AA10: 10.66 | AB10: Fixed by the operator for various services across customers | AC10: 36% of Gross Revenue | AE10: =V10-2026 -> 19 | AF10: 80% Third Party
B11: Paradip Iron Ore | C11: JSW Paradip Terminal Pvt Ltd | D11: 0.974 | E11: Created | F11: - | G11: - | H11: Terminal | I11: Concession | J11: Orissa | K11: 10 | L11: 16 | M11: Bulk | N11: Iron ore and pellets | O11: NA | P11: NA | S11: The terminal is connected with its hinterland through a network of roads and railways. It is connected by a state highway with Cuttack in the state of Odisha and the state capital Bhubaneswar and is also linked to NH 5A. The Indian Railways serves the port through a direct broad gauge double line connected to Cuttack, the commercial hub of Odisha. | T11: 2019 | U11: 30 | V11: 2045 | W11: Paradip Port Trust | X11: 7 MTPA | Y11: 1 | Z11: 370 | AA11: 9 | AB11: Fixed at bidding and WPI linked | AC11: 21% of Gross Revenue | AE11: =V11-2026 -> 19 | AF11: 70% third party. 30% Group | AG11: Merchant Pellet Plant owners and Miners in Orissa
B12: Paradip Coal Exports | C12: Paradip East Quay Coal Terminal Ltd | D12: 0.974 | E12: Created | F12: - | G12: - | H12: Terminal | I12: Concession | J12: Orissa | K12: 30 | L12: 15 | M12: Bulk | N12: Coal | O12: NA | P12: NA | S12: The terminal is connected to NH 5 through a dedicated four-lane road. The terminal also connected to East Coast Railways network leading to Cuttack in Odisha, through the Paradip Port Trust’s rail network within the port area (broad-gauge double line tracks). | T12: 2021 | U12: 30 | V12: 2047 | W12: Paradip Port Trust | X12: 8 MTPA | Y12: 2 | Z12: 686 | AA12: 23.3 | AB12: Fixed at bidding and WPI linked | AC12: 31.7% of Gross Revenue | AE12: =V12-2026 -> 21 | AF12: All third Party | AH12: Usually inland transport of Coal to Telangana and Tamil Nadu, TANGEDCO, Sembcorp
A13: Recently Acquired | B13: PNP Port | C13: PNP Maritime Services | D13: 50% stepdown subsidairy of JSW Dharmatar Port Private Ltd | E13: Acquired | F13: Shapoorji Pallonji Group (SP Port Maintenance Private Limited). The Company has vision to expand its cargo handling capacity and cargo volume/ throughput in all types of cargoes. Considering the same, this acquisition would help the Company to achieve its growth & expand its footprint. | G13: 2700mn Equity, 7000mn EV | H13: Port | I13: License | J13: Maharashtra | K13: 8 | M13: Bulk | N13: PNP Port is operating multi-purpose jetties at Shahabad in Raigad district of Maharashtra - Steel, Cement and Coal | O13: 19 | Q13: This acquisition is part of JSW Infrastructure’s strategic direction to explore opportunities to expand organically and inorganically, to provide end to end logistics services near the cargo consumption / generation centres. PNP port is expected to strengthen JSW Infrastructure’s position to provide Hub & Spoke model services to customers, thereby saving substantially in the logistics costs. JSW Infrastructure intends to upgrade the PNP Port facilities and expand its capacity from current 5 MTPA to 19 MTPA in a phased manner. This acquisition furthers its vision to increase the use of waterways and existing railway facility at PNP adds synergies to the last mile connectivity. The acquisition of PNP Port is a strategic asset for JSW infrastructure. It will allow the company to service growing share of 3rd party customers in India and derive huge synergies with our existing ports & terminals. It will be able to participate in the Govt. of India Maritime Vision to move cargo through Rail- Sea- Rail route and coastal cargo. At PNP Port, development of Port based industries will be a key focus area and service to multipurpose cargo of Bulk, Container, Liquid etc. The PNP Port is an operational port, connected with Road & Rail facilities, and servicing to various industries in the hinterland i.e. Maharashtra, Madhya Pradesh, Karnataka etc. It has a very strategic locational advantage on West Coast of India and having direct access to large cargo centres such as Mumbai, Pune, Mumbai, Palghar, Thane, Pune, Solapur, Bhiwandi, Nasik etc. PNP Port is connected with the Central & Konkan Railway network which is a very important cargo evacuation mode. With the well-connected railway system, it will be able to service customers for container, Liquid and bulk cargo in future. The Port also has very good road connectivity with Mumbai- Goa Highway. | R13: This acquisition is part of JSW Infrastructure’s strategic direction to explore opportunities to expand organically and inorganically, to provide end to end logistics services near the cargo consumption / generation centres. PNP port is expected to strengthen JSW Infrastructure’s position to provide Hub & Spoke model services to customers, thereby saving substantially in the logistics costs. JSW Infrastructure intends to upgrade the PNP Port facilities and expand its capacity from current 5 MTPA to 19 MTPA in a phased manner. This acquisition furthers its vision to increase the use of waterways and existing railway facility at PNP adds synergies to the last mile connectivity. The acquisition of PNP Port is a strategic asset for JSW infrastructure. It will allow the company to service growing share of 3rd party customers in India and derive huge synergies with our existing ports & terminals. It will be able to participate in the Govt. of India Maritime Vision to move cargo through Rail- Sea- Rail route and coastal cargo. At PNP Port, development of Port based industries will be a key focus area and service to multipurpose cargo of Bulk, Container, Liquid etc. The PNP Port is an operational port, connected with Road & Rail facilities, and servicing to various industries in the hinterland i.e. Maharashtra, Madhya Pradesh, Karnataka etc. It has a very strategic locational advantage on West Coast of India and having direct access to large cargo centres such as Mumbai, Pune, Mumbai, Palghar, Thane, Pune, Solapur, Bhiwandi, Nasik etc. PNP Port is connected with the Central & Konkan Railway network which is a very important cargo evacuation mode. With the well-connected railway system, it will be able to service customers for container, Liquid and bulk cargo in future. The Port also has very good road connectivity with Mumbai- Goa Highway. | S13: PNP Port is well connected with road and Railway facilities. | T13: 1999 | U13: 30 | V13: =+T13+U13 -> 2029 | W13: Maharashtra Maritime Board | AA13: - | AC13: NO ROYALTY, why? | AE13: =V13-2026 -> 3 | AF13: All third Party | AG13: Cement,Clinker - local traders of coal | AL13: Realisations are Similar to Dharamtar, rn margins are lower and will improve, wil spend 45-50crs and margin to come to 45-50%
A14: Recently Acquired | B14: Fujairah Liquid | C14: JSW Terminal (Middle East) FZE acquired Marine Oil Terminal Corp | D14: 1 | E14: Acquired | F14: MPT Commodities Limited, British Virgin Islands (Mercuria Group) in December 19, 2023 | G14: $187m EV, Implied EV/EBITDA valuation of 8.5x-9.5x (FY24 EBITDA) | H14: Terminal | I14: Land lease | J14: Overseas | K14: 5 | L14: - | M14: Liquid | N14: Class I to III products including fuel oil, gas oil, diesel & naphtha | O14: - | P14: - | Q14: Overseas | R14: Oil traders, Fuel operators and commodity trading companies | S14: Overseas | T14: 2015 | U14: NA | V14: NA | W14: NA | X14: NA | Y14: 15 tanks | Z14: - | AA14: - | AC14: - | AD14: - | AE14: NA | AF14: All third Party
A15: https://infra.economictimes.indiatimes.com/news/ports-shipping/did-jsw-infra-miscalculate-in-quoting-rs252-a-ton-as-royalty-to-clinch-liquid-cargo-berth-at-j-n-port/107606649 | B15: JNPT Liquid Terminal | C15: JSW JNPT Liquid Terminal Pvt Ltd | D15: 1 | E15: Created | F15: - | G15: - | H15: Terminal | I15: Concession | J15: Maharashtra | K15: 4.5 | L15: - | M15: Liquid | N15: POL, Chemical, Molasses | O15: - | P15: - | Q15: Maharashtra, Gujarat | R15: oil importers/refiners, POL & petroleum product handlers | S15: 19 pipelines of varying diameters, 6 Marine Loading Arms, From tank farms, onward evacuation to hinterland is via road tankers and rail through the JNPA logistics network | T15: 2026 | U15: 30 | V15: =+T15+U15 -> 2056 | W15: Jawaharlal Nehru Port | X15: - | Y15: 2 | Z15: 600 | AA15: - | AB15: - | AC15: Rs. 252/ tonne | AD15: 1000 | AE15: =V15-2026 -> 30 | AF15: All third Party
B16: XX | K16: 0 | O16: - | P16: -
K17: =SUM(K4:K16) -> 182.8
M18: 113.4 | N18: 51.6 | O18: =M18/$K$17 -> 0.62035011 | P18: =N18/$K$17 -> 0.28227571
B19: O&M | W19: Revenue is only 2 million USD, booked under International subsidiary
B20: Fujairah Sea Port (UAE) | C20: JSW Terminal (Middle East) FZE | J20: UAE | V20: 2027 | AB20: With effect from Fiscal 2022, the NMAGI is as follows: (i) AED 47 million if the actual cargo loaded quantity is more than 17 MTPA; (ii) AED 43.87 million if the cargo loaded quantity is between 15 MTPA and 17 MTPA; and (iii) AED 40.73 million if the actual cargo loaded quantity is between 13 MTPA and 15 MTPA.
B21: Dibba Terminal (UAE) | C21: JSW Terminal (Middle East) FZE | J21: UAE | V21: 2028 | AB21: Re-imbursement of actual costs incurred and O&M fees of AED 0.45/MMT for actual qty loaded
B24: Under Construction
B25: Port Asset | C25: Entity | D25: Stake, % | E25: Acquired or Created? | F25: Acquiried From? | G25: Acq Consideration, Rs. mn | H25: Asset Type | I25: Type of Agreement (Concession/Lease/License/O&M) | J25: State | K25: Capacity, MT | L25: Draft, m | M25: Cargo Type | N25: Major Cargoes Handled | O25: Expansion Plans, MTPA | P25: Expansion - Cargo type | Q25: Hinterland | R25: Key Customers | S25: Evacuation Plan/ Infrastructure | T25: CoD | U25: Concession, years | V25: Concession Expiry | W25: Concession With | X25: Guaranteed Throughput | Y25: No of Berths | Z25: Berth Length, mtrs | AA25: Annual/Lease charges (Rs. mn) | AB25: Tariff | AC25: Revenue Share | AD25: CAPEX, Rs. mn | AF25: Customer | AG25: Check in RHP Once
B26: Keni Greenfield | C26: JSW Keni Port Pvt Ltd | D26: 1 | E26: Created | F26: - | G26: - | H26: Port | I26: Concession | J26: Karnataka | K26: 30 | L26: - | M26: Multi-Cargo | N26: Multi-Cargo, The proposed Keni Port is located strategically between two operational Major Ports viz. Mormugao Port in the north and New Mangalore Port in the south. The proposed port’s hinterland is primarily of coal and coke cargo which is being utilized for steel, cement and power plants. It is also further supported by Iron ore, limestone, dolomite handlings and export of finished steel products. | O26: with further potential to increase substantially in the long run | P26: - | Q26: to serve the industries in the area covering Bellary, Hosapete, Hubballi, Kalaburagi and South Maharashtra | S26: Rail connectivity to the Keni Port site is proposed to be in southern side and will be connected with the existing Konkan line to north of the Ankola Station. The proposed railway alignment will be developed with a total length of approximately 8 km. The proposed port shall be well connected with Road and Railway Connectivity. | T26: 47178 | U26: 30 | V26: 56189 | W26: Karnataka Maritime Board | X26: - | Y26: - | Z26: - | AA26: - | AB26: - | AC26: Rs. 17/ tonne | AD26: 41190 | AG26: 1 tonne of steel requires 3 tonnes of raw material (2 tonnes of iron ore, 0.8 coking coal and 0.2 tonnes of others)
B27: Tuticorin Dry Bulk | C27: JSW Tuticorin Multipurpose Terminal Limited | D27: 1 | E27: Created | F27: - | G27: - | H27: Terminal | I27: Concession | J27: Tamil Nadu | K27: 6.96 | L27: 14.2 | M27: Bulk | N27: Coal / Coke ii) Limestone iii) Gypsum iv) Rock Phosphate v) Copper Concentrate | O27: - | P27: - | Q27: Primarily Tamil Nadu, and Kerala, Karnataka, Andhra Pradesh connected via state and NHs | R27: TANGEDCO, NTPL, Cement manufacturers, Fertiliser & chemical companies | S27: Rail — VOC Port owns and operates a 17.6 km internal railway network connecting berths to the broader Indian Railways broad-gauge network, Road — Connected to National Highways and State Highways serving Tamil Nadu, Kerala, Karnataka, and Andhra Pradesh., Conveyor system (direct) — A Link Conveyor system connects the Tuticorin Thermal Power Station's conveyor to the port's coal yard, discharging over 1,500 TPH of bulk cargo directly to the adjacent power plant. | T27: 46447 | U27: 30 | V27: 56431 | W27: V.O. CHIDAMBARANAR PORT TRUST | X27: 2.5 - 3 MT | Y27: North Cargo Berth 3 Mechanisation inculding Dredging for Handling Bulk Cargo | AB27: The Concessionaire shall, in consideration of its investment and services, be entitled to levy and collect a pre-determined user fee | AC27: Rs. 72/ tonne + WPI | AD27: 6000 | AE27: <-- RFQ document say 356cr? | AF27: All third Party | AG27: If JSW Infra exports this^ then it totally gets 4MT of Cargo
B28: Jatadhar | C28: JSW Jatadhar Marine Services Pvt Ltd | D28: 1 | E28: Created | F28: - | G28: - | H28: Port | I28: Concession | J28: Orissa | K28: 30 | L28: - | M28: Bulk | N28: Bulk - thermal coal, coking coal, iron ore, limestone | O28: 22 | P28: - | Q28: Odisha, Jagatsinghpur district — home to JSW Utkal Steel's , Nuagaon iron ore mines (Jajang, Odisha) | R28: JSW Steel | S28: Slurry Pipeline, Connected to National Highway NH-16, Rail: Howrah–Chennai main line | T28: FY28 | U28: 30 | V28: 56795 | W28: Orissa Maritime Board | X28: - | Y28: - | Z28: - | AA28: - | AB28: - | AC28: NO ROYALTY, why? | AD28: 30000
B29: Jaigarh Expansion | C29: JSW Jaigarh Port Ltd | D29: 1 | E29: Created | F29: - | G29: - | H29: Port | I29: Concession | J29: Maharashtra | K29: 15 | L29: - | M29: Multi-Cargo | N29: Bulk | O29: - | P29: - | Q29: Southern & Western Maharashtra, Northern & Central Karnataka | R29: JSW Steel, JSW Energy | S29: Connected to NH-66 (Mumbai–Goa highway) at Nivali via SH-106 (42 km four-laned highway), Jaigarh Digni Rail Line — 33.7 km new railway corridor connecting Jaigarh Port to Digni station on the Konkan Railway network | T29: 46447 | U29: 34 | V29: 57891 | W29: Maharashtra Maritime Board | X29: - | Y29: - | Z29: - | AA29: - | AB29: - | AC29: - | AD29: =K29/(K29+K30)*23590 -> 9829.1667
B30: Dharamtar Expansion | C30: JSW Dharmatar Port Private Ltd | D30: 1 | E30: Created | F30: - | G30: - | H30: Port | I30: Lease | J30: Maharashtra | K30: 21 | L30: - | M30: Bulk | N30: Bulk | O30: - | P30: - | Q30: Dolvi, Maharashtra; Kalmeshwar, Maharashtra; Mumbai & Raigad industrial belt | R30: JSW Steel, JSW Cement | S30: Direct conveyor to Dolvi Steel Plant, Mini Bulk Carriers, Connected to NH-66 (Mumbai–Goa); located 80 km south of Mumbai, 135 km from Pune, Just 2 km from Pen railway station on the Mumbai–Goa rail route | T30: 46447 | U30: - | V30: - | W30: Maharashtra Maritime Board | X30: - | Y30: 3 | Z30: - | AA30: - | AB30: - | AC30: - | AD30: =23590-AD29 -> 13760.833
B31: Slurry Pipeline Phase I | C31: XX | D31: 1 | E31: Created | F31: - | G31: - | H31: Slurry Pipeline | I31: Captive | J31: Orissa | K31: 30 | L31: - | M31: Multi-Cargo | N31: Iron Ore | O31: - | P31: - | Q31: - | R31: JSW Steel | S31: Jatdhar Port | T31: 46478 | U31: 20 | V31: 53783 | W31: - | X31: 18 MTPA take-or-pay; full capacity 30 MTPA | Y31: - | Z31: 300km Pipeline | AA31: - | AB31: 500-550Rs/tonne | AC31: - | AD31: 40000 | AF31: JSW Steel
A32: https://infra.economictimes.indiatimes.com/news/ports-shipping/maharashtra-seeks-bids-for-a-new-port-at-murbe-under-swiss-challenge-after-jsw-infra-place-suo-moto-offer/107983282 | B32: Murbe Port | C32: JSW Murbe Port Pvt Ltd | D32: 1 | E32: Created | F32: - | G32: - | H32: Port | I32: Concession | J32: Maharashtra | K32: 33 | L32: - | M32: Container | N32: Container | O32: - | P32: - | Q32: Major industrial centres and business hubs in the hinterland of the proposed por .. Read more at: https://infra.economictimes.indiatimes.com/news/ports-shipping/maharashtra-seeks-bids-for-a-new-port-at-murbe-under-swiss-challenge-after-jsw-infra-place-suo-moto-offer/107983282 | R32: JSW group, MIDC | S32: Road: NH-8 (Mumbai–Ahmedabad national highway); Rail: Located near Delhi-Mumbai trunk rail route and the Dedicated Western Freight Corridor (DWFC) | W32: Maharashtra Maritime Board | X32: - | Y32: - | Z32: - | AA32: - | AB32: - | AC32: - | AD32: 42590
B33: Oman Port | C33: XX | D33: 1 | E33: Created | F33: - | G33: - | H33: Port | I33: Concession | J33: Overseas | K33: 27 | L33: - | M33: Bulk | N33: Steel | O33: - | P33: - | Q33: - | R33: - | S33: - | T33: - | U33: - | V33: - | W33: - | X33: - | Y33: - | Z33: - | AA33: - | AB33: - | AC33: - | AD33: =300*84 -> 25200
B34: Goa shed | C34: =C6 -> South West Port Limited | E34: Created | F34: - | G34: - | H34: Port | J34: Goa | K34: =6.5-Assumptions!K116 -> 4 | M34: Bulk | N34: - | O34: - | P34: - | Q34: - | R34: - | S34: - | T34: - | U34: - | V34: - | W34: - | X34: - | Y34: - | Z34: - | AA34: - | AB34: - | AC34: -
B35: LPG terminal | C35: =C29 -> JSW Jaigarh Port Ltd | D35: 1 | E35: Created | F35: - | G35: - | H35: Port | J35: Maharashtra | K35: 2 | M35: Liquid | N35: - | O35: - | P35: - | Q35: - | R35: - | S35: - | T35: - | U35: - | V35: - | W35: - | X35: - | Y35: - | Z35: - | AA35: - | AB35: - | AC35: -
B36: Mangalore Container Expansion | C36: =C8 -> JSW Mangalore Container Terminal Pvt Ltd | D36: 1 | E36: Created | F36: - | G36: - | H36: Port | J36: Karnataka | K36: 1.82 | M36: Container | N36: - | O36: - | P36: - | Q36: - | R36: - | S36: - | T36: - | U36: - | V36: - | W36: - | X36: - | Y36: - | Z36: - | AA36: - | AB36: - | AC36: -
B37: Kolkata Container Terminal | C37: XX | D37: 1 | E37: Created | F37: - | G37: - | H37: Terminal | J37: West Bengal | K37: 7 | M37: Container | N37: Container | Q37: eastern India, Nepal, Bhutan, and the northeastern states | R37: Garment & textile exporters ,Engineering goods manufacturers | S37: Rail: NSD is directly connected to Indian Railways' Howrah–Chennai trunk line and the Eastern Railway network, Road: Connected to NH-12 and Kolkata's arterial road network; proximity to NH-19 (Golden Quadrilateral) for road-based evacuation | T37: 46631 | U37: 30 | V37: 56887 | W37: SMPKA, Kolkata | X37: - | Y37: 2 | Z37: - | AA37: - | AB37: - | AC37: Rs. 4,678/TEU | AD37: 7400
B38: Kolkata Container Terminal - 2 | C38: XX | D38: 1 | E38: Created | F38: - | G38: - | H38: Terminal | J38: West Bengal | K38: =C239 -> 12 | M38: Container | N38: Container | Q38: eastern India, Nepal, Bhutan, and the northeastern states | R38: Garment & textile exporters ,Engineering goods manufacturers | S38: Rail: NSD is directly connected to Indian Railways' Howrah–Chennai trunk line and the Eastern Railway network, Road: Connected to NH-12 and Kolkata's arterial road network; proximity to NH-19 (Golden Quadrilateral) for road-based evacuation | T38: 47149 | U38: 30 | V38: 58106 | W38: SMPKA, Kolkata | X38: - | Y38: =5+2 -> 7 | Z38: - | AA38: - | AB38: - | AC38: Rs. 3,701/TEU | AD38: 8322.5
K39: =SUM(K26:K38) -> 219.78
B41: Pipeline
C48: MT | E48: =Consol!L3 -> 0.15246338 | F48: <- forex exposure in revenues
B49: Operational | E49: =32886.7/Consol!L78 -> 0.77495383 | F49: <-The compnay has raised H 2,99,028.00 lakhs [USD 400 million] on 21st January, 2022 by issuing USD denominated senior secured “4.95 per cent. Senior Notes due 2029” (also referred as the notes)
B50: Port | C50: =SUMIF($H$4:$H$16,"Port",$K$4:$K$16) -> 97 | E50: 0.0495
...

Sheet Assumptions
S1: CAGR
B2: Volumes by Port, MT | C2: Port | D2: FY18 | E2: FY19 | F2: FY20 | G2: FY21 | H2: FY22 | I2: FY23 | J2: FY24 | K2: FY25 | L2: FY26 | M2: FY27E | N2: FY28E | O2: FY29E | P2: FY30E | S2: FY26-28E | T2: FY26-30E
B3: Standalone | D3: 0 | E3: 4.19 | F3: 3.1759323 | G3: 3.59 | H3: 3.0277206 | I3: 2.7 | J3: 2.65 | K3: 2.4 | L3: 2.99 | M3: =M943 -> 2.99 | N3: =N943 -> 3.0498 | O3: =O943 -> 3.110796 | P3: =P943 -> 3.1730119 | R3: =N3-M3 -> 0.0598 | S3: =IF(ISERROR((N3/L3)^(1/6)-1)," ",(N3/L3)^(1/2)-1) -> 0.0099504938 | T3: =IF(ISERROR((P3/L3)^(1/6)-1)," ",(P3/L3)^(1/4)-1) -> 0.014962809 | X3: =E2 -> FY19 | Y3: =F2 -> FY20 | Z3: =G2 -> FY21 | AA3: =H2 -> FY22 | AB3: =I2 -> FY23 | AC3: =J2 -> FY24
B4: Jaigarh | D4: 9.535 | E4: 13.05 | F4: 10.370319 | G4: 9.238 | H4: 14.019484 | I4: 20.237 | J4: 21.51 | K4: 19.9 | L4: 20.27 | M4: =M468 -> 21.0808 | N4: =N468 -> 26.303368 | O4: =O468 -> 28.933705 | P4: =P468 -> 30.38039 | Q4: << without transhipment volumes of large ships, trans shipment revenue booked in Jaigarh | R4: =N4-M4 -> 5.222568 | S4: =IF(ISERROR((N4/L4)^(1/6)-1)," ",(N4/L4)^(1/2)-1) -> 0.13914447 | T4: =IF(ISERROR((P4/L4)^(1/6)-1)," ",(P4/L4)^(1/4)-1) -> 0.10645791 | W4: East Coast | X4: =E7+E8+E9+E10 -> 0 | Y4: =F7+F8+F9+F10 -> 1.013 | Z4: =G7+G8+G9+G10 -> 11.96 | AA4: =H7+H8+H9+H10 -> 16.989441 | AB4: =I7+I8+I9+I10 -> 32.148 | AC4: =J7+J8+J9+J10 -> 39.91
