Workbook

Sheet README
A1: FORMULA-DRIVEN DAM ANALYSIS - sold and purchased volumes in the Day Ahead Market through power exchanges
A2: Source: CERC Market Monitoring monthly reports, 2020-01 to 2026-03. Units: MU.
A4: HOW THE SHEETS CHAIN (no pasted numbers beyond the first two)
A5: 1. Monthly_Sold, Monthly_Purchased - raw rows as printed in the reports (month, entity, volume, %). Columns CY, FY, Player, Group are formulas.
A6: 2. Mapping - printed name -> Player -> Group. The only place names are decided. Edit Player/Group here and every downstream sheet recalculates.
A7: 3. Annual_* - SUMIFS over the Monthly sheet by Player and year. Includes TOTAL, unique rank on TOTAL, unique rank per year, and a reconciliation row (OK / MISMATCH) against the Monthly sheet.
A8: 4. Top15_* - pulls players ranked 1-15 from Annual_* by INDEX/MATCH; Others = Total - top 15. Share block below.
A9: 5. Top15_ByYear_* - each year's own top 15 from the per-year rank columns of Annual_*.
A10: 6. AnnualGroup_* / Top15Group_* - same as 3-4 but by parent Group (Adani Green SPVs, NTPC stations etc. rolled up).
A12: PERIODS
A13: - CY = calendar year. FY = April-March fiscal year.
A14: - Partial periods: CY 2026: 2026-01 to 2026-03 only; FY FY2019-20: 2020-01 to 2020-03 only.
... A26: - Workbook is set to recalculate fully on open. If a sheet shows zeros, press Ctrl+Alt+F9 in Excel.

Sheet Mapping
A1: printed_name (normalised) | B1: Player <- edit | C1: Group <- edit | D1: renamed | E1: tables | F1: first_month | G1: last_month | H1: months | I1: total_mu
A2: GUJARAT | B2: GUJARAT | C2: GUJARAT | E2: purchased/sold | F2: 2020-01 | G2: 2026-03 | H2: 150 | I2: 69790.74
A3: TELANGANA | B3: TELANGANA | C3: TELANGANA | E3: purchased/sold | F3: 2020-01 | G3: 2026-03 | H3: 149 | I3: 57343.18
A4: UTTAR PRADESH | B4: UTTAR PRADESH | C4: UTTAR PRADESH | E4: purchased/sold | F4: 2020-01 | G4: 2026-03 | H4: 150 | I4: 52545.06
A5: MAHARASHTRA | B5: MAHARASHTRA | C5: MAHARASHTRA | E5: purchased/sold | F5: 2020-01 | G5: 2026-03 | H5: 150 | I5: 38444.52
A6: ANDHRA PRADESH | B6: ANDHRA PRADESH | C6: ANDHRA PRADESH | E6: purchased/sold | F6: 2020-01 | G6: 2026-03 | H6: 150 | I6: 33738.21
A7: WEST BENGAL | B7: WEST BENGAL | C7: WEST BENGAL | E7: purchased/sold | F7: 2020-01 | G7: 2026-03 | H7: 148 | I7: 31439.47
A8: TAMIL NADU | B8: TAMIL NADU | C8: TAMIL NADU | E8: purchased/sold | F8: 2020-01 | G8: 2026-03 | H8: 149 | I8: 26111.9
A9: RAJASTHAN | B9: RAJASTHAN | C9: RAJASTHAN | E9: purchased/sold | F9: 2020-01 | G9: 2026-03 | H9: 150 | I9: 24950.74
A10: PUNJAB | B10: PUNJAB | C10: PUNJAB | E10: purchased/sold | F10: 2020-01 | G10: 2026-03 | H10: 126 | I10: 20849.27
A11: ODISHA | B11: ODISHA | C11: ODISHA | E11: purchased/sold | F11: 2020-01 | G11: 2026-03 | H11: 150 | I11: 20811.77
A12: HARYANA | B12: HARYANA | C12: HARYANA | E12: purchased/sold | F12: 2020-01 | G12: 2026-03 | H12: 149 | I12: 17890.55
A13: BIHAR | B13: BIHAR | C13: BIHAR | E13: purchased/sold | F13: 2020-01 | G13: 2026-03 | H13: 148 | I13: 17882.84
... A16: DELHI | B16: DELHI | C16: DELHI | E16: purchased/sold | F16: 2020-01 | G16: 2026-03 | H16: 150 | I16: 15766.17
A17: MP | B17: MADHYA PRADESH | C17: MADHYA PRADESH | D17: yes | E17: purchased/sold | F17: 2020-01 | G17: 2024-07 | H17: 110 | I17: 12654.59
A18: HIMACHAL PRADESH | B18: HIMACHAL PRADESH | C18: HIMACHAL PRADESH | E18: purchased/sold | F18: 2020-01 | G18: 2026-03 | H18: 150 | I18: 11842.55
A19: J & K | B19: JAMMU & KASHMIR | C19: JAMMU & KASHMIR | D19: yes | E19: purchased/sold | F19: 2020-01 | G19: 2024-07 | H19: 91 | I19: 11332.54
A20: UTTARAKHAND | B20: UTTARAKHAND | C20: UTTARAKHAND | E20: purchased/sold | F20: 2020-01 | G20: 2026-03 | H20: 135 | I20: 11296.96
A21: SEMBCORP | B21: SEIL ENERGY INDIA (EX-SEMBCORP) | C21: SEIL ENERGY INDIA | D21: yes | E21: sold | F21: 2020-01 | G21: 2024-07 | H21: 53 | I21: 8978.48
A22: ASSAM | B22: ASSAM | C22: ASSAM | E22: purchased/sold | F22: 2020-01 | G22: 2026-03 | H22: 136 | I22: 8884.77
A23: TEESTA STG3 | B23: TEESTA URJA (TEESTA-III HEP) | C23: TEESTA URJA (TEESTA-III HEP) | D23: yes | E23: sold | F23: 2020-01 | G23: 2022-08 | H23: 30 | I23: 8347.91
A24: JAYPEE NIGRIE | B24: JAYPEE NIGRIE STPP | C24: JAYPEE NIGRIE STPP | D24: yes | E24: sold | F24: 2020-01 | G24: 2024-07 | H24: 55 | I24: 7183.88
A25: JINDAL STAGE-II | B25: JINDAL POWER LTD - STAGE 2 | C25: JINDAL POWER LTD (BOTH STAGES) | D25: yes | E25: purchased/sold | F25: 2020-02 | G25: 2024-07 | H25: 54 | I25: 7137.04
A26: KERALA | B26: KERALA | C26: KERALA | E26: purchased/sold | F26: 2020-01 | G26: 2026-03 | H26: 150 | I26: 6957.96
A27: JINDAL POWER | B27: JINDAL POWER LTD - STAGE 1 | C27: JINDAL POWER LTD (BOTH STAGES) | D27: yes | E27: purchased/sold | F27: 2020-01 | G27: 2024-07 | H27: 57 | I27: 6646.39
A28: NEPAL(NVVN) | B28: NEPAL (NEA / NVVN) | C28: NEPAL (NEA / NVVN) | D28: yes | E28: purchased/sold | F28: 2021-04 | G28: 2024-07 | H28: 46 | I28: 6246.72
A29: JINDAL POWER LIMITED, STAGE-2 | B29: JINDAL POWER LTD - STAGE 2 | C29: JINDAL POWER LTD (BOTH STAGES) | D29: yes | E29: purchased/sold | F29: 2024-08 | G29: 2026-03 | H29: 21 | I29: 6213.66
A30: ESSAR POWER | B30: MAHAN ENERGEN (EX-ESSAR POWER MP) | C30: ADANI POWER (ALL PLANTS) | D30: yes | E30: sold | F30: 2020-01 | G30: 2024-07 | H30: 55 | I30: 5936.77
A31: JITPL | B31: JINDAL INDIA THERMAL POWER (JITPL) | C31: JINDAL INDIA THERMAL POWER (JITPL) | D31: yes | E31: sold | F31: 2020-01 | G31: 2024-07 | H31: 55 | I31: 5822.96
A32: DB POWER | B32: DB POWER | C32: DB POWER | E32: sold | F32: 2020-01 | G32: 2024-07 | H32: 55 | I32: 5715.87
A33: MADHYA PRADESH | B33: MADHYA PRADESH | C33: MADHYA PRADESH | E33: purchased/sold | F33: 2024-08 | G33: 2026-03 | H33: 40 | I33: 5161.25
A34: RPREL | B34: ADANI POWER - RAIPUR TPP (EX-GMR CHHATTISGARH) | C34: ADANI POWER (ALL PLANTS) | D34: yes | E34: sold | F34: 2020-04 | G34: 2023-06 | H34: 39 | I34: 4015.94
A35: MB POWER | B35: MB POWER (MP) | C35: MB POWER (MP) | D35: yes | E35: purchased/sold | F35: 2020-01 | G35: 2024-07 | H35: 60 | I35: 3923.55
A36: AMPS HAZIRA | B36: AM/NS INDIA (HAZIRA) | C36: AM/NS INDIA (HAZIRA) | D36: yes | E36: purchased/sold | F36: 2020-04 | G36: 2024-07 | H36: 53 | I36: 3713.12
A37: ADANI POWER LIMITED-RAIPUR TPP | B37: ADANI POWER - RAIPUR TPP (EX-GMR CHHATTISGARH) | C37: ADANI POWER (ALL PLANTS) | D37: yes | E37: purchased/sold | F37: 2024-08 | G37: 2026-03 | H37: 23 | I37: 3648.21
A38: JHARKHAND | B38: JHARKHAND | C38: JHARKHAND | E38: purchased/sold | F38: 2020-01 | G38: 2026-03 | H38: 133 | I38: 3136.46
A39: DRUK GREEN POWER CORPORATION LIMITED (DGPCL-BHUTAN) | B39: DRUK GREEN POWER (BHUTAN) | C39: DRUK GREEN POWER (BHUTAN) | D39: yes | E39: purchased | F39: 2024-11 | G39: 2026-03 | H39: 11 | I39: 2706
A40: JINDAL POWER LIMITED, STAGE-1 | B40: JINDAL POWER LTD - STAGE 1 | C40: JINDAL POWER LTD (BOTH STAGES) | D40: yes | E40: sold | F40: 2024-08 | G40: 2026-03 | H40: 20 | I40: 2644.25
A41: DD&DNH | B41: DNH & DD (UT) | C41: DNH & DD (UT) | D41: yes | E41: purchased | F41: 2022-06 | G41: 2024-07 | H41: 26 | I41: 2565.94
A42: ARTPP | B42: ADANI POWER - RAIPUR TPP (EX-GMR CHHATTISGARH) | C42: ADANI POWER (ALL PLANTS) | D42: yes | E42: sold | F42: 2023-07 | G42: 2024-07 | H42: 13 | I42: 2430.58
...

Sheet Monthly_Sold
A1: month | B1: CY | C1: FY | D1: entity (as printed) | E1: printed_name (normalised) | F1: Player | G1: Group | H1: volume_mu | I1: pct_of_table
A2: 2020-01 | B2: =VALUE(LEFT(A2,4)) -> 2020 | C2: ="FY"&IF(VALUE(MID(A2,6,2))>=4,VALUE(LEFT(A2,4)),VALUE(LEFT(A2,4))-1)&"-"&TEXT(MOD(IF(VALUE(MID(A2,6,2))>=4,VALUE(LEFT(A2,4)),VALUE(LEFT(A2,4))-1)+1,100),"00") -> FY2019-20 | D2: SEMBCORP | E2: SEMBCORP | F2: =INDEX(Mapping!$B$2:$B$465,MATCH(E2,Mapping!$A$2:$A$465,0)) -> SEIL ENERGY INDIA (EX-SEMBCORP) | G2: =INDEX(Mapping!$C$2:$C$465,MATCH(E2,Mapping!$A$2:$A$465,0)) -> SEIL ENERGY INDIA | H2: 527.61 | I2: 11.01
A3: 2020-01 | B3: =VALUE(LEFT(A3,4)) -> 2020 | C3: ="FY"&IF(VALUE(MID(A3,6,2))>=4,VALUE(LEFT(A3,4)),VALUE(LEFT(A3,4))-1)&"-"&TEXT(MOD(IF(VALUE(MID(A3,6,2))>=4,VALUE(LEFT(A3,4)),VALUE(LEFT(A3,4))-1)+1,100),"00") -> FY2019-20 | D3: MP | E3: MP | F3: =INDEX(Mapping!$B$2:$B$465,MATCH(E3,Mapping!$A$2:$A$465,0)) -> MADHYA PRADESH | G3: =INDEX(Mapping!$C$2:$C$465,MATCH(E3,Mapping!$A$2:$A$465,0)) -> MADHYA PRADESH | H3: 493.24 | I3: 10.29
A4: 2020-01 | B4: =VALUE(LEFT(A4,4)) -> 2020 | C4: ="FY"&IF(VALUE(MID(A4,6,2))>=4,VALUE(LEFT(A4,4)),VALUE(LEFT(A4,4))-1)&"-"&TEXT(MOD(IF(VALUE(MID(A4,6,2))>=4,VALUE(LEFT(A4,4)),VALUE(LEFT(A4,4))-1)+1,100),"00") -> FY2019-20 | D4: GUJARAT | E4: GUJARAT | F4: =INDEX(Mapping!$B$2:$B$465,MATCH(E4,Mapping!$A$2:$A$465,0)) -> GUJARAT | G4: =INDEX(Mapping!$C$2:$C$465,MATCH(E4,Mapping!$A$2:$A$465,0)) -> GUJARAT | H4: 426.61 | I4: 8.9
A5: 2020-01 | B5: =VALUE(LEFT(A5,4)) -> 2020 | C5: ="FY"&IF(VALUE(MID(A5,6,2))>=4,VALUE(LEFT(A5,4)),VALUE(LEFT(A5,4))-1)&"-"&TEXT(MOD(IF(VALUE(MID(A5,6,2))>=4,VALUE(LEFT(A5,4)),VALUE(LEFT(A5,4))-1)+1,100),"00") -> FY2019-20 | D5: GMR CHATTISGARH | E5: GMR CHATTISGARH | F5: =INDEX(Mapping!$B$2:$B$465,MATCH(E5,Mapping!$A$2:$A$465,0)) -> ADANI POWER - RAIPUR TPP (EX-GMR CHHATTISGARH) | G5: =INDEX(Mapping!$C$2:$C$465,MATCH(E5,Mapping!$A$2:$A$465,0)) -> ADANI POWER (ALL PLANTS) | H5: 374.35 | I5: 7.81
A6: 2020-01 | B6: =VALUE(LEFT(A6,4)) -> 2020 | C6: ="FY"&IF(VALUE(MID(A6,6,2))>=4,VALUE(LEFT(A6,4)),VALUE(LEFT(A6,4))-1)&"-"&TEXT(MOD(IF(VALUE(MID(A6,6,2))>=4,VALUE(LEFT(A6,4)),VALUE(LEFT(A6,4))-1)+1,100),"00") -> FY2019-20 | D6: ODISHA | E6: ODISHA | F6: =INDEX(Mapping!$B$2:$B$465,MATCH(E6,Mapping!$A$2:$A$465,0)) -> ODISHA | G6: =INDEX(Mapping!$C$2:$C$465,MATCH(E6,Mapping!$A$2:$A$465,0)) -> ODISHA | H6: 219.9 | I6: 4.59
A7: 2020-01 | B7: =VALUE(LEFT(A7,4)) -> 2020 | C7: ="FY"&IF(VALUE(MID(A7,6,2))>=4,VALUE(LEFT(A7,4)),VALUE(LEFT(A7,4))-1)&"-"&TEXT(MOD(IF(VALUE(MID(A7,6,2))>=4,VALUE(LEFT(A7,4)),VALUE(LEFT(A7,4))-1)+1,100),"00") -> FY2019-20 | D7: MB POWER | E7: MB POWER | F7: =INDEX(Mapping!$B$2:$B$465,MATCH(E7,Mapping!$A$2:$A$465,0)) -> MB POWER (MP) | G7: =INDEX(Mapping!$C$2:$C$465,MATCH(E7,Mapping!$A$2:$A$465,0)) -> MB POWER (MP) | H7: 211.68 | I7: 4.42
A8: 2020-01 | B8: =VALUE(LEFT(A8,4)) -> 2020 | C8: ="FY"&IF(VALUE(MID(A8,6,2))>=4,VALUE(LEFT(A8,4)),VALUE(LEFT(A8,4))-1)&"-"&TEXT(MOD(IF(VALUE(MID(A8,6,2))>=4,VALUE(LEFT(A8,4)),VALUE(LEFT(A8,4))-1)+1,100),"00") -> FY2019-20 | D8: RAJASTHAN | E8: RAJASTHAN | F8: =INDEX(Mapping!$B$2:$B$465,MATCH(E8,Mapping!$A$2:$A$465,0)) -> RAJASTHAN | G8: =INDEX(Mapping!$C$2:$C$465,MATCH(E8,Mapping!$A$2:$A$465,0)) -> RAJASTHAN | H8: 200.41 | I8: 4.18
A9: 2020-01 | B9: =VALUE(LEFT(A9,4)) -> 2020 | C9: ="FY"&IF(VALUE(MID(A9,6,2))>=4,VALUE(LEFT(A9,4)),VALUE(LEFT(A9,4))-1)&"-"&TEXT(MOD(IF(VALUE(MID(A9,6,2))>=4,VALUE(LEFT(A9,4)),VALUE(LEFT(A9,4))-1)+1,100),"00") -> FY2019-20 | D9: JAYPEE NIGRIE | E9: JAYPEE NIGRIE | F9: =INDEX(Mapping!$B$2:$B$465,MATCH(E9,Mapping!$A$2:$A$465,0)) -> JAYPEE NIGRIE STPP | G9: =INDEX(Mapping!$C$2:$C$465,MATCH(E9,Mapping!$A$2:$A$465,0)) -> JAYPEE NIGRIE STPP | H9: 171.66 | I9: 3.58
A10: 2020-01 | B10: =VALUE(LEFT(A10,4)) -> 2020 | C10: ="FY"&IF(VALUE(MID(A10,6,2))>=4,VALUE(LEFT(A10,4)),VALUE(LEFT(A10,4))-1)&"-"&TEXT(MOD(IF(VALUE(MID(A10,6,2))>=4,VALUE(LEFT(A10,4)),VALUE(LEFT(A10,4))-1)+1,100),"00") -> FY2019-20 | D10: UTTAR PRADESH | E10: UTTAR PRADESH | F10: =INDEX(Mapping!$B$2:$B$465,MATCH(E10,Mapping!$A$2:$A$465,0)) -> UTTAR PRADESH | G10: =INDEX(Mapping!$C$2:$C$465,MATCH(E10,Mapping!$A$2:$A$465,0)) -> UTTAR PRADESH | H10: 162.55 | I10: 3.39
A11: 2020-01 | B11: =VALUE(LEFT(A11,4)) -> 2020 | C11: ="FY"&IF(VALUE(MID(A11,6,2))>=4,VALUE(LEFT(A11,4)),VALUE(LEFT(A11,4))-1)&"-"&TEXT(MOD(IF(VALUE(MID(A11,6,2))>=4,VALUE(LEFT(A11,4)),VALUE(LEFT(A11,4))-1)+1,100),"00") -> FY2019-20 | D11: JINDAL POWER | E11: JINDAL POWER | F11: =INDEX(Mapping!$B$2:$B$465,MATCH(E11,Mapping!$A$2:$A$465,0)) -> JINDAL POWER LTD - STAGE 1 | G11: =INDEX(Mapping!$C$2:$C$465,MATCH(E11,Mapping!$A$2:$A$465,0)) -> JINDAL POWER LTD (BOTH STAGES) | H11: 139.26 | I11: 2.91
A12: 2020-01 | B12: =VALUE(LEFT(A12,4)) -> 2020 | C12: ="FY"&IF(VALUE(MID(A12,6,2))>=4,VALUE(LEFT(A12,4)),VALUE(LEFT(A12,4))-1)&"-"&TEXT(MOD(IF(VALUE(MID(A12,6,2))>=4,VALUE(LEFT(A12,4)),VALUE(LEFT(A12,4))-1)+1,100),"00") -> FY2019-20 | D12: DB POWER | E12: DB POWER | F12: =INDEX(Mapping!$B$2:$B$465,MATCH(E12,Mapping!$A$2:$A$465,0)) -> DB POWER | G12: =INDEX(Mapping!$C$2:$C$465,MATCH(E12,Mapping!$A$2:$A$465,0)) -> DB POWER | H12: 138.1 | I12: 2.88
A13: 2020-01 | B13: =VALUE(LEFT(A13,4)) -> 2020 | C13: ="FY"&IF(VALUE(MID(A13,6,2))>=4,VALUE(LEFT(A13,4)),VALUE(LEFT(A13,4))-1)&"-"&TEXT(MOD(IF(VALUE(MID(A13,6,2))>=4,VALUE(LEFT(A13,4)),VALUE(LEFT(A13,4))-1)+1,100),"00") -> FY2019-20 | D13: ASSAM | E13: ASSAM | F13: =INDEX(Mapping!$B$2:$B$465,MATCH(E13,Mapping!$A$2:$A$465,0)) -> ASSAM | G13: =INDEX(Mapping!$C$2:$C$465,MATCH(E13,Mapping!$A$2:$A$465,0)) -> ASSAM | H13: 136.42 | I13: 2.85
... A7864: 2026-03 | B7864: =VALUE(LEFT(A7864,4)) -> 2026 | C7864: ="FY"&IF(VALUE(MID(A7864,6,2))>=4,VALUE(LEFT(A7864,4)),VALUE(LEFT(A7864,4))-1)&"-"&TEXT(MOD(IF(VALUE(MID(A7864,6,2))>=4,VALUE(LEFT(A7864,4)),VALUE(LEFT(A7864,4))-1)+1,100),"00") -> FY2025-26 | D7864: NLC INDIA LIMITED THERMAL POWER STATION I EXPANSION | E7864: NLC INDIA LIMITED THERMAL POWER STATION I EXPANSION | F7864: =INDEX(Mapping!$B$2:$B$465,MATCH(E7864,Mapping!$A$2:$A$465,0)) -> NLC INDIA | G7864: =INDEX(Mapping!$C$2:$C$465,MATCH(E7864,Mapping!$A$2:$A$465,0)) -> NLC INDIA GROUP | H7864: 0.004 | I7864: 0.0001

Sheet Monthly_Purchased
A1: month | B1: CY | C1: FY | D1: entity (as printed) | E1: printed_name (normalised) | F1: Player | G1: Group | H1: volume_mu | I1: pct_of_table
A2: 2020-01 | B2: =VALUE(LEFT(A2,4)) -> 2020 | C2: ="FY"&IF(VALUE(MID(A2,6,2))>=4,VALUE(LEFT(A2,4)),VALUE(LEFT(A2,4))-1)&"-"&TEXT(MOD(IF(VALUE(MID(A2,6,2))>=4,VALUE(LEFT(A2,4)),VALUE(LEFT(A2,4))-1)+1,100),"00") -> FY2019-20 | D2: TELANGANA | E2: TELANGANA | F2: =INDEX(Mapping!$B$2:$B$465,MATCH(E2,Mapping!$A$2:$A$465,0)) -> TELANGANA | G2: =INDEX(Mapping!$C$2:$C$465,MATCH(E2,Mapping!$A$2:$A$465,0)) -> TELANGANA | H2: 920.41 | I2: 19.21
A3: 2020-01 | B3: =VALUE(LEFT(A3,4)) -> 2020 | C3: ="FY"&IF(VALUE(MID(A3,6,2))>=4,VALUE(LEFT(A3,4)),VALUE(LEFT(A3,4))-1)&"-"&TEXT(MOD(IF(VALUE(MID(A3,6,2))>=4,VALUE(LEFT(A3,4)),VALUE(LEFT(A3,4))-1)+1,100),"00") -> FY2019-20 | D3: GUJARAT | E3: GUJARAT | F3: =INDEX(Mapping!$B$2:$B$465,MATCH(E3,Mapping!$A$2:$A$465,0)) -> GUJARAT | G3: =INDEX(Mapping!$C$2:$C$465,MATCH(E3,Mapping!$A$2:$A$465,0)) -> GUJARAT | H3: 525.95 | I3: 10.98
A4: 2020-01 | B4: =VALUE(LEFT(A4,4)) -> 2020 | C4: ="FY"&IF(VALUE(MID(A4,6,2))>=4,VALUE(LEFT(A4,4)),VALUE(LEFT(A4,4))-1)&"-"&TEXT(MOD(IF(VALUE(MID(A4,6,2))>=4,VALUE(LEFT(A4,4)),VALUE(LEFT(A4,4))-1)+1,100),"00") -> FY2019-20 | D4: MAHARASHTRA | E4: MAHARASHTRA | F4: =INDEX(Mapping!$B$2:$B$465,MATCH(E4,Mapping!$A$2:$A$465,0)) -> MAHARASHTRA | G4: =INDEX(Mapping!$C$2:$C$465,MATCH(E4,Mapping!$A$2:$A$465,0)) -> MAHARASHTRA | H4: 435.65 | I4: 9.09
A5: 2020-01 | B5: =VALUE(LEFT(A5,4)) -> 2020 | C5: ="FY"&IF(VALUE(MID(A5,6,2))>=4,VALUE(LEFT(A5,4)),VALUE(LEFT(A5,4))-1)&"-"&TEXT(MOD(IF(VALUE(MID(A5,6,2))>=4,VALUE(LEFT(A5,4)),VALUE(LEFT(A5,4))-1)+1,100),"00") -> FY2019-20 | D5: TAMIL NADU | E5: TAMIL NADU | F5: =INDEX(Mapping!$B$2:$B$465,MATCH(E5,Mapping!$A$2:$A$465,0)) -> TAMIL NADU | G5: =INDEX(Mapping!$C$2:$C$465,MATCH(E5,Mapping!$A$2:$A$465,0)) -> TAMIL NADU | H5: 382.14 | I5: 7.97
A6: 2020-01 | B6: =VALUE(LEFT(A6,4)) -> 2020 | C6: ="FY"&IF(VALUE(MID(A6,6,2))>=4,VALUE(LEFT(A6,4)),VALUE(LEFT(A6,4))-1)&"-"&TEXT(MOD(IF(VALUE(MID(A6,6,2))>=4,VALUE(LEFT(A6,4)),VALUE(LEFT(A6,4))-1)+1,100),"00") -> FY2019-20 | D6: J & K | E6: J & K | F6: =INDEX(Mapping!$B$2:$B$465,MATCH(E6,Mapping!$A$2:$A$465,0)) -> JAMMU & KASHMIR | G6: =INDEX(Mapping!$C$2:$C$465,MATCH(E6,Mapping!$A$2:$A$465,0)) -> JAMMU & KASHMIR | H6: 349.19 | I6: 7.29
A7: 2020-01 | B7: =VALUE(LEFT(A7,4)) -> 2020 | C7: ="FY"&IF(VALUE(MID(A7,6,2))>=4,VALUE(LEFT(A7,4)),VALUE(LEFT(A7,4))-1)&"-"&TEXT(MOD(IF(VALUE(MID(A7,6,2))>=4,VALUE(LEFT(A7,4)),VALUE(LEFT(A7,4))-1)+1,100),"00") -> FY2019-20 | D7: DELHI | E7: DELHI | F7: =INDEX(Mapping!$B$2:$B$465,MATCH(E7,Mapping!$A$2:$A$465,0)) -> DELHI | G7: =INDEX(Mapping!$C$2:$C$465,MATCH(E7,Mapping!$A$2:$A$465,0)) -> DELHI | H7: 311.38 | I7: 6.5
A8: 2020-01 | B8: =VALUE(LEFT(A8,4)) -> 2020 | C8: ="FY"&IF(VALUE(MID(A8,6,2))>=4,VALUE(LEFT(A8,4)),VALUE(LEFT(A8,4))-1)&"-"&TEXT(MOD(IF(VALUE(MID(A8,6,2))>=4,VALUE(LEFT(A8,4)),VALUE(LEFT(A8,4))-1)+1,100),"00") -> FY2019-20 | D8: RAJASTHAN | E8: RAJASTHAN | F8: =INDEX(Mapping!$B$2:$B$465,MATCH(E8,Mapping!$A$2:$A$465,0)) -> RAJASTHAN | G8: =INDEX(Mapping!$C$2:$C$465,MATCH(E8,Mapping!$A$2:$A$465,0)) -> RAJASTHAN | H8: 303.42 | I8: 6.33
A9: 2020-01 | B9: =VALUE(LEFT(A9,4)) -> 2020 | C9: ="FY"&IF(VALUE(MID(A9,6,2))>=4,VALUE(LEFT(A9,4)),VALUE(LEFT(A9,4))-1)&"-"&TEXT(MOD(IF(VALUE(MID(A9,6,2))>=4,VALUE(LEFT(A9,4)),VALUE(LEFT(A9,4))-1)+1,100),"00") -> FY2019-20 | D9: BIHAR | E9: BIHAR | F9: =INDEX(Mapping!$B$2:$B$465,MATCH(E9,Mapping!$A$2:$A$465,0)) -> BIHAR | G9: =INDEX(Mapping!$C$2:$C$465,MATCH(E9,Mapping!$A$2:$A$465,0)) -> BIHAR | H9: 206.79 | I9: 4.32
A10: 2020-01 | B10: =VALUE(LEFT(A10,4)) -> 2020 | C10: ="FY"&IF(VALUE(MID(A10,6,2))>=4,VALUE(LEFT(A10,4)),VALUE(LEFT(A10,4))-1)&"-"&TEXT(MOD(IF(VALUE(MID(A10,6,2))>=4,VALUE(LEFT(A10,4)),VALUE(LEFT(A10,4))-1)+1,100),"00") -> FY2019-20 | D10: PUNJAB | E10: PUNJAB | F10: =INDEX(Mapping!$B$2:$B$465,MATCH(E10,Mapping!$A$2:$A$465,0)) -> PUNJAB | G10: =INDEX(Mapping!$C$2:$C$465,MATCH(E10,Mapping!$A$2:$A$465,0)) -> PUNJAB | H10: 152.99 | I10: 3.19
A11: 2020-01 | B11: =VALUE(LEFT(A11,4)) -> 2020 | C11: ="FY"&IF(VALUE(MID(A11,6,2))>=4,VALUE(LEFT(A11,4)),VALUE(LEFT(A11,4))-1)&"-"&TEXT(MOD(IF(VALUE(MID(A11,6,2))>=4,VALUE(LEFT(A11,4)),VALUE(LEFT(A11,4))-1)+1,100),"00") -> FY2019-20 | D11: HARYANA | E11: HARYANA | F11: =INDEX(Mapping!$B$2:$B$465,MATCH(E11,Mapping!$A$2:$A$465,0)) -> HARYANA | G11: =INDEX(Mapping!$C$2:$C$465,MATCH(E11,Mapping!$A$2:$A$465,0)) -> HARYANA | H11: 139.41 | I11: 2.91
A12: 2020-01 | B12: =VALUE(LEFT(A12,4)) -> 2020 | C12: ="FY"&IF(VALUE(MID(A12,6,2))>=4,VALUE(LEFT(A12,4)),VALUE(LEFT(A12,4))-1)&"-"&TEXT(MOD(IF(VALUE(MID(A12,6,2))>=4,VALUE(LEFT(A12,4)),VALUE(LEFT(A12,4))-1)+1,100),"00") -> FY2019-20 | D12: CHHATTISGARH | E12: CHHATTISGARH | F12: =INDEX(Mapping!$B$2:$B$465,MATCH(E12,Mapping!$A$2:$A$465,0)) -> CHHATTISGARH | G12: =INDEX(Mapping!$C$2:$C$465,MATCH(E12,Mapping!$A$2:$A$465,0)) -> CHHATTISGARH | H12: 134.38 | I12: 2.8
A13: 2020-01 | B13: =VALUE(LEFT(A13,4)) -> 2020 | C13: ="FY"&IF(VALUE(MID(A13,6,2))>=4,VALUE(LEFT(A13,4)),VALUE(LEFT(A13,4))-1)&"-"&TEXT(MOD(IF(VALUE(MID(A13,6,2))>=4,VALUE(LEFT(A13,4)),VALUE(LEFT(A13,4))-1)+1,100),"00") -> FY2019-20 | D13: UTTAR PRADESH | E13: UTTAR PRADESH | F13: =INDEX(Mapping!$B$2:$B$465,MATCH(E13,Mapping!$A$2:$A$465,0)) -> UTTAR PRADESH | G13: =INDEX(Mapping!$C$2:$C$465,MATCH(E13,Mapping!$A$2:$A$465,0)) -> UTTAR PRADESH | H13: 133.27 | I13: 2.78
... A2607: 2026-03 | B2607: =VALUE(LEFT(A2607,4)) -> 2026 | C2607: ="FY"&IF(VALUE(MID(A2607,6,2))>=4,VALUE(LEFT(A2607,4)),VALUE(LEFT(A2607,4))-1)&"-"&TEXT(MOD(IF(VALUE(MID(A2607,6,2))>=4,VALUE(LEFT(A2607,4)),VALUE(LEFT(A2607,4))-1)+1,100),"00") -> FY2025-26 | D2607: Arunachal Pradesh | E2607: ARUNACHAL PRADESH | F2607: =INDEX(Mapping!$B$2:$B$465,MATCH(E2607,Mapping!$A$2:$A$465,0)) -> ARUNACHAL PRADESH | G2607: =INDEX(Mapping!$C$2:$C$465,MATCH(E2607,Mapping!$A$2:$A$465,0)) -> ARUNACHAL PRADESH | H2607: 0.02 | I2607: 0.0002

Sheet Annual_Sold_CY
A1: SOLD in DAM by player and CY (MU). Formulas: SUMIFS over Monthly_Sold. | H1: 2026-01 to 2026-03 only
A2: Player | B2: 2020 | C2: 2021 | D2: 2022 | E2: 2023 | F2: 2024 | G2: 2025 | H2: 2026 | I2: TOTAL | J2: Rank (TOTAL) | K2: Rank 2020 | L2: Rank 2021 | M2: Rank 2022 | N2: Rank 2023 | O2: Rank 2024 | P2: Rank 2025 | Q2: Rank 2026
A3: 2X600 VEDANTA LIMITED CHHATTISGARH POWER PLANT | B3: =ROUND(SUMIFS(Monthly_Sold!$H$2:$H$7864,Monthly_Sold!$F$2:$F$7864,$A3,Monthly_Sold!$B$2:$B$7864,B$2),4) -> 0 | C3: =ROUND(SUMIFS(Monthly_Sold!$H$2:$H$7864,Monthly_Sold!$F$2:$F$7864,$A3,Monthly_Sold!$B$2:$B$7864,C$2),4) -> 0 | D3: =ROUND(SUMIFS(Monthly_Sold!$H$2:$H$7864,Monthly_Sold!$F$2:$F$7864,$A3,Monthly_Sold!$B$2:$B$7864,D$2),4) -> 0 | E3: =ROUND(SUMIFS(Monthly_Sold!$H$2:$H$7864,Monthly_Sold!$F$2:$F$7864,$A3,Monthly_Sold!$B$2:$B$7864,E$2),4) -> 0 | F3: =ROUND(SUMIFS(Monthly_Sold!$H$2:$H$7864,Monthly_Sold!$F$2:$F$7864,$A3,Monthly_Sold!$B$2:$B$7864,F$2),4) -> 0 | G3: =ROUND(SUMIFS(Monthly_Sold!$H$2:$H$7864,Monthly_Sold!$F$2:$F$7864,$A3,Monthly_Sold!$B$2:$B$7864,G$2),4) -> 66.58 | H3: =ROUND(SUMIFS(Monthly_Sold!$H$2:$H$7864,Monthly_Sold!$F$2:$F$7864,$A3,Monthly_Sold!$B$2:$B$7864,H$2),4) -> 25.45 | I3: =ROUND(SUM(B3:H3),4) -> 92.03 | J3: =RANK(I3,$I$3:$I$304,0)+COUNTIF($I$3:I3,I3)-1 -> 121 | K3: =RANK(B3,$B$3:$B$304,0)+COUNTIF($B$3:B3,B3)-1 -> 82 | L3: =RANK(C3,$C$3:$C$304,0)+COUNTIF($C$3:C3,C3)-1 -> 98 | M3: =RANK(D3,$D$3:$D$304,0)+COUNTIF($D$3:D3,D3)-1 -> 102 | N3: =RANK(E3,$E$3:$E$304,0)+COUNTIF($E$3:E3,E3)-1 -> 98 | O3: =RANK(F3,$F$3:$F$304,0)+COUNTIF($F$3:F3,F3)-1 -> 184 | P3: =RANK(G3,$G$3:$G$304,0)+COUNTIF($G$3:G3,G3)-1 -> 86 | Q3: =RANK(H3,$H$3:$H$304,0)+COUNTIF($H$3:H3,H3)-1 -> 87
A4: ACB (INDIA) | B4: =ROUND(SUMIFS(Monthly_Sold!$H$2:$H$7864,Monthly_Sold!$F$2:$F$7864,$A4,Monthly_Sold!$B$2:$B$7864,B$2),4) -> 316.17 | C4: =ROUND(SUMIFS(Monthly_Sold!$H$2:$H$7864,Monthly_Sold!$F$2:$F$7864,$A4,Monthly_Sold!$B$2:$B$7864,C$2),4) -> 413.39 | D4: =ROUND(SUMIFS(Monthly_Sold!$H$2:$H$7864,Monthly_Sold!$F$2:$F$7864,$A4,Monthly_Sold!$B$2:$B$7864,D$2),4) -> 751.69 | E4: =ROUND(SUMIFS(Monthly_Sold!$H$2:$H$7864,Monthly_Sold!$F$2:$F$7864,$A4,Monthly_Sold!$B$2:$B$7864,E$2),4) -> 496.83 | F4: =ROUND(SUMIFS(Monthly_Sold!$H$2:$H$7864,Monthly_Sold!$F$2:$F$7864,$A4,Monthly_Sold!$B$2:$B$7864,F$2),4) -> 550.96 | G4: =ROUND(SUMIFS(Monthly_Sold!$H$2:$H$7864,Monthly_Sold!$F$2:$F$7864,$A4,Monthly_Sold!$B$2:$B$7864,G$2),4) -> 315.97 | H4: =ROUND(SUMIFS(Monthly_Sold!$H$2:$H$7864,Monthly_Sold!$F$2:$F$7864,$A4,Monthly_Sold!$B$2:$B$7864,H$2),4) -> 99.01 | I4: =ROUND(SUM(B4:H4),4) -> 2944.02 | J4: =RANK(I4,$I$3:$I$304,0)+COUNTIF($I$3:I4,I4)-1 -> 31 | K4: =RANK(B4,$B$3:$B$304,0)+COUNTIF($B$3:B4,B4)-1 -> 45 | L4: =RANK(C4,$C$3:$C$304,0)+COUNTIF($C$3:C4,C4)-1 -> 33 | M4: =RANK(D4,$D$3:$D$304,0)+COUNTIF($D$3:D4,D4)-1 -> 22 | N4: =RANK(E4,$E$3:$E$304,0)+COUNTIF($E$3:E4,E4)-1 -> 32 | O4: =RANK(F4,$F$3:$F$304,0)+COUNTIF($F$3:F4,F4)-1 -> 29 | P4: =RANK(G4,$G$3:$G$304,0)+COUNTIF($G$3:G4,G4)-1 -> 48 | Q4: =RANK(H4,$H$3:$H$304,0)+COUNTIF($H$3:H4,H4)-1 -> 48
A5: ACME SURYODAYA PRIVATE LIMITED_BESS | B5: =ROUND(SUMIFS(Monthly_Sold!$H$2:$H$7864,Monthly_Sold!$F$2:$F$7864,$A5,Monthly_Sold!$B$2:$B$7864,B$2),4) -> 0 | C5: =ROUND(SUMIFS(Monthly_Sold!$H$2:$H$7864,Monthly_Sold!$F$2:$F$7864,$A5,Monthly_Sold!$B$2:$B$7864,C$2),4) -> 0 | D5: =ROUND(SUMIFS(Monthly_Sold!$H$2:$H$7864,Monthly_Sold!$F$2:$F$7864,$A5,Monthly_Sold!$B$2:$B$7864,D$2),4) -> 0 | E5: =ROUND(SUMIFS(Monthly_Sold!$H$2:$H$7864,Monthly_Sold!$F$2:$F$7864,$A5,Monthly_Sold!$B$2:$B$7864,E$2),4) -> 0 | F5: =ROUND(SUMIFS(Monthly_Sold!$H$2:$H$7864,Monthly_Sold!$F$2:$F$7864,$A5,Monthly_Sold!$B$2:$B$7864,F$2),4) -> 0 | G5: =ROUND(SUMIFS(Monthly_Sold!$H$2:$H$7864,Monthly_Sold!$F$2:$F$7864,$A5,Monthly_Sold!$B$2:$B$7864,G$2),4) -> 0 | H5: =ROUND(SUMIFS(Monthly_Sold!$H$2:$H$7864,Monthly_Sold!$F$2:$F$7864,$A5,Monthly_Sold!$B$2:$B$7864,H$2),4) -> 0.11 | I5: =ROUND(SUM(B5:H5),4) -> 0.11 | J5: =RANK(I5,$I$3:$I$304,0)+COUNTIF($I$3:I5,I5)-1 -> 286 | K5: =RANK(B5,$B$3:$B$304,0)+COUNTIF($B$3:B5,B5)-1 -> 83 | L5: =RANK(C5,$C$3:$C$304,0)+COUNTIF($C$3:C5,C5)-1 -> 99 | M5: =RANK(D5,$D$3:$D$304,0)+COUNTIF($D$3:D5,D5)-1 -> 103 | N5: =RANK(E5,$E$3:$E$304,0)+COUNTIF($E$3:E5,E5)-1 -> 99 | O5: =RANK(F5,$F$3:$F$304,0)+COUNTIF($F$3:F5,F5)-1 -> 185 | P5: =RANK(G5,$G$3:$G$304,0)+COUNTIF($G$3:G5,G5)-1 -> 180 | Q5: =RANK(H5,$H$3:$H$304,0)+COUNTIF($H$3:H5,H5)-1 -> 158
A6: AD HYDRO POWER | B6: =ROUND(SUMIFS(Monthly_Sold!$H$2:$H$7864,Monthly_Sold!$F$2:$F$7864,$A6,Monthly_Sold!$B$2:$B$7864,B$2),4) -> 462.43 | C6: =ROUND(SUMIFS(Monthly_Sold!$H$2:$H$7864,Monthly_Sold!$F$2:$F$7864,$A6,Monthly_Sold!$B$2:$B$7864,C$2),4) -> 315.93 | D6: =ROUND(SUMIFS(Monthly_Sold!$H$2:$H$7864,Monthly_Sold!$F$2:$F$7864,$A6,Monthly_Sold!$B$2:$B$7864,D$2),4) -> 213.26 | E6: =ROUND(SUMIFS(Monthly_Sold!$H$2:$H$7864,Monthly_Sold!$F$2:$F$7864,$A6,Monthly_Sold!$B$2:$B$7864,E$2),4) -> 261.13 | F6: =ROUND(SUMIFS(Monthly_Sold!$H$2:$H$7864,Monthly_Sold!$F$2:$F$7864,$A6,Monthly_Sold!$B$2:$B$7864,F$2),4) -> 510.49 | G6: =ROUND(SUMIFS(Monthly_Sold!$H$2:$H$7864,Monthly_Sold!$F$2:$F$7864,$A6,Monthly_Sold!$B$2:$B$7864,G$2),4) -> 527.17 | H6: =ROUND(SUMIFS(Monthly_Sold!$H$2:$H$7864,Monthly_Sold!$F$2:$F$7864,$A6,Monthly_Sold!$B$2:$B$7864,H$2),4) -> 39.82 | I6: =ROUND(SUM(B6:H6),4) -> 2330.23 | J6: =RANK(I6,$I$3:$I$304,0)+COUNTIF($I$3:I6,I6)-1 -> 36 | K6: =RANK(B6,$B$3:$B$304,0)+COUNTIF($B$3:B6,B6)-1 -> 29 | L6: =RANK(C6,$C$3:$C$304,0)+COUNTIF($C$3:C6,C6)-1 -> 39 | M6: =RANK(D6,$D$3:$D$304,0)+COUNTIF($D$3:D6,D6)-1 -> 39 | N6: =RANK(E6,$E$3:$E$304,0)+COUNTIF($E$3:E6,E6)-1 -> 38 | O6: =RANK(F6,$F$3:$F$304,0)+COUNTIF($F$3:F6,F6)-1 -> 31 | P6: =RANK(G6,$G$3:$G$304,0)+COUNTIF($G$3:G6,G6)-1 -> 34 | Q6: =RANK(H6,$H$3:$H$304,0)+COUNTIF($H$3:H6,H6)-1 -> 66
A7: ADANI GREEN | B7: =ROUND(SUMIFS(Monthly_Sold!$H$2:$H$7864,Monthly_Sold!$F$2:$F$7864,$A7,Monthly_Sold!$B$2:$B$7864,B$2),4) -> 28.52 | C7: =ROUND(SUMIFS(Monthly_Sold!$H$2:$H$7864,Monthly_Sold!$F$2:$F$7864,$A7,Monthly_Sold!$B$2:$B$7864,C$2),4) -> 2.82 | D7: =ROUND(SUMIFS(Monthly_Sold!$H$2:$H$7864,Monthly_Sold!$F$2:$F$7864,$A7,Monthly_Sold!$B$2:$B$7864,D$2),4) -> 23.11 | E7: =ROUND(SUMIFS(Monthly_Sold!$H$2:$H$7864,Monthly_Sold!$F$2:$F$7864,$A7,Monthly_Sold!$B$2:$B$7864,E$2),4) -> 0 | F7: =ROUND(SUMIFS(Monthly_Sold!$H$2:$H$7864,Monthly_Sold!$F$2:$F$7864,$A7,Monthly_Sold!$B$2:$B$7864,F$2),4) -> 0 | G7: =ROUND(SUMIFS(Monthly_Sold!$H$2:$H$7864,Monthly_Sold!$F$2:$F$7864,$A7,Monthly_Sold!$B$2:$B$7864,G$2),4) -> 0 | H7: =ROUND(SUMIFS(Monthly_Sold!$H$2:$H$7864,Monthly_Sold!$F$2:$F$7864,$A7,Monthly_Sold!$B$2:$B$7864,H$2),4) -> 0 | I7: =ROUND(SUM(B7:H7),4) -> 54.45 | J7: =RANK(I7,$I$3:$I$304,0)+COUNTIF($I$3:I7,I7)-1 -> 145 | K7: =RANK(B7,$B$3:$B$304,0)+COUNTIF($B$3:B7,B7)-1 -> 69 | L7: =RANK(C7,$C$3:$C$304,0)+COUNTIF($C$3:C7,C7)-1 -> 82 | M7: =RANK(D7,$D$3:$D$304,0)+COUNTIF($D$3:D7,D7)-1 -> 74 | N7: =RANK(E7,$E$3:$E$304,0)+COUNTIF($E$3:E7,E7)-1 -> 100 | O7: =RANK(F7,$F$3:$F$304,0)+COUNTIF($F$3:F7,F7)-1 -> 186 | P7: =RANK(G7,$G$3:$G$304,0)+COUNTIF($G$3:G7,G7)-1 -> 181 | Q7: =RANK(H7,$H$3:$H$304,0)+COUNTIF($H$3:H7,H7)-1 -> 164
A8: ADANI GREEN ENERGY TWENTY FIVE A LIMITED_INFIRM | B8: =ROUND(SUMIFS(Monthly_Sold!$H$2:$H$7864,Monthly_Sold!$F$2:$F$7864,$A8,Monthly_Sold!$B$2:$B$7864,B$2),4) -> 0 | C8: =ROUND(SUMIFS(Monthly_Sold!$H$2:$H$7864,Monthly_Sold!$F$2:$F$7864,$A8,Monthly_Sold!$B$2:$B$7864,C$2),4) -> 0 | D8: =ROUND(SUMIFS(Monthly_Sold!$H$2:$H$7864,Monthly_Sold!$F$2:$F$7864,$A8,Monthly_Sold!$B$2:$B$7864,D$2),4) -> 0 | E8: =ROUND(SUMIFS(Monthly_Sold!$H$2:$H$7864,Monthly_Sold!$F$2:$F$7864,$A8,Monthly_Sold!$B$2:$B$7864,E$2),4) -> 0 | F8: =ROUND(SUMIFS(Monthly_Sold!$H$2:$H$7864,Monthly_Sold!$F$2:$F$7864,$A8,Monthly_Sold!$B$2:$B$7864,F$2),4) -> 28.57 | G8: =ROUND(SUMIFS(Monthly_Sold!$H$2:$H$7864,Monthly_Sold!$F$2:$F$7864,$A8,Monthly_Sold!$B$2:$B$7864,G$2),4) -> 0 | H8: =ROUND(SUMIFS(Monthly_Sold!$H$2:$H$7864,Monthly_Sold!$F$2:$F$7864,$A8,Monthly_Sold!$B$2:$B$7864,H$2),4) -> 0 | I8: =ROUND(SUM(B8:H8),4) -> 28.57 | J8: =RANK(I8,$I$3:$I$304,0)+COUNTIF($I$3:I8,I8)-1 -> 172 | K8: =RANK(B8,$B$3:$B$304,0)+COUNTIF($B$3:B8,B8)-1 -> 84 | L8: =RANK(C8,$C$3:$C$304,0)+COUNTIF($C$3:C8,C8)-1 -> 100 | M8: =RANK(D8,$D$3:$D$304,0)+COUNTIF($D$3:D8,D8)-1 -> 104 | N8: =RANK(E8,$E$3:$E$304,0)+COUNTIF($E$3:E8,E8)-1 -> 101 | O8: =RANK(F8,$F$3:$F$304,0)+COUNTIF($F$3:F8,F8)-1 -> 102 | P8: =RANK(G8,$G$3:$G$304,0)+COUNTIF($G$3:G8,G8)-1 -> 182 | Q8: =RANK(H8,$H$3:$H$304,0)+COUNTIF($H$3:H8,H8)-1 -> 165
A9: ADANI GREEN ENERGY TWENTY FIVE A LIMITED_PSS-2 | B9: =ROUND(SUMIFS(Monthly_Sold!$H$2:$H$7864,Monthly_Sold!$F$2:$F$7864,$A9,Monthly_Sold!$B$2:$B$7864,B$2),4) -> 0 | C9: =ROUND(SUMIFS(Monthly_Sold!$H$2:$H$7864,Monthly_Sold!$F$2:$F$7864,$A9,Monthly_Sold!$B$2:$B$7864,C$2),4) -> 0 | D9: =ROUND(SUMIFS(Monthly_Sold!$H$2:$H$7864,Monthly_Sold!$F$2:$F$7864,$A9,Monthly_Sold!$B$2:$B$7864,D$2),4) -> 0 | E9: =ROUND(SUMIFS(Monthly_Sold!$H$2:$H$7864,Monthly_Sold!$F$2:$F$7864,$A9,Monthly_Sold!$B$2:$B$7864,E$2),4) -> 0 | F9: =ROUND(SUMIFS(Monthly_Sold!$H$2:$H$7864,Monthly_Sold!$F$2:$F$7864,$A9,Monthly_Sold!$B$2:$B$7864,F$2),4) -> 13.87 | G9: =ROUND(SUMIFS(Monthly_Sold!$H$2:$H$7864,Monthly_Sold!$F$2:$F$7864,$A9,Monthly_Sold!$B$2:$B$7864,G$2),4) -> 559.5 | H9: =ROUND(SUMIFS(Monthly_Sold!$H$2:$H$7864,Monthly_Sold!$F$2:$F$7864,$A9,Monthly_Sold!$B$2:$B$7864,H$2),4) -> 154.82 | I9: =ROUND(SUM(B9:H9),4) -> 728.19 | J9: =RANK(I9,$I$3:$I$304,0)+COUNTIF($I$3:I9,I9)-1 -> 63 | K9: =RANK(B9,$B$3:$B$304,0)+COUNTIF($B$3:B9,B9)-1 -> 85 | L9: =RANK(C9,$C$3:$C$304,0)+COUNTIF($C$3:C9,C9)-1 -> 101 | M9: =RANK(D9,$D$3:$D$304,0)+COUNTIF($D$3:D9,D9)-1 -> 105 | N9: =RANK(E9,$E$3:$E$304,0)+COUNTIF($E$3:E9,E9)-1 -> 102 | O9: =RANK(F9,$F$3:$F$304,0)+COUNTIF($F$3:F9,F9)-1 -> 123 | P9: =RANK(G9,$G$3:$G$304,0)+COUNTIF($G$3:G9,G9)-1 -> 32 | Q9: =RANK(H9,$H$3:$H$304,0)+COUNTIF($H$3:H9,H9)-1 -> 31
A10: ADANI GREEN ENERGY TWENTY FIVE B LIMITED(HYBRID SOLAR)_PSS9 | B10: =ROUND(SUMIFS(Monthly_Sold!$H$2:$H$7864,Monthly_Sold!$F$2:$F$7864,$A10,Monthly_Sold!$B$2:$B$7864,B$2),4) -> 0 | C10: =ROUND(SUMIFS(Monthly_Sold!$H$2:$H$7864,Monthly_Sold!$F$2:$F$7864,$A10,Monthly_Sold!$B$2:$B$7864,C$2),4) -> 0 | D10: =ROUND(SUMIFS(Monthly_Sold!$H$2:$H$7864,Monthly_Sold!$F$2:$F$7864,$A10,Monthly_Sold!$B$2:$B$7864,D$2),4) -> 0 | E10: =ROUND(SUMIFS(Monthly_Sold!$H$2:$H$7864,Monthly_Sold!$F$2:$F$7864,$A10,Monthly_Sold!$B$2:$B$7864,E$2),4) -> 0 | F10: =ROUND(SUMIFS(Monthly_Sold!$H$2:$H$7864,Monthly_Sold!$F$2:$F$7864,$A10,Monthly_Sold!$B$2:$B$7864,F$2),4) -> 0 | G10: =ROUND(SUMIFS(Monthly_Sold!$H$2:$H$7864,Monthly_Sold!$F$2:$F$7864,$A10,Monthly_Sold!$B$2:$B$7864,G$2),4) -> 29.17 | H10: =ROUND(SUMIFS(Monthly_Sold!$H$2:$H$7864,Monthly_Sold!$F$2:$F$7864,$A10,Monthly_Sold!$B$2:$B$7864,H$2),4) -> 28.76 | I10: =ROUND(SUM(B10:H10),4) -> 57.93 | J10: =RANK(I10,$I$3:$I$304,0)+COUNTIF($I$3:I10,I10)-1 -> 141 | K10: =RANK(B10,$B$3:$B$304,0)+COUNTIF($B$3:B10,B10)-1 -> 86 | L10: =RANK(C10,$C$3:$C$304,0)+COUNTIF($C$3:C10,C10)-1 -> 102 | M10: =RANK(D10,$D$3:$D$304,0)+COUNTIF($D$3:D10,D10)-1 -> 106 | N10: =RANK(E10,$E$3:$E$304,0)+COUNTIF($E$3:E10,E10)-1 -> 103 | O10: =RANK(F10,$F$3:$F$304,0)+COUNTIF($F$3:F10,F10)-1 -> 187 | P10: =RANK(G10,$G$3:$G$304,0)+COUNTIF($G$3:G10,G10)-1 -> 111 | Q10: =RANK(H10,$H$3:$H$304,0)+COUNTIF($H$3:H10,H10)-1 -> 84
A11: ADANI GREEN ENERGY TWENTY FIVE B LIMITED(WIND)_PSS9 | B11: =ROUND(SUMIFS(Monthly_Sold!$H$2:$H$7864,Monthly_Sold!$F$2:$F$7864,$A11,Monthly_Sold!$B$2:$B$7864,B$2),4) -> 0 | C11: =ROUND(SUMIFS(Monthly_Sold!$H$2:$H$7864,Monthly_Sold!$F$2:$F$7864,$A11,Monthly_Sold!$B$2:$B$7864,C$2),4) -> 0 | D11: =ROUND(SUMIFS(Monthly_Sold!$H$2:$H$7864,Monthly_Sold!$F$2:$F$7864,$A11,Monthly_Sold!$B$2:$B$7864,D$2),4) -> 0 | E11: =ROUND(SUMIFS(Monthly_Sold!$H$2:$H$7864,Monthly_Sold!$F$2:$F$7864,$A11,Monthly_Sold!$B$2:$B$7864,E$2),4) -> 0 | F11: =ROUND(SUMIFS(Monthly_Sold!$H$2:$H$7864,Monthly_Sold!$F$2:$F$7864,$A11,Monthly_Sold!$B$2:$B$7864,F$2),4) -> 0 | G11: =ROUND(SUMIFS(Monthly_Sold!$H$2:$H$7864,Monthly_Sold!$F$2:$F$7864,$A11,Monthly_Sold!$B$2:$B$7864,G$2),4) -> 35.61 | H11: =ROUND(SUMIFS(Monthly_Sold!$H$2:$H$7864,Monthly_Sold!$F$2:$F$7864,$A11,Monthly_Sold!$B$2:$B$7864,H$2),4) -> 18.57 | I11: =ROUND(SUM(B11:H11),4) -> 54.18 | J11: =RANK(I11,$I$3:$I$304,0)+COUNTIF($I$3:I11,I11)-1 -> 146 | K11: =RANK(B11,$B$3:$B$304,0)+COUNTIF($B$3:B11,B11)-1 -> 87 | L11: =RANK(C11,$C$3:$C$304,0)+COUNTIF($C$3:C11,C11)-1 -> 103 | M11: =RANK(D11,$D$3:$D$304,0)+COUNTIF($D$3:D11,D11)-1 -> 107 | N11: =RANK(E11,$E$3:$E$304,0)+COUNTIF($E$3:E11,E11)-1 -> 104 | O11: =RANK(F11,$F$3:$F$304,0)+COUNTIF($F$3:F11,F11)-1 -> 188 | P11: =RANK(G11,$G$3:$G$304,0)+COUNTIF($G$3:G11,G11)-1 -> 104 | Q11: =RANK(H11,$H$3:$H$304,0)+COUNTIF($H$3:H11,H11)-1 -> 94
A12: ADANI GREEN ENERGY TWENTY FIVE B LIMITED_INFIRM | B12: =ROUND(SUMIFS(Monthly_Sold!$H$2:$H$7864,Monthly_Sold!$F$2:$F$7864,$A12,Monthly_Sold!$B$2:$B$7864,B$2),4) -> 0 | C12: =ROUND(SUMIFS(Monthly_Sold!$H$2:$H$7864,Monthly_Sold!$F$2:$F$7864,$A12,Monthly_Sold!$B$2:$B$7864,C$2),4) -> 0 | D12: =ROUND(SUMIFS(Monthly_Sold!$H$2:$H$7864,Monthly_Sold!$F$2:$F$7864,$A12,Monthly_Sold!$B$2:$B$7864,D$2),4) -> 0 | E12: =ROUND(SUMIFS(Monthly_Sold!$H$2:$H$7864,Monthly_Sold!$F$2:$F$7864,$A12,Monthly_Sold!$B$2:$B$7864,E$2),4) -> 0 | F12: =ROUND(SUMIFS(Monthly_Sold!$H$2:$H$7864,Monthly_Sold!$F$2:$F$7864,$A12,Monthly_Sold!$B$2:$B$7864,F$2),4) -> 116.18 | G12: =ROUND(SUMIFS(Monthly_Sold!$H$2:$H$7864,Monthly_Sold!$F$2:$F$7864,$A12,Monthly_Sold!$B$2:$B$7864,G$2),4) -> 0 | H12: =ROUND(SUMIFS(Monthly_Sold!$H$2:$H$7864,Monthly_Sold!$F$2:$F$7864,$A12,Monthly_Sold!$B$2:$B$7864,H$2),4) -> 0 | I12: =ROUND(SUM(B12:H12),4) -> 116.18 | J12: =RANK(I12,$I$3:$I$304,0)+COUNTIF($I$3:I12,I12)-1 -> 114 | K12: =RANK(B12,$B$3:$B$304,0)+COUNTIF($B$3:B12,B12)-1 -> 88 | L12: =RANK(C12,$C$3:$C$304,0)+COUNTIF($C$3:C12,C12)-1 -> 104 | M12: =RANK(D12,$D$3:$D$304,0)+COUNTIF($D$3:D12,D12)-1 -> 108 | N12: =RANK(E12,$E$3:$E$304,0)+COUNTIF($E$3:E12,E12)-1 -> 105 | O12: =RANK(F12,$F$3:$F$304,0)+COUNTIF($F$3:F12,F12)-1 -> 61 | P12: =RANK(G12,$G$3:$G$304,0)+COUNTIF($G$3:G12,G12)-1 -> 183 | Q12: =RANK(H12,$H$3:$H$304,0)+COUNTIF($H$3:H12,H12)-1 -> 166
A13: ADANI GREEN ENERGY TWENTY FIVE B LIMITED_PSS-2 | B13: =ROUND(SUMIFS(Monthly_Sold!$H$2:$H$7864,Monthly_Sold!$F$2:$F$7864,$A13,Monthly_Sold!$B$2:$B$7864,B$2),4) -> 0 | C13: =ROUND(SUMIFS(Monthly_Sold!$H$2:$H$7864,Monthly_Sold!$F$2:$F$7864,$A13,Monthly_Sold!$B$2:$B$7864,C$2),4) -> 0 | D13: =ROUND(SUMIFS(Monthly_Sold!$H$2:$H$7864,Monthly_Sold!$F$2:$F$7864,$A13,Monthly_Sold!$B$2:$B$7864,D$2),4) -> 0 | E13: =ROUND(SUMIFS(Monthly_Sold!$H$2:$H$7864,Monthly_Sold!$F$2:$F$7864,$A13,Monthly_Sold!$B$2:$B$7864,E$2),4) -> 0 | F13: =ROUND(SUMIFS(Monthly_Sold!$H$2:$H$7864,Monthly_Sold!$F$2:$F$7864,$A13,Monthly_Sold!$B$2:$B$7864,F$2),4) -> 28.51 | G13: =ROUND(SUMIFS(Monthly_Sold!$H$2:$H$7864,Monthly_Sold!$F$2:$F$7864,$A13,Monthly_Sold!$B$2:$B$7864,G$2),4) -> 726.51 | H13: =ROUND(SUMIFS(Monthly_Sold!$H$2:$H$7864,Monthly_Sold!$F$2:$F$7864,$A13,Monthly_Sold!$B$2:$B$7864,H$2),4) -> 192.71 | I13: =ROUND(SUM(B13:H13),4) -> 947.73 | J13: =RANK(I13,$I$3:$I$304,0)+COUNTIF($I$3:I13,I13)-1 -> 55 | K13: =RANK(B13,$B$3:$B$304,0)+COUNTIF($B$3:B13,B13)-1 -> 89 | L13: =RANK(C13,$C$3:$C$304,0)+COUNTIF($C$3:C13,C13)-1 -> 105 | M13: =RANK(D13,$D$3:$D$304,0)+COUNTIF($D$3:D13,D13)-1 -> 109 | N13: =RANK(E13,$E$3:$E$304,0)+COUNTIF($E$3:E13,E13)-1 -> 106 | O13: =RANK(F13,$F$3:$F$304,0)+COUNTIF($F$3:F13,F13)-1 -> 103 | P13: =RANK(G13,$G$3:$G$304,0)+COUNTIF($G$3:G13,G13)-1 -> 24 | Q13: =RANK(H13,$H$3:$H$304,0)+COUNTIF($H$3:H13,H13)-1 -> 26
A14: ADANI GREEN ENERGY TWENTY FIVE C LIMITED_PSS11 | B14: =ROUND(SUMIFS(Monthly_Sold!$H$2:$H$7864,Monthly_Sold!$F$2:$F$7864,$A14,Monthly_Sold!$B$2:$B$7864,B$2),4) -> 0 | C14: =ROUND(SUMIFS(Monthly_Sold!$H$2:$H$7864,Monthly_Sold!$F$2:$F$7864,$A14,Monthly_Sold!$B$2:$B$7864,C$2),4) -> 0 | D14: =ROUND(SUMIFS(Monthly_Sold!$H$2:$H$7864,Monthly_Sold!$F$2:$F$7864,$A14,Monthly_Sold!$B$2:$B$7864,D$2),4) -> 0 | E14: =ROUND(SUMIFS(Monthly_Sold!$H$2:$H$7864,Monthly_Sold!$F$2:$F$7864,$A14,Monthly_Sold!$B$2:$B$7864,E$2),4) -> 0 | F14: =ROUND(SUMIFS(Monthly_Sold!$H$2:$H$7864,Monthly_Sold!$F$2:$F$7864,$A14,Monthly_Sold!$B$2:$B$7864,F$2),4) -> 0 | G14: =ROUND(SUMIFS(Monthly_Sold!$H$2:$H$7864,Monthly_Sold!$F$2:$F$7864,$A14,Monthly_Sold!$B$2:$B$7864,G$2),4) -> 0 | H14: =ROUND(SUMIFS(Monthly_Sold!$H$2:$H$7864,Monthly_Sold!$F$2:$F$7864,$A14,Monthly_Sold!$B$2:$B$7864,H$2),4) -> 11.48 | I14: =ROUND(SUM(B14:H14),4) -> 11.48 | J14: =RANK(I14,$I$3:$I$304,0)+COUNTIF($I$3:I14,I14)-1 -> 208 | K14: =RANK(B14,$B$3:$B$304,0)+COUNTIF($B$3:B14,B14)-1 -> 90 | L14: =RANK(C14,$C$3:$C$304,0)+COUNTIF($C$3:C14,C14)-1 -> 106 | M14: =RANK(D14,$D$3:$D$304,0)+COUNTIF($D$3:D14,D14)-1 -> 110 | N14: =RANK(E14,$E$3:$E$304,0)+COUNTIF($E$3:E14,E14)-1 -> 107 | O14: =RANK(F14,$F$3:$F$304,0)+COUNTIF($F$3:F14,F14)-1 -> 189 | P14: =RANK(G14,$G$3:$G$304,0)+COUNTIF($G$3:G14,G14)-1 -> 184 | Q14: =RANK(H14,$H$3:$H$304,0)+COUNTIF($H$3:H14,H14)-1 -> 103
... A304: ZENATARIS RENEWABLE ENERGY PRIVATE LIMITED | B304: =ROUND(SUMIFS(Monthly_Sold!$H$2:$H$7864,Monthly_Sold!$F$2:$F$7864,$A304,Monthly_Sold!$B$2:$B$7864,B$2),4) -> 0 | C304: =ROUND(SUMIFS(Monthly_Sold!$H$2:$H$7864,Monthly_Sold!$F$2:$F$7864,$A304,Monthly_Sold!$B$2:$B$7864,C$2),4) -> 0 | D304: =ROUND(SUMIFS(Monthly_Sold!$H$2:$H$7864,Monthly_Sold!$F$2:$F$7864,$A304,Monthly_Sold!$B$2:$B$7864,D$2),4) -> 0 | E304: =ROUND(SUMIFS(Monthly_Sold!$H$2:$H$7864,Monthly_Sold!$F$2:$F$7864,$A304,Monthly_Sold!$B$2:$B$7864,E$2),4) -> 0 | F304: =ROUND(SUMIFS(Monthly_Sold!$H$2:$H$7864,Monthly_Sold!$F$2:$F$7864,$A304,Monthly_Sold!$B$2:$B$7864,F$2),4) -> 0 | G304: =ROUND(SUMIFS(Monthly_Sold!$H$2:$H$7864,Monthly_Sold!$F$2:$F$7864,$A304,Monthly_Sold!$B$2:$B$7864,G$2),4) -> 0.02 | H304: =ROUND(SUMIFS(Monthly_Sold!$H$2:$H$7864,Monthly_Sold!$F$2:$F$7864,$A304,Monthly_Sold!$B$2:$B$7864,H$2),4) -> 0 | I304: =ROUND(SUM(B304:H304),4) -> 0.02 | J304: =RANK(I304,$I$3:$I$304,0)+COUNTIF($I$3:I304,I304)-1 -> 300 | K304: =RANK(B304,$B$3:$B$304,0)+COUNTIF($B$3:B304,B304)-1 -> 302 | L304: =RANK(C304,$C$3:$C$304,0)+COUNTIF($C$3:C304,C304)-1 -> 302 | M304: =RANK(D304,$D$3:$D$304,0)+COUNTIF($D$3:D304,D304)-1 -> 302 | N304: =RANK(E304,$E$3:$E$304,0)+COUNTIF($E$3:E304,E304)-1 -> 302 | O304: =RANK(F304,$F$3:$F$304,0)+COUNTIF($F$3:F304,F304)-1 -> 302 | P304: =RANK(G304,$G$3:$G$304,0)+COUNTIF($G$3:G304,G304)-1 -> 177 | Q304: =RANK(H304,$H$3:$H$304,0)+COUNTIF($H$3:H304,H304)-1 -> 302
A305: TOTAL | B305: =SUM(B3:B304) -> 56426.36 | C305: =SUM(C3:C304) -> 65677.324 | D305: =SUM(D3:D304) -> 53792.735 | E305: =SUM(E3:E304) -> 52878.601 | F305: =SUM(F3:F304) -> 59306.487 | G305: =SUM(G3:G304) -> 60454.5 | H305: =SUM(H3:H304) -> 19585.018 | I305: =SUM(I3:I304) -> 368121.03
A306: Check vs Monthly (should be OK) | B306: =IF(ABS(B305-SUMIFS(Monthly_Sold!$H$2:$H$7864,Monthly_Sold!$B$2:$B$7864,B$2))<0.01,"OK","MISMATCH") -> OK | C306: =IF(ABS(C305-SUMIFS(Monthly_Sold!$H$2:$H$7864,Monthly_Sold!$B$2:$B$7864,C$2))<0.01,"OK","MISMATCH") -> OK | D306: =IF(ABS(D305-SUMIFS(Monthly_Sold!$H$2:$H$7864,Monthly_Sold!$B$2:$B$7864,D$2))<0.01,"OK","MISMATCH") -> OK | E306: =IF(ABS(E305-SUMIFS(Monthly_Sold!$H$2:$H$7864,Monthly_Sold!$B$2:$B$7864,E$2))<0.01,"OK","MISMATCH") -> OK | F306: =IF(ABS(F305-SUMIFS(Monthly_Sold!$H$2:$H$7864,Monthly_Sold!$B$2:$B$7864,F$2))<0.01,"OK","MISMATCH") -> OK | G306: =IF(ABS(G305-SUMIFS(Monthly_Sold!$H$2:$H$7864,Monthly_Sold!$B$2:$B$7864,G$2))<0.01,"OK","MISMATCH") -> OK | H306: =IF(ABS(H305-SUMIFS(Monthly_Sold!$H$2:$H$7864,Monthly_Sold!$B$2:$B$7864,H$2))<0.01,"OK","MISMATCH") -> OK | I306: =IF(ABS(I305-SUM(Monthly_Sold!$H$2:$H$7864))<0.01,"OK","MISMATCH") -> OK

Sheet Top15_Sold_CY
A1: SOLD in DAM - top 15 players by TOTAL volume over the whole period (MU), from Annual_Sold_CY | I1: 2026-01 to 2026-03 only
A2: Rank | B2: Player | C2: 2020 | D2: 2021 | E2: 2022 | F2: 2023 | G2: 2024 | H2: 2025 | I2: 2026 | J2: TOTAL
A3: 1 | B3: =INDEX(Annual_Sold_CY!$A$3:$A$304,MATCH(A3,Annual_Sold_CY!$J$3:$J$304,0)) -> UTTAR PRADESH | C3: =INDEX(Annual_Sold_CY!$B$3:$B$304,MATCH($B3,Annual_Sold_CY!$A$3:$A$304,0)) -> 2809.73 | D3: =INDEX(Annual_Sold_CY!$C$3:$C$304,MATCH($B3,Annual_Sold_CY!$A$3:$A$304,0)) -> 6692.48 | E3: =INDEX(Annual_Sold_CY!$D$3:$D$304,MATCH($B3,Annual_Sold_CY!$A$3:$A$304,0)) -> 6753.72 | F3: =INDEX(Annual_Sold_CY!$E$3:$E$304,MATCH($B3,Annual_Sold_CY!$A$3:$A$304,0)) -> 7651.46 | G3: =INDEX(Annual_Sold_CY!$F$3:$F$304,MATCH($B3,Annual_Sold_CY!$A$3:$A$304,0)) -> 4638.41 | H3: =INDEX(Annual_Sold_CY!$G$3:$G$304,MATCH($B3,Annual_Sold_CY!$A$3:$A$304,0)) -> 4047.69 | I3: =INDEX(Annual_Sold_CY!$H$3:$H$304,MATCH($B3,Annual_Sold_CY!$A$3:$A$304,0)) -> 1436.57 | J3: =INDEX(Annual_Sold_CY!$I$3:$I$304,MATCH($B3,Annual_Sold_CY!$A$3:$A$304,0)) -> 34030.06
A4: 2 | B4: =INDEX(Annual_Sold_CY!$A$3:$A$304,MATCH(A4,Annual_Sold_CY!$J$3:$J$304,0)) -> ODISHA | C4: =INDEX(Annual_Sold_CY!$B$3:$B$304,MATCH($B4,Annual_Sold_CY!$A$3:$A$304,0)) -> 4477.1 | D4: =INDEX(Annual_Sold_CY!$C$3:$C$304,MATCH($B4,Annual_Sold_CY!$A$3:$A$304,0)) -> 3501.12 | E4: =INDEX(Annual_Sold_CY!$D$3:$D$304,MATCH($B4,Annual_Sold_CY!$A$3:$A$304,0)) -> 1131.36 | F4: =INDEX(Annual_Sold_CY!$E$3:$E$304,MATCH($B4,Annual_Sold_CY!$A$3:$A$304,0)) -> 1325.74 | G4: =INDEX(Annual_Sold_CY!$F$3:$F$304,MATCH($B4,Annual_Sold_CY!$A$3:$A$304,0)) -> 2647.4 | H4: =INDEX(Annual_Sold_CY!$G$3:$G$304,MATCH($B4,Annual_Sold_CY!$A$3:$A$304,0)) -> 2707.16 | I4: =INDEX(Annual_Sold_CY!$H$3:$H$304,MATCH($B4,Annual_Sold_CY!$A$3:$A$304,0)) -> 1139.12 | J4: =INDEX(Annual_Sold_CY!$I$3:$I$304,MATCH($B4,Annual_Sold_CY!$A$3:$A$304,0)) -> 16929
A5: 3 | B5: =INDEX(Annual_Sold_CY!$A$3:$A$304,MATCH(A5,Annual_Sold_CY!$J$3:$J$304,0)) -> CHHATTISGARH | C5: =INDEX(Annual_Sold_CY!$B$3:$B$304,MATCH($B5,Annual_Sold_CY!$A$3:$A$304,0)) -> 1629.91 | D5: =INDEX(Annual_Sold_CY!$C$3:$C$304,MATCH($B5,Annual_Sold_CY!$A$3:$A$304,0)) -> 1848.17 | E5: =INDEX(Annual_Sold_CY!$D$3:$D$304,MATCH($B5,Annual_Sold_CY!$A$3:$A$304,0)) -> 2432.45 | F5: =INDEX(Annual_Sold_CY!$E$3:$E$304,MATCH($B5,Annual_Sold_CY!$A$3:$A$304,0)) -> 3755.79 | G5: =INDEX(Annual_Sold_CY!$F$3:$F$304,MATCH($B5,Annual_Sold_CY!$A$3:$A$304,0)) -> 3387.22 | H5: =INDEX(Annual_Sold_CY!$G$3:$G$304,MATCH($B5,Annual_Sold_CY!$A$3:$A$304,0)) -> 1849.29 | I5: =INDEX(Annual_Sold_CY!$H$3:$H$304,MATCH($B5,Annual_Sold_CY!$A$3:$A$304,0)) -> 840.69 | J5: =INDEX(Annual_Sold_CY!$I$3:$I$304,MATCH($B5,Annual_Sold_CY!$A$3:$A$304,0)) -> 15743.52
A6: 4 | B6: =INDEX(Annual_Sold_CY!$A$3:$A$304,MATCH(A6,Annual_Sold_CY!$J$3:$J$304,0)) -> WEST BENGAL | C6: =INDEX(Annual_Sold_CY!$B$3:$B$304,MATCH($B6,Annual_Sold_CY!$A$3:$A$304,0)) -> 1081.86 | D6: =INDEX(Annual_Sold_CY!$C$3:$C$304,MATCH($B6,Annual_Sold_CY!$A$3:$A$304,0)) -> 5224.76 | E6: =INDEX(Annual_Sold_CY!$D$3:$D$304,MATCH($B6,Annual_Sold_CY!$A$3:$A$304,0)) -> 4569.6 | F6: =INDEX(Annual_Sold_CY!$E$3:$E$304,MATCH($B6,Annual_Sold_CY!$A$3:$A$304,0)) -> 1327 | G6: =INDEX(Annual_Sold_CY!$F$3:$F$304,MATCH($B6,Annual_Sold_CY!$A$3:$A$304,0)) -> 1174.53 | H6: =INDEX(Annual_Sold_CY!$G$3:$G$304,MATCH($B6,Annual_Sold_CY!$A$3:$A$304,0)) -> 785.04 | I6: =INDEX(Annual_Sold_CY!$H$3:$H$304,MATCH($B6,Annual_Sold_CY!$A$3:$A$304,0)) -> 348.43 | J6: =INDEX(Annual_Sold_CY!$I$3:$I$304,MATCH($B6,Annual_Sold_CY!$A$3:$A$304,0)) -> 14511.22
A7: 5 | B7: =INDEX(Annual_Sold_CY!$A$3:$A$304,MATCH(A7,Annual_Sold_CY!$J$3:$J$304,0)) -> BIHAR | C7: =INDEX(Annual_Sold_CY!$B$3:$B$304,MATCH($B7,Annual_Sold_CY!$A$3:$A$304,0)) -> 824.79 | D7: =INDEX(Annual_Sold_CY!$C$3:$C$304,MATCH($B7,Annual_Sold_CY!$A$3:$A$304,0)) -> 2442.46 | E7: =INDEX(Annual_Sold_CY!$D$3:$D$304,MATCH($B7,Annual_Sold_CY!$A$3:$A$304,0)) -> 3593.27 | F7: =INDEX(Annual_Sold_CY!$E$3:$E$304,MATCH($B7,Annual_Sold_CY!$A$3:$A$304,0)) -> 3871.34 | G7: =INDEX(Annual_Sold_CY!$F$3:$F$304,MATCH($B7,Annual_Sold_CY!$A$3:$A$304,0)) -> 1363.74 | H7: =INDEX(Annual_Sold_CY!$G$3:$G$304,MATCH($B7,Annual_Sold_CY!$A$3:$A$304,0)) -> 1349.22 | I7: =INDEX(Annual_Sold_CY!$H$3:$H$304,MATCH($B7,Annual_Sold_CY!$A$3:$A$304,0)) -> 883.76 | J7: =INDEX(Annual_Sold_CY!$I$3:$I$304,MATCH($B7,Annual_Sold_CY!$A$3:$A$304,0)) -> 14328.58
A8: 6 | B8: =INDEX(Annual_Sold_CY!$A$3:$A$304,MATCH(A8,Annual_Sold_CY!$J$3:$J$304,0)) -> JINDAL POWER LTD - STAGE 2 | C8: =INDEX(Annual_Sold_CY!$B$3:$B$304,MATCH($B8,Annual_Sold_CY!$A$3:$A$304,0)) -> 1232.5 | D8: =INDEX(Annual_Sold_CY!$C$3:$C$304,MATCH($B8,Annual_Sold_CY!$A$3:$A$304,0)) -> 987.39 | E8: =INDEX(Annual_Sold_CY!$D$3:$D$304,MATCH($B8,Annual_Sold_CY!$A$3:$A$304,0)) -> 1850.72 | F8: =INDEX(Annual_Sold_CY!$E$3:$E$304,MATCH($B8,Annual_Sold_CY!$A$3:$A$304,0)) -> 1310.49 | G8: =INDEX(Annual_Sold_CY!$F$3:$F$304,MATCH($B8,Annual_Sold_CY!$A$3:$A$304,0)) -> 3421.38 | H8: =INDEX(Annual_Sold_CY!$G$3:$G$304,MATCH($B8,Annual_Sold_CY!$A$3:$A$304,0)) -> 3431.77 | I8: =INDEX(Annual_Sold_CY!$H$3:$H$304,MATCH($B8,Annual_Sold_CY!$A$3:$A$304,0)) -> 1093.08 | J8: =INDEX(Annual_Sold_CY!$I$3:$I$304,MATCH($B8,Annual_Sold_CY!$A$3:$A$304,0)) -> 13327.33
A9: 7 | B9: =INDEX(Annual_Sold_CY!$A$3:$A$304,MATCH(A9,Annual_Sold_CY!$J$3:$J$304,0)) -> MADHYA PRADESH | C9: =INDEX(Annual_Sold_CY!$B$3:$B$304,MATCH($B9,Annual_Sold_CY!$A$3:$A$304,0)) -> 1791.95 | D9: =INDEX(Annual_Sold_CY!$C$3:$C$304,MATCH($B9,Annual_Sold_CY!$A$3:$A$304,0)) -> 2556.96 | E9: =INDEX(Annual_Sold_CY!$D$3:$D$304,MATCH($B9,Annual_Sold_CY!$A$3:$A$304,0)) -> 2528.98 | F9: =INDEX(Annual_Sold_CY!$E$3:$E$304,MATCH($B9,Annual_Sold_CY!$A$3:$A$304,0)) -> 1539.32 | G9: =INDEX(Annual_Sold_CY!$F$3:$F$304,MATCH($B9,Annual_Sold_CY!$A$3:$A$304,0)) -> 1528.65 | H9: =INDEX(Annual_Sold_CY!$G$3:$G$304,MATCH($B9,Annual_Sold_CY!$A$3:$A$304,0)) -> 1762.13 | I9: =INDEX(Annual_Sold_CY!$H$3:$H$304,MATCH($B9,Annual_Sold_CY!$A$3:$A$304,0)) -> 383.95 | J9: =INDEX(Annual_Sold_CY!$I$3:$I$304,MATCH($B9,Annual_Sold_CY!$A$3:$A$304,0)) -> 12091.94
A10: 8 | B10: =INDEX(Annual_Sold_CY!$A$3:$A$304,MATCH(A10,Annual_Sold_CY!$J$3:$J$304,0)) -> HIMACHAL PRADESH | C10: =INDEX(Annual_Sold_CY!$B$3:$B$304,MATCH($B10,Annual_Sold_CY!$A$3:$A$304,0)) -> 3088.63 | D10: =INDEX(Annual_Sold_CY!$C$3:$C$304,MATCH($B10,Annual_Sold_CY!$A$3:$A$304,0)) -> 2502.79 | E10: =INDEX(Annual_Sold_CY!$D$3:$D$304,MATCH($B10,Annual_Sold_CY!$A$3:$A$304,0)) -> 1319.6 | F10: =INDEX(Annual_Sold_CY!$E$3:$E$304,MATCH($B10,Annual_Sold_CY!$A$3:$A$304,0)) -> 1162.91 | G10: =INDEX(Annual_Sold_CY!$F$3:$F$304,MATCH($B10,Annual_Sold_CY!$A$3:$A$304,0)) -> 1674.63 | H10: =INDEX(Annual_Sold_CY!$G$3:$G$304,MATCH($B10,Annual_Sold_CY!$A$3:$A$304,0)) -> 1324.05 | I10: =INDEX(Annual_Sold_CY!$H$3:$H$304,MATCH($B10,Annual_Sold_CY!$A$3:$A$304,0)) -> 187.72 | J10: =INDEX(Annual_Sold_CY!$I$3:$I$304,MATCH($B10,Annual_Sold_CY!$A$3:$A$304,0)) -> 11260.33
A11: 9 | B11: =INDEX(Annual_Sold_CY!$A$3:$A$304,MATCH(A11,Annual_Sold_CY!$J$3:$J$304,0)) -> SEIL ENERGY INDIA (EX-SEMBCORP) | C11: =INDEX(Annual_Sold_CY!$B$3:$B$304,MATCH($B11,Annual_Sold_CY!$A$3:$A$304,0)) -> 3288.17 | D11: =INDEX(Annual_Sold_CY!$C$3:$C$304,MATCH($B11,Annual_Sold_CY!$A$3:$A$304,0)) -> 3408.24 | E11: =INDEX(Annual_Sold_CY!$D$3:$D$304,MATCH($B11,Annual_Sold_CY!$A$3:$A$304,0)) -> 1887.2 | F11: =INDEX(Annual_Sold_CY!$E$3:$E$304,MATCH($B11,Annual_Sold_CY!$A$3:$A$304,0)) -> 855.97 | G11: =INDEX(Annual_Sold_CY!$F$3:$F$304,MATCH($B11,Annual_Sold_CY!$A$3:$A$304,0)) -> 809.86 | H11: =INDEX(Annual_Sold_CY!$G$3:$G$304,MATCH($B11,Annual_Sold_CY!$A$3:$A$304,0)) -> 713.2 | I11: =INDEX(Annual_Sold_CY!$H$3:$H$304,MATCH($B11,Annual_Sold_CY!$A$3:$A$304,0)) -> 74.22 | J11: =INDEX(Annual_Sold_CY!$I$3:$I$304,MATCH($B11,Annual_Sold_CY!$A$3:$A$304,0)) -> 11036.86
A12: 10 | B12: =INDEX(Annual_Sold_CY!$A$3:$A$304,MATCH(A12,Annual_Sold_CY!$J$3:$J$304,0)) -> ADANI POWER - RAIPUR TPP (EX-GMR CHHATTISGARH) | C12: =INDEX(Annual_Sold_CY!$B$3:$B$304,MATCH($B12,Annual_Sold_CY!$A$3:$A$304,0)) -> 2188.37 | D12: =INDEX(Annual_Sold_CY!$C$3:$C$304,MATCH($B12,Annual_Sold_CY!$A$3:$A$304,0)) -> 722 | E12: =INDEX(Annual_Sold_CY!$D$3:$D$304,MATCH($B12,Annual_Sold_CY!$A$3:$A$304,0)) -> 1106.89 | F12: =INDEX(Annual_Sold_CY!$E$3:$E$304,MATCH($B12,Annual_Sold_CY!$A$3:$A$304,0)) -> 1647.87 | G12: =INDEX(Annual_Sold_CY!$F$3:$F$304,MATCH($B12,Annual_Sold_CY!$A$3:$A$304,0)) -> 2839.61 | H12: =INDEX(Annual_Sold_CY!$G$3:$G$304,MATCH($B12,Annual_Sold_CY!$A$3:$A$304,0)) -> 1708.05 | I12: =INDEX(Annual_Sold_CY!$H$3:$H$304,MATCH($B12,Annual_Sold_CY!$A$3:$A$304,0)) -> 629.63 | J12: =INDEX(Annual_Sold_CY!$I$3:$I$304,MATCH($B12,Annual_Sold_CY!$A$3:$A$304,0)) -> 10842.42
A13: 11 | B13: =INDEX(Annual_Sold_CY!$A$3:$A$304,MATCH(A13,Annual_Sold_CY!$J$3:$J$304,0)) -> KARNATAKA | C13: =INDEX(Annual_Sold_CY!$B$3:$B$304,MATCH($B13,Annual_Sold_CY!$A$3:$A$304,0)) -> 725.93 | D13: =INDEX(Annual_Sold_CY!$C$3:$C$304,MATCH($B13,Annual_Sold_CY!$A$3:$A$304,0)) -> 3006.33 | E13: =INDEX(Annual_Sold_CY!$D$3:$D$304,MATCH($B13,Annual_Sold_CY!$A$3:$A$304,0)) -> 2221.31 | F13: =INDEX(Annual_Sold_CY!$E$3:$E$304,MATCH($B13,Annual_Sold_CY!$A$3:$A$304,0)) -> 728.16 | G13: =INDEX(Annual_Sold_CY!$F$3:$F$304,MATCH($B13,Annual_Sold_CY!$A$3:$A$304,0)) -> 2036.65 | H13: =INDEX(Annual_Sold_CY!$G$3:$G$304,MATCH($B13,Annual_Sold_CY!$A$3:$A$304,0)) -> 1040.05 | I13: =INDEX(Annual_Sold_CY!$H$3:$H$304,MATCH($B13,Annual_Sold_CY!$A$3:$A$304,0)) -> 150.03 | J13: =INDEX(Annual_Sold_CY!$I$3:$I$304,MATCH($B13,Annual_Sold_CY!$A$3:$A$304,0)) -> 9908.46
A14: 12 | B14: =INDEX(Annual_Sold_CY!$A$3:$A$304,MATCH(A14,Annual_Sold_CY!$J$3:$J$304,0)) -> MAHAN ENERGEN (EX-ESSAR POWER MP) | C14: =INDEX(Annual_Sold_CY!$B$3:$B$304,MATCH($B14,Annual_Sold_CY!$A$3:$A$304,0)) -> 871 | D14: =INDEX(Annual_Sold_CY!$C$3:$C$304,MATCH($B14,Annual_Sold_CY!$A$3:$A$304,0)) -> 1161.64 | E14: =INDEX(Annual_Sold_CY!$D$3:$D$304,MATCH($B14,Annual_Sold_CY!$A$3:$A$304,0)) -> 865.37 | F14: =INDEX(Annual_Sold_CY!$E$3:$E$304,MATCH($B14,Annual_Sold_CY!$A$3:$A$304,0)) -> 1492.1 | G14: =INDEX(Annual_Sold_CY!$F$3:$F$304,MATCH($B14,Annual_Sold_CY!$A$3:$A$304,0)) -> 2832 | H14: =INDEX(Annual_Sold_CY!$G$3:$G$304,MATCH($B14,Annual_Sold_CY!$A$3:$A$304,0)) -> 1982.22 | I14: =INDEX(Annual_Sold_CY!$H$3:$H$304,MATCH($B14,Annual_Sold_CY!$A$3:$A$304,0)) -> 420.03 | J14: =INDEX(Annual_Sold_CY!$I$3:$I$304,MATCH($B14,Annual_Sold_CY!$A$3:$A$304,0)) -> 9624.36
... A17: 15 | B17: =INDEX(Annual_Sold_CY!$A$3:$A$304,MATCH(A17,Annual_Sold_CY!$J$3:$J$304,0)) -> JINDAL POWER LTD - STAGE 1 | C17: =INDEX(Annual_Sold_CY!$B$3:$B$304,MATCH($B17,Annual_Sold_CY!$A$3:$A$304,0)) -> 1749.25 | D17: =INDEX(Annual_Sold_CY!$C$3:$C$304,MATCH($B17,Annual_Sold_CY!$A$3:$A$304,0)) -> 2137.03 | E17: =INDEX(Annual_Sold_CY!$D$3:$D$304,MATCH($B17,Annual_Sold_CY!$A$3:$A$304,0)) -> 949.23 | F17: =INDEX(Annual_Sold_CY!$E$3:$E$304,MATCH($B17,Annual_Sold_CY!$A$3:$A$304,0)) -> 1020.54 | G17: =INDEX(Annual_Sold_CY!$F$3:$F$304,MATCH($B17,Annual_Sold_CY!$A$3:$A$304,0)) -> 1473.66 | H17: =INDEX(Annual_Sold_CY!$G$3:$G$304,MATCH($B17,Annual_Sold_CY!$A$3:$A$304,0)) -> 1513.84 | I17: =INDEX(Annual_Sold_CY!$H$3:$H$304,MATCH($B17,Annual_Sold_CY!$A$3:$A$304,0)) -> 444.69 | J17: =INDEX(Annual_Sold_CY!$I$3:$I$304,MATCH($B17,Annual_Sold_CY!$A$3:$A$304,0)) -> 9288.24
A18: =COUNTIF(Annual_Sold_CY!$I$3:$I$304,">0")-15 -> 287 | B18: ="OTHERS ("&A18&" players)" -> OTHERS (287 players) | C18: =C19-SUM(C3:C17) -> 23617.18 | D18: =D19-SUM(D3:D17) -> 25141.544 | E18: =E19-SUM(E3:E17) -> 20195.845 | F18: =F19-SUM(F3:F17) -> 23072.071 | G18: =G19-SUM(G3:G17) -> 28062.497 | H18: =H19-SUM(H3:H17) -> 34902.1 | I18: =I19-SUM(I3:I17) -> 11339.408 | J18: =J19-SUM(J3:J17) -> 166330.65
B19: TOTAL | C19: =Annual_Sold_CY!B305 -> 56426.36 | D19: =Annual_Sold_CY!C305 -> 65677.324 | E19: =Annual_Sold_CY!D305 -> 53792.735 | F19: =Annual_Sold_CY!E305 -> 52878.601 | G19: =Annual_Sold_CY!F305 -> 59306.487 | H19: =Annual_Sold_CY!G305 -> 60454.5 | I19: =Annual_Sold_CY!H305 -> 19585.018 | J19: =Annual_Sold_CY!I305 -> 368121.03
B20: Check: top15 + Others = Annual total | C20: =IF(ABS(SUM(C3:C18)-C19)<0.01,"OK","MISMATCH") -> OK | D20: =IF(ABS(SUM(D3:D18)-D19)<0.01,"OK","MISMATCH") -> OK | E20: =IF(ABS(SUM(E3:E18)-E19)<0.01,"OK","MISMATCH") -> OK | F20: =IF(ABS(SUM(F3:F18)-F19)<0.01,"OK","MISMATCH") -> OK | G20: =IF(ABS(SUM(G3:G18)-G19)<0.01,"OK","MISMATCH") -> OK | H20: =IF(ABS(SUM(H3:H18)-H19)<0.01,"OK","MISMATCH") -> OK | I20: =IF(ABS(SUM(I3:I18)-I19)<0.01,"OK","MISMATCH") -> OK | J20: =IF(ABS(SUM(J3:J18)-J19)<0.01,"OK","MISMATCH") -> OK
A22: Share of period total (%)
A23: Rank | B23: Player | C23: 2020 | D23: 2021 | E23: 2022 | F23: 2023 | G23: 2024 | H23: 2025 | I23: 2026 | J23: TOTAL
A24: =A3 -> 1 | B24: =B3 -> UTTAR PRADESH | C24: =IF(C$19=0,0,C3/C$19*100) -> 4.9794635 | D24: =IF(D$19=0,0,D3/D$19*100) -> 10.18994 | E24: =IF(E$19=0,0,E3/E$19*100) -> 12.555078 | F24: =IF(F$19=0,0,F3/F$19*100) -> 14.469861 | G24: =IF(G$19=0,0,G3/G$19*100) -> 7.8210837 | H24: =IF(H$19=0,0,H3/H$19*100) -> 6.6954321 | I24: =IF(I$19=0,0,I3/I$19*100) -> 7.3350456 | J24: =IF(J$19=0,0,J3/J$19*100) -> 9.2442587
A25: =A4 -> 2 | B25: =B4 -> ODISHA | C25: =IF(C$19=0,0,C4/C$19*100) -> 7.9344122 | D25: =IF(D$19=0,0,D4/D$19*100) -> 5.3307897 | E25: =IF(E$19=0,0,E4/E$19*100) -> 2.1031836 | F25: =IF(F$19=0,0,F4/F$19*100) -> 2.5071389 | G25: =IF(G$19=0,0,G4/G$19*100) -> 4.4639299 | H25: =IF(H$19=0,0,H4/H$19*100) -> 4.4780124 | I25: =IF(I$19=0,0,I4/I$19*100) -> 5.8162826 | J25: =IF(J$19=0,0,J4/J$19*100) -> 4.5987593
A26: =A5 -> 3 | B26: =B5 -> CHHATTISGARH | C26: =IF(C$19=0,0,C5/C$19*100) -> 2.8885613 | D26: =IF(D$19=0,0,D5/D$19*100) -> 2.8140154 | E26: =IF(E$19=0,0,E5/E$19*100) -> 4.5218932 | F26: =IF(F$19=0,0,F5/F$19*100) -> 7.1026652 | G26: =IF(G$19=0,0,G5/G$19*100) -> 5.711382 | H26: =IF(H$19=0,0,H5/H$19*100) -> 3.0589782 | I26: =IF(I$19=0,0,I5/I$19*100) -> 4.2925158 | J26: =IF(J$19=0,0,J5/J$19*100) -> 4.2767239
A27: =A6 -> 4 | B27: =B6 -> WEST BENGAL | C27: =IF(C$19=0,0,C6/C$19*100) -> 1.9172954 | D27: =IF(D$19=0,0,D6/D$19*100) -> 7.9551962 | E27: =IF(E$19=0,0,E6/E$19*100) -> 8.4948274 | F27: =IF(F$19=0,0,F6/F$19*100) -> 2.5095218 | G27: =IF(G$19=0,0,G6/G$19*100) -> 1.980441 | H27: =IF(H$19=0,0,H6/H$19*100) -> 1.2985634 | I27: =IF(I$19=0,0,I6/I$19*100) -> 1.779064 | J27: =IF(J$19=0,0,J6/J$19*100) -> 3.9419699
A28: =A7 -> 5 | B28: =B7 -> BIHAR | C28: =IF(C$19=0,0,C7/C$19*100) -> 1.4617104 | D28: =IF(D$19=0,0,D7/D$19*100) -> 3.7188787 | E28: =IF(E$19=0,0,E7/E$19*100) -> 6.6798425 | F28: =IF(F$19=0,0,F7/F$19*100) -> 7.3211846 | G28: =IF(G$19=0,0,G7/G$19*100) -> 2.2994786 | H28: =IF(H$19=0,0,H7/H$19*100) -> 2.2317941 | I28: =IF(I$19=0,0,I7/I$19*100) -> 4.5124288 | J28: =IF(J$19=0,0,J7/J$19*100) -> 3.8923558
A29: =A8 -> 6 | B29: =B8 -> JINDAL POWER LTD - STAGE 2 | C29: =IF(C$19=0,0,C8/C$19*100) -> 2.1842628 | D29: =IF(D$19=0,0,D8/D$19*100) -> 1.5033956 | E29: =IF(E$19=0,0,E8/E$19*100) -> 3.4404646 | F29: =IF(F$19=0,0,F8/F$19*100) -> 2.4782993 | G29: =IF(G$19=0,0,G8/G$19*100) -> 5.7689811 | H29: =IF(H$19=0,0,H8/H$19*100) -> 5.6766163 | I29: =IF(I$19=0,0,I8/I$19*100) -> 5.581205 | J29: =IF(J$19=0,0,J8/J$19*100) -> 3.6203664
A30: =A9 -> 7 | B30: =B9 -> MADHYA PRADESH | C30: =IF(C$19=0,0,C9/C$19*100) -> 3.1757321 | D30: =IF(D$19=0,0,D9/D$19*100) -> 3.8932159 | E30: =IF(E$19=0,0,E9/E$19*100) -> 4.7013412 | F30: =IF(F$19=0,0,F9/F$19*100) -> 2.9110452 | G30: =IF(G$19=0,0,G9/G$19*100) -> 2.5775427 | H30: =IF(H$19=0,0,H9/H$19*100) -> 2.9148037 | I30: =IF(I$19=0,0,I9/I$19*100) -> 1.9604271 | J30: =IF(J$19=0,0,J9/J$19*100) -> 3.284773
A31: =A10 -> 8 | B31: =B10 -> HIMACHAL PRADESH | C31: =IF(C$19=0,0,C10/C$19*100) -> 5.473736 | D31: =IF(D$19=0,0,D10/D$19*100) -> 3.8107369 | E31: =IF(E$19=0,0,E10/E$19*100) -> 2.4531194 | F31: =IF(F$19=0,0,F10/F$19*100) -> 2.1992072 | G31: =IF(G$19=0,0,G10/G$19*100) -> 2.8236877 | H31: =IF(H$19=0,0,H10/H$19*100) -> 2.1901595 | I31: =IF(I$19=0,0,I10/I$19*100) -> 0.95848776 | J31: =IF(J$19=0,0,J10/J$19*100) -> 3.0588663
A32: =A11 -> 9 | B32: =B11 -> SEIL ENERGY INDIA (EX-SEMBCORP) | C32: =IF(C$19=0,0,C11/C$19*100) -> 5.8273651 | D32: =IF(D$19=0,0,D11/D$19*100) -> 5.189371 | E32: =IF(E$19=0,0,E11/E$19*100) -> 3.5082804 | F32: =IF(F$19=0,0,F11/F$19*100) -> 1.6187455 | G32: =IF(G$19=0,0,G11/G$19*100) -> 1.3655504 | H32: =IF(H$19=0,0,H11/H$19*100) -> 1.1797302 | I32: =IF(I$19=0,0,I11/I$19*100) -> 0.37896314 | J32: =IF(J$19=0,0,J11/J$19*100) -> 2.9981607
A33: =A12 -> 10 | B33: =B12 -> ADANI POWER - RAIPUR TPP (EX-GMR CHHATTISGARH) | C33: =IF(C$19=0,0,C12/C$19*100) -> 3.878276 | D33: =IF(D$19=0,0,D12/D$19*100) -> 1.099314 | E33: =IF(E$19=0,0,E12/E$19*100) -> 2.0576942 | F33: =IF(F$19=0,0,F12/F$19*100) -> 3.1163268 | G33: =IF(G$19=0,0,G12/G$19*100) -> 4.788026 | H33: =IF(H$19=0,0,H12/H$19*100) -> 2.825348 | I33: =IF(I$19=0,0,I12/I$19*100) -> 3.2148554 | J33: =IF(J$19=0,0,J12/J$19*100) -> 2.9453411
A34: =A13 -> 11 | B34: =B13 -> KARNATAKA | C34: =IF(C$19=0,0,C13/C$19*100) -> 1.2865086 | D34: =IF(D$19=0,0,D13/D$19*100) -> 4.5774246 | E34: =IF(E$19=0,0,E13/E$19*100) -> 4.1293866 | F34: =IF(F$19=0,0,F13/F$19*100) -> 1.377041 | G34: =IF(G$19=0,0,G13/G$19*100) -> 3.43411 | H34: =IF(H$19=0,0,H13/H$19*100) -> 1.7203847 | I34: =IF(I$19=0,0,I13/I$19*100) -> 0.76604474 | J34: =IF(J$19=0,0,J13/J$19*100) -> 2.6916311
A35: =A14 -> 12 | B35: =B14 -> MAHAN ENERGEN (EX-ESSAR POWER MP) | C35: =IF(C$19=0,0,C14/C$19*100) -> 1.5436048 | D35: =IF(D$19=0,0,D14/D$19*100) -> 1.7687079 | E35: =IF(E$19=0,0,E14/E$19*100) -> 1.6087117 | F35: =IF(F$19=0,0,F14/F$19*100) -> 2.8217464 | G35: =IF(G$19=0,0,G14/G$19*100) -> 4.7751943 | H35: =IF(H$19=0,0,H14/H$19*100) -> 3.2788626 | I35: =IF(I$19=0,0,I14/I$19*100) -> 2.1446495 | J35: =IF(J$19=0,0,J14/J$19*100) -> 2.6144554
... A40: =A19 -> 0 | B40: =B19 -> TOTAL | C40: =IF(C$19=0,0,C19/C$19*100) -> 100 | D40: =IF(D$19=0,0,D19/D$19*100) -> 100 | E40: =IF(E$19=0,0,E19/E$19*100) -> 100 | F40: =IF(F$19=0,0,F19/F$19*100) -> 100 | G40: =IF(G$19=0,0,G19/G$19*100) -> 100 | H40: =IF(H$19=0,0,H19/H$19*100) -> 100 | I40: =IF(I$19=0,0,I19/I$19*100) -> 100 | J40: =IF(J$19=0,0,J19/J$19*100) -> 100

Sheet Top15_ByYear_Sold_CY
A1: SOLD in DAM - each period's own top 15 players (MU and % of that period), from Annual_Sold_CY
A2: 2020 | F2: 2021 | K2: 2022 | P2: 2023 | U2: 2024 | Z2: 2025 | AE2: 2026 (2026-01 to 2026-03 only)
A3: Rank | B3: Player | C3: MU | D3: % share | F3: Rank | G3: Player | H3: MU | I3: % share | K3: Rank | L3: Player | M3: MU | N3: % share | P3: Rank | Q3: Player | R3: MU | S3: % share | U3: Rank | V3: Player | W3: MU | X3: % share | Z3: Rank | AA3: Player | AB3: MU | AC3: % share | AE3: Rank | AF3: Player | AG3: MU | AH3: % share
A4: 1 | B4: =INDEX(Annual_Sold_CY!$A$3:$A$304,MATCH(A4,Annual_Sold_CY!$K$3:$K$304,0)) -> TEESTA URJA (TEESTA-III HEP) | C4: =INDEX(Annual_Sold_CY!$B$3:$B$304,MATCH(B4,Annual_Sold_CY!$A$3:$A$304,0)) -> 4669.39 | D4: =IF(C$20=0,0,C4/C$20*100) -> 8.2751927 | F4: 1 | G4: =INDEX(Annual_Sold_CY!$A$3:$A$304,MATCH(F4,Annual_Sold_CY!$L$3:$L$304,0)) -> UTTAR PRADESH | H4: =INDEX(Annual_Sold_CY!$C$3:$C$304,MATCH(G4,Annual_Sold_CY!$A$3:$A$304,0)) -> 6692.48 | I4: =IF(H$20=0,0,H4/H$20*100) -> 10.18994 | K4: 1 | L4: =INDEX(Annual_Sold_CY!$A$3:$A$304,MATCH(K4,Annual_Sold_CY!$M$3:$M$304,0)) -> UTTAR PRADESH | M4: =INDEX(Annual_Sold_CY!$D$3:$D$304,MATCH(L4,Annual_Sold_CY!$A$3:$A$304,0)) -> 6753.72 | N4: =IF(M$20=0,0,M4/M$20*100) -> 12.555078 | P4: 1 | Q4: =INDEX(Annual_Sold_CY!$A$3:$A$304,MATCH(P4,Annual_Sold_CY!$N$3:$N$304,0)) -> UTTAR PRADESH | R4: =INDEX(Annual_Sold_CY!$E$3:$E$304,MATCH(Q4,Annual_Sold_CY!$A$3:$A$304,0)) -> 7651.46 | S4: =IF(R$20=0,0,R4/R$20*100) -> 14.469861 | U4: 1 | V4: =INDEX(Annual_Sold_CY!$A$3:$A$304,MATCH(U4,Annual_Sold_CY!$O$3:$O$304,0)) -> UTTAR PRADESH | W4: =INDEX(Annual_Sold_CY!$F$3:$F$304,MATCH(V4,Annual_Sold_CY!$A$3:$A$304,0)) -> 4638.41 | X4: =IF(W$20=0,0,W4/W$20*100) -> 7.8210837 | Z4: 1 | AA4: =INDEX(Annual_Sold_CY!$A$3:$A$304,MATCH(Z4,Annual_Sold_CY!$P$3:$P$304,0)) -> UTTAR PRADESH | AB4: =INDEX(Annual_Sold_CY!$G$3:$G$304,MATCH(AA4,Annual_Sold_CY!$A$3:$A$304,0)) -> 4047.69 | AC4: =IF(AB$20=0,0,AB4/AB$20*100) -> 6.6954321 | AE4: 1 | AF4: =INDEX(Annual_Sold_CY!$A$3:$A$304,MATCH(AE4,Annual_Sold_CY!$Q$3:$Q$304,0)) -> UTTAR PRADESH | AG4: =INDEX(Annual_Sold_CY!$H$3:$H$304,MATCH(AF4,Annual_Sold_CY!$A$3:$A$304,0)) -> 1436.57 | AH4: =IF(AG$20=0,0,AG4/AG$20*100) -> 7.3350456
