Workbook
Name \a: #REF!
Name \a: #REF!
Name \b: #REF!
Name \b: #REF!
Name \c: #REF!
Name \c: #REF!
Name \d: #REF!
Name \e: #REF!
Name \F: #REF!
Name \g: #REF!
Name \h: #REF!
Name \i: #REF!
Name \j: #REF!
Name \l: #REF!
Name \M: [1]bajaj_copeland!$D$508
Name \M: #REF!
Name \n: #REF!
Name \o: #REF!
Name \p: #REF!
Name \q: #REF!
Name \r: #REF!
Name \s: #REF!
Name \t: #REF!
Name \u: #REF!
Name \u: [2]Header!#REF!
Name \v: #REF!
Name \VAL: #REF!
Name \w: #REF!
Name \x: #REF!
Name \y: #REF!
Name \z: #REF!
Name __________Less_Misc_expenditure: #REF!
Name __________Reserves_n_surplus: #REF!
Name __________Revaluation_reserves: #REF!
Name ______Current_Year_maturity: #REF!
Name ______Current_Year_maturity: #REF!
Name ______Long_term_borrowings: #REF!
Name ______Long_term_borrowings: #REF!
Name ______Short_term_borrowings: #REF!
Name ______Short_term_borrowings: #REF!
Name ______Trade_Payables: #REF!
Name ______Trade_Payables: #REF!
Name _____Deferred_tax_Assets: #REF!
Name _____Deferred_tax_Assets: #REF!
Name _____Fixed_assets_Net_block: #REF!
Name _____Fixed_assets_Net_block: #REF!
Name _____Goodwill_on_Consolidation: #REF!
Name _____Goodwill_on_Consolidation: #REF!
Name _____Long_Term_loans_and_advances: #REF!
Name _____Non_current_Investments: #REF!
Name _____Other_non_current_assets: #REF!
Name _____Share_Capital: #REF!
Name _____Share_Capital: #REF!
Name ____Minorities_interests_BS: #REF!
Name ____Minorities_interests_BS: #REF!
Name ____Share_application_money_pending_allotment: #REF!
Name ____Share_application_money_pending_allotment: #REF!
Name ____Shareholders_funds: #REF!
Name ____Shareholders_funds: #REF!
Name ___Adjusted_EPS_Rs: #REF!

Sheet Key (2)
B2: Name of Project SPV(s) | C2: Status | D2: State | E2: Type | F2: Capacity (in MW) | G2: Off-taker | H2: Tariff (INR/kWh) | I2: COD | J2: PPA Tenor (years) | K2: LOA
B3: ACME Solar Technologies (Gujarat) Private Limited | C3: Operational | D3: Gujarat | E3: Solar | F3: 15 | G3: GUVNL | H3: 5 | I3: 40969 | J3: 25
B4: ACME Solar Energy MP Private Limited | C4: Operational | D4: Madhya Pradesh | E4: Solar | F4: 25 | G4: MPPMCL | H4: 8.05 | I4: 41670 | J4: 25
B5: ACME Odisha Solar Power Private Limited | C5: Operational | D5: Odisha | E5: Solar | F5: 25 | G5: Off-taker | H5: 7.28 | I5: 42156 | J5: 25
B6: Acme Raipur Solar Power Private Limited | C6: Operational | D6: Chhattisgarh | E6: Solar | F6: 30 | G6: CSPDCL | H6: 6.46 | I6: 42460 | J6: 25
B7: Acme Solar Rooftop Systems Private Limited | C7: Operational | D7: Punjab | E7: Solar | F7: 30 | G7: PSPCL | H7: 7.57 | I7: 42521 | J7: 25
B8: Aarohi Solar Power Private Limited | C8: Operational | D8: Andhra Pradesh | E8: Solar | F8: 50 | G8: APSPDCL | H8: 5.63 | I8: 42460 | J8: 25
B9: Acme Jaisalmer Solar Power Private Limited | C9: Operational | D9: Andhra Pradesh | E9: Solar | F9: 20 | G9: APSPDCL | H9: 5.63 | I9: 42521 | J9: 25
B10: Dayanidhi Solar Power Private Limited | C10: Operational | D10: Andhra Pradesh | E10: Solar | F10: 40 | G10: APSPDCL | H10: 5.97 | I10: 42490 | J10: 25
B11: Niranjana Solar Power Private Limited | C11: Operational | D11: Andhra Pradesh | E11: Solar | F11: 20 | G11: APSPDCL | H11: 5.71 | I11: 42460 | J11: 25
B12: Viswatma Solar Energy Private Limited | C12: Operational | D12: Andhra Pradesh | E12: Solar | F12: 30 | G12: APSPDCL | H12: 5.71 | I12: 42490 | J12: 25
B13: ACME Magadh Solar Power Private Limited | C13: Operational | D13: Bihar | E13: Solar | F13: 10 | G13: SBPDCL and NBPDCL | H13: 8.73 | I13: 42551 | J13: 25
B14: ACME Nalanda Solar Power Private Limited | C14: Operational | D14: Bihar | E14: Solar | F14: 15 | G14: SBPDCL and NBPDCL | H14: 8.73 | I14: 42551 | J14: 25
... B33: Acme Eco Clean Energy Pvt. Ltd. | C33: Operational | D33: Gujarat | E33: Wind | F33: 72 | G33: GUVNL | H33: 3.01 | I33: 45945 | J33: 25
B34: ACME Eco Clean Energy Private Limited | C34: Under Construction | E34: Wind | F34: 28 | G34: GUVNL | H34: 3.01 | I34: 46053 | J34: 25
B35: ACME Surya Power Private Limited | C35: Under Construction | E35: FDRE | F35: 250 | G35: SJVN | H35: 4.38 | I35: 46173 | J35: 25 | K35: 45245
B36: ACME Sun Power Private Limited | C36: Under Construction | E36: FDRE | F36: 320 | G36: SJVN | H36: 4.38 | I36: 46173 | J36: 25 | K36: 45245
B37: ACME Urja One Private Limited | C37: Under Construction | E37: FDRE | F37: 190 | G37: SECI | H37: 4.73 | I37: 46203 | J37: 25 | K37: 45031
B38: ACME Renewtech Private Limited | C38: Under Construction | E38: Hybrid | F38: 300 | G38: NTPC | H38: 3.36 | I38: 46477 | J38: 25 | K38: 45275
B39: ACME Platinum Urja Private Limited | C39: Under Construction | E39: FDRE | F39: 350 | G39: SECI | H39: 3.42 | I39: 46295 | J39: 25 | K39: 45488
B40: Acme Venue Urja Pvt Ltd | C40: Under Construction | E40: FDRE | F40: 400 | G40: NHPC | H40: 4.64 | I40: 46477 | J40: 25 | K40: 45337
B41: ACME Hybrid Urja Private Limited | C41: Under Construction | E41: FDRE | F41: 280 | G41: NHPC | H41: 4.64 | I41: =+K41+30*30 -> 46237 | J41: 25 | K41: 45337
B42: Acme Renewtech Fifth Pvt Ltd | C42: Under Construction | E42: FDRE | F42: 250 | G42: NHPC | H42: 4.56 | I42: 46361 | J42: 25 | K42: 45641
A43: TPDDL, 250 MW, RE with ESS, Pan India, April 2025 | B43: ACME Sigma Urja Private Limited | C43: Under Construction | E43: FDRE | F43: 50 | G43: TPDDL | H43: 4.43 | I43: =+K43+24*30 -> 46604 | J43: 25 | K43: 45884
B44: ACME Urja One Private Limited | C44: Under Construction | E44: FDRE | F44: 250 | G44: NHPC | H44: 4.33 | J44: 25
B45: ACME Greentech Nineth Pvt. Ltd. | C45: Under Construction | E45: BESS | F45: 450 | G45: NHPC | H45: 2.22 lakhs/MW/Month | I45: =+K45+18*30 -> 46363 | J45: 25 | K45: 45823
B46: ACME Greentech Nineth Pvt. Ltd. | C46: Under Construction | E46: BESS | F46: 100 | G46: NHPC | H46: 2.22 lakhs/MW/Month | I46: =+K46+18*30 -> 46363 | J46: 25 | K46: 45823
A47: SECI, 1200 MW, Wind Solar Hybrid with ESS )Tranche VI, Pan India Nov 2022 | B47: Acme Urja One Pvt. Ltd. | C47: L1 | E47: FDRE | F47: 190 | G47: SECI | H47: 4.73 | I47: =+K47+50*30 -> 46531 | K47: 45031
A48: SECI, 1200 MW , ISTS Connected Solar with 600 MW/1200 MWh ESS (ISTS-XV), Pan India, Mar 2024 | B48: ACME Marigold Urja Pvt. Ltd. | C48: L1 | E48: FDRE | F48: 130 | G48: SECI | H48: 4.35 | I48: =+K48+35*30 -> 46538 | K48: 45488
B49: Acme Alpha Renewables Pvt. Ltd. | C49: L1 | E49: Hybrid | F49: 150 | G49: NTPC | H49: 3.32 | I49: =+K49+40*30 -> 46566 | K49: 45366
B50: Acme Omega Urja Pvt. Ltd. | C50: L1 | E50: Solar | F50: 300 | G50: SJVN | H50: 2.52 | I50: =+K50+40*30 -> 46719 | K50: 45519
B51: Acme Renewtech Second Pvt. Ltd. | C51: L1 | E51: Hybrid | F51: 300 | G51: SECI | H51: 3.25 | I51: =+K51+32*30 -> 46540 | K51: 45580
B52: Acme Marigold Urja Pvt. Ltd. | C52: L1 | E52: FDRE | F52: 400 | G52: NTPC | H52: 4.7 | I52: =+K52+36*30 -> 46691 | K52: 45611
A53: https://www.mercomindia.com/acme-and-ceigall-win-rumsls-600-mw-solar-plus-storage-auction | B53: Acme Renewtech Fourth Pvt. Ltd. | C53: L1 | E53: FDRE | F53: 220 | H53: 2.764 | I53: =+K53+36*30 -> 47002 | K53: 45922
A54: SJVN, 6000 MWh, peak power supply from ISTS connected RE Power with ESS, Pan India, Dec 2024 | B54: ACME Greentech Seventh Pvt. Ltd | C54: L1 | E54: FDRE | F54: 450 | G54: SJVN | H54: 6.74 | I54: =+K54+36*30 -> 47025 | K54: 45945
B57: Operational
B58: Solar | C58: =+SUMIFS($F$3:$F$54,$E$3:$E$54,$B58,$C$3:$C$54,$B$57) -> 2840
B59: Wind | C59: =+SUMIFS($F$3:$F$54,$E$3:$E$54,$B59,$C$3:$C$54,$B$57) -> 122
B60: FDRE | C60: =+SUMIFS($F$3:$F$54,$E$3:$E$54,$B60,$C$3:$C$54,$B$57) -> 0
B61: Hybrid | C61: =+SUMIFS($F$3:$F$54,$E$3:$E$54,$B61,$C$3:$C$54,$B$57) -> 0
...

Sheet Key_New
A2: # | B2: Project SPV | C2: Status | D2: State | E2: Technology | F2: Capacity (MW) | G2: BESS (MWh) | H2: Off-taker | I2: Off-taker category | J2: Tariff (INR/kWh) | K2: PPA tenor (yrs) | L2: PPA signed | M2: LoA / award date | N2: Company SCOD / guidance | O2: Model COD | P2: COD FY | Q2: Debt tied up | R2: Grid connectivity | S2: Tariff adoption | T2: Company SCOD basis | U2: Notes
A3: 1 | B3: ACME Solar Technologies (Gujarat) Pvt Ltd | C3: Operational | D3: Gujarat | E3: Solar | F3: 15 | H3: GUVNL | I3: =IF($H3="","–",IF($H3="GUVNL","GUVNL",IF(OR($H3="SECI",$H3="NTPC",$H3="SJVN",$H3="NHPC"),"Central","State & Other"))) -> GUVNL | J3: 5 | K3: 25 | L3: Yes | O3: 40999 | P3: =IF($O3="","–",IF(MONTH($O3)<=3,YEAR($O3),YEAR($O3)+1)) -> 2012 | T3: Actual (commissioned) | U3: Tariff INR 15.00/kWh for first 12 years, INR 5.00/kWh for next 13 years
A4: 2 | B4: ACME Solar Energy MP Pvt Ltd | C4: Operational | D4: Madhya Pradesh | E4: Solar | F4: 25 | H4: MPPMCL | I4: =IF($H4="","–",IF($H4="GUVNL","GUVNL",IF(OR($H4="SECI",$H4="NTPC",$H4="SJVN",$H4="NHPC"),"Central","State & Other"))) -> State & Other | J4: 8.05 | K4: 25 | L4: Yes | O4: 41670 | P4: =IF($O4="","–",IF(MONTH($O4)<=3,YEAR($O4),YEAR($O4)+1)) -> 2014 | T4: Actual (commissioned) | U4: Phase I 10 MW Dec-13; Phase II 15 MW Jan-14
A5: 3 | B5: ACME Odisha Solar Power Pvt Ltd | C5: Operational | D5: Odisha | E5: Solar | F5: 25 | H5: GRIDCO | I5: =IF($H5="","–",IF($H5="GUVNL","GUVNL",IF(OR($H5="SECI",$H5="NTPC",$H5="SJVN",$H5="NHPC"),"Central","State & Other"))) -> State & Other | J5: 7.28 | K5: 25 | L5: Yes | O5: 42185 | P5: =IF($O5="","–",IF(MONTH($O5)<=3,YEAR($O5),YEAR($O5)+1)) -> 2016 | T5: Actual (commissioned)
A6: 4 | B6: ACME Raipur Solar Power Pvt Ltd | C6: Operational | D6: Chhattisgarh | E6: Solar | F6: 30 | H6: CSPDCL | I6: =IF($H6="","–",IF($H6="GUVNL","GUVNL",IF(OR($H6="SECI",$H6="NTPC",$H6="SJVN",$H6="NHPC"),"Central","State & Other"))) -> State & Other | J6: 6.46 | K6: 25 | L6: Yes | O6: 42460 | P6: =IF($O6="","–",IF(MONTH($O6)<=3,YEAR($O6),YEAR($O6)+1)) -> 2016 | T6: Actual (commissioned) | U6: Phase I 23 MW Jan-16; Phase II 7 MW Mar-16
A7: 5 | B7: ACME Solar Rooftop Systems Pvt Ltd | C7: Operational | D7: Punjab | E7: Solar | F7: 30 | H7: PSPCL | I7: =IF($H7="","–",IF($H7="GUVNL","GUVNL",IF(OR($H7="SECI",$H7="NTPC",$H7="SJVN",$H7="NHPC"),"Central","State & Other"))) -> State & Other | J7: 7.57 | K7: 25 | L7: Yes | O7: 42521 | P7: =IF($O7="","–",IF(MONTH($O7)<=3,YEAR($O7),YEAR($O7)+1)) -> 2017 | T7: Actual (commissioned)
A8: 6 | B8: Aarohi Solar Power Pvt Ltd | C8: Operational | D8: Andhra Pradesh | E8: Solar | F8: 50 | H8: APSPDCL | I8: =IF($H8="","–",IF($H8="GUVNL","GUVNL",IF(OR($H8="SECI",$H8="NTPC",$H8="SJVN",$H8="NHPC"),"Central","State & Other"))) -> State & Other | J8: 7.35 | K8: 25 | L8: Yes | O8: 42460 | P8: =IF($O8="","–",IF(MONTH($O8)<=3,YEAR($O8),YEAR($O8)+1)) -> 2016 | T8: Actual (commissioned)
A9: 7 | B9: ACME Jaisalmer Solar Power Pvt Ltd | C9: Operational | D9: Andhra Pradesh | E9: Solar | F9: 20 | H9: APSPDCL | I9: =IF($H9="","–",IF($H9="GUVNL","GUVNL",IF(OR($H9="SECI",$H9="NTPC",$H9="SJVN",$H9="NHPC"),"Central","State & Other"))) -> State & Other | J9: 7.35 | K9: 25 | L9: Yes | O9: 42521 | P9: =IF($O9="","–",IF(MONTH($O9)<=3,YEAR($O9),YEAR($O9)+1)) -> 2017 | T9: Actual (commissioned)
A10: 8 | B10: Dayanidhi Solar Power Pvt Ltd | C10: Operational | D10: Andhra Pradesh | E10: Solar | F10: 40 | H10: APSPDCL | I10: =IF($H10="","–",IF($H10="GUVNL","GUVNL",IF(OR($H10="SECI",$H10="NTPC",$H10="SJVN",$H10="NHPC"),"Central","State & Other"))) -> State & Other | J10: 7.79 | K10: 25 | L10: Yes | O10: 42490 | P10: =IF($O10="","–",IF(MONTH($O10)<=3,YEAR($O10),YEAR($O10)+1)) -> 2017 | T10: Actual (commissioned)
A11: 9 | B11: Niranjana Solar Power Pvt Ltd | C11: Operational | D11: Andhra Pradesh | E11: Solar | F11: 20 | H11: APSPDCL | I11: =IF($H11="","–",IF($H11="GUVNL","GUVNL",IF(OR($H11="SECI",$H11="NTPC",$H11="SJVN",$H11="NHPC"),"Central","State & Other"))) -> State & Other | J11: 7.45 | K11: 25 | L11: Yes | O11: 42460 | P11: =IF($O11="","–",IF(MONTH($O11)<=3,YEAR($O11),YEAR($O11)+1)) -> 2016 | T11: Actual (commissioned)
A12: 10 | B12: Viswatma Solar Energy Pvt Ltd | C12: Operational | D12: Andhra Pradesh | E12: Solar | F12: 30 | H12: APSPDCL | I12: =IF($H12="","–",IF($H12="GUVNL","GUVNL",IF(OR($H12="SECI",$H12="NTPC",$H12="SJVN",$H12="NHPC"),"Central","State & Other"))) -> State & Other | J12: 7.45 | K12: 25 | L12: Yes | O12: 42490 | P12: =IF($O12="","–",IF(MONTH($O12)<=3,YEAR($O12),YEAR($O12)+1)) -> 2017 | T12: Actual (commissioned)
A13: 11 | B13: ACME Magadh Solar Power Pvt Ltd | C13: Operational | D13: Bihar | E13: Solar | F13: 10 | H13: SBPDCL & NBPDCL | I13: =IF($H13="","–",IF($H13="GUVNL","GUVNL",IF(OR($H13="SECI",$H13="NTPC",$H13="SJVN",$H13="NHPC"),"Central","State & Other"))) -> State & Other | J13: 8.73 | K13: 25 | L13: Yes | O13: 42551 | P13: =IF($O13="","–",IF(MONTH($O13)<=3,YEAR($O13),YEAR($O13)+1)) -> 2017 | T13: Actual (commissioned)
A14: 12 | B14: ACME Nalanda Solar Power Pvt Ltd | C14: Operational | D14: Bihar | E14: Solar | F14: 15 | H14: SBPDCL & NBPDCL | I14: =IF($H14="","–",IF($H14="GUVNL","GUVNL",IF(OR($H14="SECI",$H14="NTPC",$H14="SJVN",$H14="NHPC"),"Central","State & Other"))) -> State & Other | J14: 8.73 | K14: 25 | L14: Yes | O14: 42551 | P14: =IF($O14="","–",IF(MONTH($O14)<=3,YEAR($O14),YEAR($O14)+1)) -> 2017 | T14: Actual (commissioned)
A15: 13 | B15: Dayakara Solar Power Pvt Ltd | C15: Operational | D15: Telangana | E15: Solar | F15: 30 | H15: TSSPDCL | I15: =IF($H15="","–",IF($H15="GUVNL","GUVNL",IF(OR($H15="SECI",$H15="NTPC",$H15="SJVN",$H15="NHPC"),"Central","State & Other"))) -> State & Other | J15: 6.848 | K15: 25 | L15: Yes | O15: 42582 | P15: =IF($O15="","–",IF(MONTH($O15)<=3,YEAR($O15),YEAR($O15)+1)) -> 2017 | T15: Actual (commissioned) | U15: Phase I 14 MW Jun-16; Phase II 16 MW Jul-16
A16: 14 | B16: Grahati Solar Power Pvt Ltd | C16: Operational | D16: Telangana | E16: Solar | F16: 50 | H16: TSSPDCL | I16: =IF($H16="","–",IF($H16="GUVNL","GUVNL",IF(OR($H16="SECI",$H16="NTPC",$H16="SJVN",$H16="NHPC"),"Central","State & Other"))) -> State & Other | J16: 6.737 | K16: 25 | L16: Yes | O16: 42613 | P16: =IF($O16="","–",IF(MONTH($O16)<=3,YEAR($O16),YEAR($O16)+1)) -> 2017 | T16: Actual (commissioned) | U16: Phase I 20 MW Jul-16; Phase II 30 MW Aug-16
A17: 15 | B17: ACME PV Powertech Pvt Ltd | C17: Operational | D17: Telangana | E17: Solar | F17: 50 | H17: TSNPDCL | I17: =IF($H17="","–",IF($H17="GUVNL","GUVNL",IF(OR($H17="SECI",$H17="NTPC",$H17="SJVN",$H17="NHPC"),"Central","State & Other"))) -> State & Other | J17: 5.595 | K17: 25 | L17: Yes | O17: 42978 | P17: =IF($O17="","–",IF(MONTH($O17)<=3,YEAR($O17),YEAR($O17)+1)) -> 2018 | T17: Actual (commissioned) | U17: Phase I 40 MW Jul-17; Phase II 10 MW Aug-17
A18: 16 | B18: ACME Solar Power Technology Pvt Ltd | C18: Operational | D18: Telangana | E18: Solar | F18: 50 | H18: TSNPDCL | I18: =IF($H18="","–",IF($H18="GUVNL","GUVNL",IF(OR($H18="SECI",$H18="NTPC",$H18="SJVN",$H18="NHPC"),"Central","State & Other"))) -> State & Other | J18: 5.59 | K18: 25 | L18: Yes | O18: 43159 | P18: =IF($O18="","–",IF(MONTH($O18)<=3,YEAR($O18),YEAR($O18)+1)) -> 2018 | T18: Actual (commissioned)
A19: 17 | B19: ACME Yamunanagar Solar Power Pvt Ltd | C19: Operational | D19: Telangana | E19: Solar | F19: 20 | H19: NTPC | I19: =IF($H19="","–",IF($H19="GUVNL","GUVNL",IF(OR($H19="SECI",$H19="NTPC",$H19="SJVN",$H19="NHPC"),"Central","State & Other"))) -> Central | J19: 4.67 | K19: 25 | L19: Yes | O19: 43008 | P19: =IF($O19="","–",IF(MONTH($O19)<=3,YEAR($O19),YEAR($O19)+1)) -> 2018 | T19: Actual (commissioned)
A20: 18 | B20: ACME Mahbubnagar Solar Energy Pvt Ltd | C20: Operational | D20: Telangana | E20: Solar | F20: 30 | H20: NTPC | I20: =IF($H20="","–",IF($H20="GUVNL","GUVNL",IF(OR($H20="SECI",$H20="NTPC",$H20="SJVN",$H20="NHPC"),"Central","State & Other"))) -> Central | J20: 4.67 | K20: 25 | L20: Yes | O20: 43008 | P20: =IF($O20="","–",IF(MONTH($O20)<=3,YEAR($O20),YEAR($O20)+1)) -> 2018 | T20: Actual (commissioned)
A21: 19 | B21: Nirosha Power Pvt Ltd | C21: Operational | D21: Uttar Pradesh | E21: Solar | F21: 30 | H21: UPPCL | I21: =IF($H21="","–",IF($H21="GUVNL","GUVNL",IF(OR($H21="SECI",$H21="NTPC",$H21="SJVN",$H21="NHPC"),"Central","State & Other"))) -> State & Other | J21: 8.93 | K21: 12 | L21: Yes | O21: 42643 | P21: =IF($O21="","–",IF(MONTH($O21)<=3,YEAR($O21),YEAR($O21)+1)) -> 2017 | T21: Actual (commissioned) | U21: PPA tenor 12 years, renewable for a further 13 years
A22: 20 | B22: ACME Sidlaghatta Solar Energy Pvt Ltd | C22: Operational | D22: Karnataka | E22: Solar | F22: 20 | H22: BESCOM | I22: =IF($H22="","–",IF($H22="GUVNL","GUVNL",IF(OR($H22="SECI",$H22="NTPC",$H22="SJVN",$H22="NHPC"),"Central","State & Other"))) -> State & Other | J22: 2.97 | K22: 25 | L22: Yes | O22: 43769 | P22: =IF($O22="","–",IF(MONTH($O22)<=3,YEAR($O22),YEAR($O22)+1)) -> 2020 | T22: Actual (commissioned)
A23: 21 | B23: ACME Jodhpur Solar Power Pvt Ltd | C23: Operational | D23: Rajasthan | E23: Solar | F23: 100 | H23: SECI | I23: =IF($H23="","–",IF($H23="GUVNL","GUVNL",IF(OR($H23="SECI",$H23="NTPC",$H23="SJVN",$H23="NHPC"),"Central","State & Other"))) -> Central | J23: 2.44 | K23: 25 | L23: Yes | O23: 43373 | P23: =IF($O23="","–",IF(MONTH($O23)<=3,YEAR($O23),YEAR($O23)+1)) -> 2019 | T23: Actual (commissioned)
A24: 22 | B24: ACME Rewa Solar Power Pvt Ltd | C24: Operational | D24: Rajasthan | E24: Solar | F24: 100 | H24: SECI | I24: =IF($H24="","–",IF($H24="GUVNL","GUVNL",IF(OR($H24="SECI",$H24="NTPC",$H24="SJVN",$H24="NHPC"),"Central","State & Other"))) -> Central | J24: 2.44 | K24: 25 | L24: Yes | O24: 43404 | P24: =IF($O24="","–",IF(MONTH($O24)<=3,YEAR($O24),YEAR($O24)+1)) -> 2019 | T24: Actual (commissioned)
A25: 23 | B25: ACME Heergarh Powertech Pvt Ltd | C25: Operational | D25: Rajasthan | E25: Solar | F25: 300 | H25: MSEDCL | I25: =IF($H25="","–",IF($H25="GUVNL","GUVNL",IF(OR($H25="SECI",$H25="NTPC",$H25="SJVN",$H25="NHPC"),"Central","State & Other"))) -> State & Other | J25: 2.74 | K25: 25 | L25: Yes | O25: 44712 | P25: =IF($O25="","–",IF(MONTH($O25)<=3,YEAR($O25),YEAR($O25)+1)) -> 2023 | T25: Actual (commissioned) | U25: Phase I 100 MW Apr-22; Phase II 200 MW May-22. ICRA AA- rated
A26: 24 | B26: ACME Aklera Power Technology Pvt Ltd | C26: Operational | D26: Rajasthan | E26: Solar | F26: 250 | H26: SECI | I26: =IF($H26="","–",IF($H26="GUVNL","GUVNL",IF(OR($H26="SECI",$H26="NTPC",$H26="SJVN",$H26="NHPC"),"Central","State & Other"))) -> Central | J26: 2.48 | K26: 25 | L26: Yes | O26: 45322 | P26: =IF($O26="","–",IF(MONTH($O26)<=3,YEAR($O26),YEAR($O26)+1)) -> 2024 | T26: Actual (commissioned) | U26: Phase I 200 MW Jul-23; Phase II 50 MW Jan-24
A27: 25 | B27: ACME Raisar Solar Energy Pvt Ltd | C27: Operational | D27: Rajasthan | E27: Solar | F27: 300 | H27: SECI | I27: =IF($H27="","–",IF($H27="GUVNL","GUVNL",IF(OR($H27="SECI",$H27="NTPC",$H27="SJVN",$H27="NHPC"),"Central","State & Other"))) -> Central | J27: 2.44 | K27: 25 | L27: Yes | O27: 45688 | P27: =IF($O27="","–",IF(MONTH($O27)<=3,YEAR($O27),YEAR($O27)+1)) -> 2025 | T27: Actual (commissioned) | U27: Phase I 272 MW Dec-24; Phase II 28 MW Jan-25
A28: 26 | B28: ACME Dhaulpur Powertech Pvt Ltd | C28: Operational | D28: Rajasthan | E28: Solar | F28: 300 | H28: SECI | I28: =IF($H28="","–",IF($H28="GUVNL","GUVNL",IF(OR($H28="SECI",$H28="NTPC",$H28="SJVN",$H28="NHPC"),"Central","State & Other"))) -> Central | J28: 2.44 | K28: 25 | L28: Yes | O28: 45688 | P28: =IF($O28="","–",IF(MONTH($O28)<=3,YEAR($O28),YEAR($O28)+1)) -> 2025 | T28: Actual (commissioned) | U28: Phase I 238 MW Dec-24; Phase II 62 MW Jan-25
A29: 27 | B29: ACME Deoghar Solar Power Pvt Ltd | C29: Operational | D29: Rajasthan | E29: Solar | F29: 300 | H29: SECI | I29: =IF($H29="","–",IF($H29="GUVNL","GUVNL",IF(OR($H29="SECI",$H29="NTPC",$H29="SJVN",$H29="NHPC"),"Central","State & Other"))) -> Central | J29: 2.44 | K29: 25 | L29: Yes | O29: 45688 | P29: =IF($O29="","–",IF(MONTH($O29)<=3,YEAR($O29),YEAR($O29)+1)) -> 2025 | T29: Actual (commissioned) | U29: Phase I 253 MW Dec-24; Phase II 47 MW Jan-25
A30: 28 | B30: ACME Phalodi Solar Energy Pvt Ltd | C30: Operational | D30: Rajasthan | E30: Solar | F30: 300 | H30: SECI | I30: =IF($H30="","–",IF($H30="GUVNL","GUVNL",IF(OR($H30="SECI",$H30="NTPC",$H30="SJVN",$H30="NHPC"),"Central","State & Other"))) -> Central | J30: 2.44 | K30: 25 | L30: Yes | O30: 45688 | P30: =IF($O30="","–",IF(MONTH($O30)<=3,YEAR($O30),YEAR($O30)+1)) -> 2025 | T30: Actual (commissioned) | U30: Phase I 260 MW Dec-24; Phase II 40 MW Jan-25
A31: 29 | B31: ACME Sikar Solar Pvt Ltd | C31: Operational | D31: Rajasthan | E31: Solar | F31: 300 | H31: SECI | I31: =IF($H31="","–",IF($H31="GUVNL","GUVNL",IF(OR($H31="SECI",$H31="NTPC",$H31="SJVN",$H31="NHPC"),"Central","State & Other"))) -> Central | J31: 3.05 | K31: 25 | L31: Yes | O31: 45838 | P31: =IF($O31="","–",IF(MONTH($O31)<=3,YEAR($O31),YEAR($O31)+1)) -> 2026 | T31: Actual (commissioned) | U31: Commissioned May-Jun 25
A32: 30 | B32: ACME Pokhran Solar Pvt Ltd | C32: Operational | D32: Gujarat | E32: Wind | F32: 50 | H32: GUVNL | I32: =IF($H32="","–",IF($H32="GUVNL","GUVNL",IF(OR($H32="SECI",$H32="NTPC",$H32="SJVN",$H32="NHPC"),"Central","State & Other"))) -> GUVNL | J32: 2.9 | K32: 25 | L32: Yes | O32: 45838 | P32: =IF($O32="","–",IF(MONTH($O32)<=3,YEAR($O32),YEAR($O32)+1)) -> 2026 | T32: Actual (commissioned) | U32: CRISIL A+ rated
A33: 31 | B33: ACME Eco Clean Energy Pvt Ltd (Ph I-II) | C33: Operational | D33: Gujarat | E33: Wind | F33: 72 | H33: GUVNL | I33: =IF($H33="","–",IF($H33="GUVNL","GUVNL",IF(OR($H33="SECI",$H33="NTPC",$H33="SJVN",$H33="NHPC"),"Central","State & Other"))) -> GUVNL | J33: 3.01 | K33: 25 | L33: Yes | O33: 46053 | P33: =IF($O33="","–",IF(MONTH($O33)<=3,YEAR($O33),YEAR($O33)+1)) -> 2026 | T33: Actual (commissioned) | U33: Phase I 28 MW Oct-25; Phase II 44 MW Jan-26. CRISIL A+ rated
A34: 32 | B34: ACME Eco Clean Energy Pvt Ltd (Ph III) | C34: Operational | D34: Gujarat | E34: Wind | F34: 20 | H34: GUVNL | I34: =IF($H34="","–",IF($H34="GUVNL","GUVNL",IF(OR($H34="SECI",$H34="NTPC",$H34="SJVN",$H34="NHPC"),"Central","State & Other"))) -> GUVNL | J34: 3.01 | K34: 25 | L34: Yes | O34: 46112 | P34: =IF($O34="","–",IF(MONTH($O34)<=3,YEAR($O34),YEAR($O34)+1)) -> 2026 | T34: Actual (commissioned) | U34: Phase III commissioned Feb-Apr 26; split estimated so FY26 close ties to 2,982 MW per AR26
A35: 33 | B35: ACME Eco Clean Energy Pvt Ltd (Ph IV) | C35: Operational | D35: Gujarat | E35: Wind | F35: 8 | H35: GUVNL | I35: =IF($H35="","–",IF($H35="GUVNL","GUVNL",IF(OR($H35="SECI",$H35="NTPC",$H35="SJVN",$H35="NHPC"),"Central","State & Other"))) -> GUVNL | J35: 3.01 | K35: 25 | L35: Yes | O35: 46142 | P35: =IF($O35="","–",IF(MONTH($O35)<=3,YEAR($O35),YEAR($O35)+1)) -> 2027 | T35: Actual (commissioned) | U35: 8 MW commissioned after 31-Mar-26 (AR26 fn 54); takes operational portfolio to 2,990 MW
A36: 34 | B36: ACME Surya Power Pvt Ltd | C36: Under Construction | D36: Rajasthan | E36: FDRE | F36: 250 | H36: SJVN | I36: =IF($H36="","–",IF($H36="GUVNL","GUVNL",IF(OR($H36="SECI",$H36="NTPC",$H36="SJVN",$H36="NHPC"),"Central","State & Other"))) -> Central | J36: 4.38 | K36: 25 | L36: Yes | M36: 45245 | N36: 46568 | O36: 46568 | P36: =IF($O36="","–",IF(MONTH($O36)<=3,YEAR($O36),YEAR($O36)+1)) -> 2028 | Q36: Yes | R36: Secured | S36: Tariff adopted | T36: Disclosed (deck SCOD) | U36: Fatehgarh II. Night-time GNA Dec-26. Mgmt will not commission on TGNA — solar awaits daytime GNA; battery operated first
A37: 35 | B37: ACME Sun Power Pvt Ltd | C37: Under Construction | D37: Rajasthan | E37: FDRE | F37: 320 | H37: SJVN | I37: =IF($H37="","–",IF($H37="GUVNL","GUVNL",IF(OR($H37="SECI",$H37="NTPC",$H37="SJVN",$H37="NHPC"),"Central","State & Other"))) -> Central | J37: 4.38 | K37: 25 | L37: Yes | M37: 45245 | N37: 46568 | O37: 46568 | P37: =IF($O37="","–",IF(MONTH($O37)<=3,YEAR($O37),YEAR($O37)+1)) -> 2028 | Q37: Yes | R37: Secured | S37: Tariff adopted | T37: Disclosed (deck SCOD) | U37: Fatehgarh II. Night-time GNA Dec-26. Mgmt will not commission on TGNA — solar awaits daytime GNA; battery operated first
A38: 36 | B38: ACME Urja One Pvt Ltd (SECI) | C38: Under Construction | D38: Andhra Pradesh / Maharashtra | E38: FDRE | F38: 380 | H38: SECI | I38: =IF($H38="","–",IF($H38="GUVNL","GUVNL",IF(OR($H38="SECI",$H38="NTPC",$H38="SJVN",$H38="NHPC"),"Central","State & Other"))) -> Central | J38: 4.73 | K38: 25 | L38: Yes | M38: 45031 | N38: 46326 | O38: 46433 | P38: =IF($O38="","–",IF(MONTH($O38)<=3,YEAR($O38),YEAR($O38)+1)) -> 2027 | Q38: Yes | R38: Secured | S38: Tariff adopted | T38: Disclosed (phased from Sep-26) | U38: Deck shows phased commissioning from Sep-26 but carries only 190 MW of the 380 MW in the FY27 target table. Dating the full capacity at mid-Feb-27 approximates half the capacity running from Sep-26 plus the balance later, without splitting the row.
A39: 37 | B39: ACME Renewtech Pvt Ltd | C39: Under Construction | D39: Rajasthan / Maharashtra | E39: Hybrid | F39: 300 | H39: NTPC | I39: =IF($H39="","–",IF($H39="GUVNL","GUVNL",IF(OR($H39="SECI",$H39="NTPC",$H39="SJVN",$H39="NHPC"),"Central","State & Other"))) -> Central | J39: 3.36 | K39: 25 | L39: Yes | M39: 45275 | N39: 46660 | O39: 46660 | P39: =IF($O39="","–",IF(MONTH($O39)<=3,YEAR($O39),YEAR($O39)+1)) -> 2028 | Q39: Yes | R39: Secured | S39: Tariff adopted | T39: Disclosed (deck SCOD) | U39: Returned to the contractual SCOD of Sep-27 per the Q1 FY27 deck. The earlier FY27 placement assumed commissioning well ahead of SCOD on the Bikaner III GNA being available from Sep-26, which proved too aggressive.
A40: 38 | B40: ACME Platinum Urja Pvt Ltd | C40: Under Construction | D40: Karnataka | E40: FDRE | F40: 350 | H40: SECI | I40: =IF($H40="","–",IF($H40="GUVNL","GUVNL",IF(OR($H40="SECI",$H40="NTPC",$H40="SJVN",$H40="NHPC"),"Central","State & Other"))) -> Central | J40: 3.42 | K40: 25 | L40: Yes | M40: 45488 | N40: 46477 | O40: 46433 | P40: =IF($O40="","–",IF(MONTH($O40)<=3,YEAR($O40),YEAR($O40)+1)) -> 2027 | Q40: Yes | R40: Secured | S40: Tariff adopted | T40: Disclosed (deck SCOD) | U40: Deck SCOD is Mar-27 and the FY27 target table carries only 150 MW of the 350 MW. Dated mid-Feb-27 so it commissions within FY27 but contributes only ~6 weeks of generation.
A41: 39 | B41: ACME Venus Urja Pvt Ltd | C41: Under Construction | D41: – | E41: FDRE | F41: 400 | H41: NHPC | I41: =IF($H41="","–",IF($H41="GUVNL","GUVNL",IF(OR($H41="SECI",$H41="NTPC",$H41="SJVN",$H41="NHPC"),"Central","State & Other"))) -> Central | J41: 4.64 | K41: 25 | L41: Yes | M41: 45337 | O41: 46660 | P41: =IF($O41="","–",IF(MONTH($O41)<=3,YEAR($O41),YEAR($O41)+1)) -> 2028 | Q41: Yes | R41: Secured | S41: Tariff adopted | T41: Not disclosed
...

Sheet Consolidated
B2: P&L, Rs. Mn - Consolidated | D2: 2018 | E2: 2019 | F2: 2020 | G2: 2021 | H2: 2022 | I2: 2023 | J2: 2024 | K2: 2025 | L2: =+K2+1 -> 2026 | M2: 2027E | N2: 2028E | O2: 2029E | P2: 2030E
B5: Revenue from Operations | D5: 10961.34 | E5: 16718.99 | F5: 17772.54 | G5: 16917.45 | H5: 14879.02 | I5: 12949.04 | J5: 13192.5 | K5: 14051.31 | L5: =20229.59+4.2 -> 20233.79 | M5: =Assumptions!G6 -> 40060.235 | N5: =Assumptions!H6 -> 69187.16 | O5: =Assumptions!I6 -> 95080.807 | P5: =Assumptions!J6 -> 113592.78 | Q5: =(N5/K5)^(1/3)-1 -> 0.70125558 | R5: =(P5/K5)^(1/5)-1 -> 0.51889161 | T5: Consensus | U5: FY27E | V5: FY28E | W5: FY29E
B6: growth, % | I6: =I5/H5-1 -> -0.1297115 | J6: =J5/I5-1 -> 0.018801394 | K6: =K5/J5-1 -> 0.065098351 | L6: =L5/K5-1 -> 0.43999314 | M6: =M5/L5-1 -> 0.97986808 | N6: =N5/M5-1 -> 0.72707824 | O6: =O5/N5-1 -> 0.37425509 | P6: =P5/O5-1 -> 0.19469726 | T6: Revenue | U6: =[111]Sheet1!U14 -> 37816.8 | V6: =[111]Sheet1!V14 -> 69856.533 | W6: =[111]Sheet1!W14 -> 95602.615
T7: EBITDA | U7: =[111]Sheet1!U28 -> 31581.8 | V7: =[111]Sheet1!V28 -> 59535.667 | W7: =[111]Sheet1!W28 -> 81852.357
B8: Cost of material consumed | D8: 544.85 | E8: 691.95 | F8: 146.06 | G8: 0 | H8: 938.5 | T8: EBITDAM | U8: =+U7/U6 -> 0.83512619 | V8: =+V7/V6 -> 0.85225624 | W8: =+W7/W6 -> 0.85617278
B9: Employee benefit expenses | D9: 517.58 | E9: 100.25 | F9: 60.16 | G9: 301.36 | H9: 382.37 | I9: 346.44 | J9: 589.95 | K9: 649.75 | L9: 619.69 | T9: PAT | U9: =[111]Sheet1!U43 -> 8163.1333 | V9: =[111]Sheet1!V43 -> 16047.133 | W9: =[111]Sheet1!W43 -> 22406.769
B10: Other expenses | D10: 1070.12 | E10: 1407.89 | F10: 1080.59 | G10: 1088.42 | H10: 1154.93 | I10: 876.67 | J10: 1711.07 | K10: 1047.56 | L10: 1800.74 | T10: Depreciation | U10: =[111]Sheet1!U26 -> 7696.7394 | V10: =[111]Sheet1!V26 -> 14101.158 | W10: =[111]Sheet1!W26 -> 19495.897
B11: Total Expenses | D11: =SUM(D8:D10) -> 2132.55 | E11: =SUM(E8:E10) -> 2200.09 | F11: =SUM(F8:F10) -> 1286.81 | G11: =SUM(G8:G10) -> 1389.78 | H11: =SUM(H8:H10) -> 2475.8 | I11: =SUM(I8:I10) -> 1223.11 | J11: =SUM(J8:J10) -> 2301.02 | K11: =SUM(K8:K10) -> 1697.31 | L11: =SUM(L8:L10) -> 2420.43 | M11: =M5-M15 -> 7084.3125 | N11: =N5-N15 -> 8370.8169 | O11: =O5-O15 -> 11253.7 | P11: =P5-P15 -> 10910.831 | T11: Finance Cost | U11: =[111]Sheet1!U32 -> 17153.037 | V11: =[111]Sheet1!V32 -> 28234.251 | W11: =[111]Sheet1!W32 -> 37833.531
B12: growth, % | I12: =I11/H11-1 -> -0.50597383 | J12: =J11/I11-1 -> 0.88128623 | K12: =K11/J11-1 -> -0.26236625 | L12: =L11/K11-1 -> 0.42603885 | M12: =M11/L11-1 -> 1.9268818 | N12: =N11/M11-1 -> 0.18159905 | O12: =O11/N11-1 -> 0.34439683 | P12: =P11/O11-1 -> -0.03046721 | T12: Capex | U12: =-[111]Sheet1!U129 -> 162186.16 | V12: =-[111]Sheet1!V129 -> 179571.71 | W12: =-[111]Sheet1!W129 -> 117350.28
B13: as% of revenues | I13: =I11/I5 -> 0.094455651 | J13: =J11/J5 -> 0.1744188 | K13: =K11/K5 -> 0.12079372 | L13: =L11/L5 -> 0.11962317 | M13: =M11/M5 -> 0.17684151 | N13: =N11/N5 -> 0.12098801 | O13: =O11/O5 -> 0.11835932 | P13: =P11/P5 -> 0.096052152 | T13: Other Income | U13: =-[111]Sheet1!U33 -> 4937.7468 | V13: =-[111]Sheet1!V33 -> 5359.8467 | W13: =-[111]Sheet1!W33 -> 5610.8569
B15: EBITDA | D15: =D5-SUM(D8:D10) -> 8828.79 | E15: =E5-SUM(E8:E10) -> 14518.9 | F15: =F5-SUM(F8:F10) -> 16485.73 | G15: =G5-SUM(G8:G10) -> 15527.67 | H15: =H5-SUM(H8:H10) -> 12403.22 | I15: =I5-SUM(I8:I10) -> 11725.93 | J15: =J5-SUM(J8:J10) -> 10891.48 | K15: =K5-SUM(K8:K10) -> 12354 | L15: =L5-SUM(L8:L10) -> 17813.36 | M15: =Assumptions!G41 -> 32975.922 | N15: =Assumptions!H41 -> 60816.343 | O15: =Assumptions!I41 -> 83827.107 | P15: =Assumptions!J41 -> 102681.95 | Q15: =(N15/K15)^(1/3)-1 -> 0.70113025 | R15: =(P15/K15)^(1/5)-1 -> 0.52734554 | T15: Spark
B16: margin, % | D16: =IF(ISERROR(D15/D5)," ",D15/D5) -> 0.80544806 | E16: =IF(ISERROR(E15/E5)," ",E15/E5) -> 0.86840772 | F16: =IF(ISERROR(F15/F5)," ",F15/F5) -> 0.92759561 | G16: =IF(ISERROR(G15/G5)," ",G15/G5) -> 0.91784932 | H16: =IF(ISERROR(H15/H5)," ",H15/H5) -> 0.83360463 | I16: =IF(ISERROR(I15/I5)," ",I15/I5) -> 0.90554435 | J16: =IF(ISERROR(J15/J5)," ",J15/J5) -> 0.8255812 | K16: =IF(ISERROR(K15/K5)," ",K15/K5) -> 0.87920628 | L16: =IF(ISERROR(L15/L5)," ",L15/L5) -> 0.88037683 | M16: =IFERROR(M15/M5,"–") -> 0.82315849 | N16: =IFERROR(N15/N5,"–") -> 0.87901199 | O16: =IFERROR(O15/O5,"–") -> 0.88164068 | P16: =IFERROR(P15/P5,"–") -> 0.90394785 | T16: Revenue | U16: =M5 -> 40060.235 | V16: =N5 -> 69187.16 | W16: =O5 -> 95080.807
B17: growth, % | I17: =I15/H15-1 -> -0.054605981 | J17: =J15/I15-1 -> -0.071162799 | K17: =K15/J15-1 -> 0.13428111 | L17: =L15/K15-1 -> 0.44191031 | M17: =M15/L15-1 -> 0.85119048 | N17: =N15/M15-1 -> 0.8442651 | O17: =O15/N15-1 -> 0.37836481 | P17: =P15/O15-1 -> 0.22492535 | T17: EBITDA | U17: =M15 -> 32975.922 | V17: =N15 -> 60816.343 | W17: =O15 -> 83827.107
T18: EBITDAM | U18: =+U17/U16 -> 0.82315849 | V18: =+V17/V16 -> 0.87901199 | W18: =+W17/W16 -> 0.88164068
B19: Other Income | D19: 901.32 | E19: 1304.23 | F19: 776.58 | G19: 2184.67 | H19: 748.24 | I19: 664.69 | J19: 1470.17 | K19: 1701.1 | L19: 4837.01 | M19: =M215 -> 4246.5051 | N19: =N215 -> 5795.6285 | O19: =O215 -> 7246.9913 | P19: =P215 -> 7874.3622 | T19: PAT | U19: =M43 -> 8891.3067 | V19: =N43 -> 16962.06 | W19: =O43 -> 23112.177
B20: Depreciation and Amortisation | D20: 3668.95 | E20: 5708.07 | F20: 7000.8 | G20: 6217.8 | H20: 5462.75 | I20: 4848.02 | J20: 3081.38 | K20: 2873.13 | L20: 4679.02 | M20: =SUM(Assumptions!BP53:BP133) -> 7198.5436 | N20: =SUM(Assumptions!BQ53:BQ133) -> 15339.542 | O20: =SUM(Assumptions!BR53:BR133) -> 21812.595 | P20: =SUM(Assumptions!BS53:BS133) -> 29531.773 | T20: Depreciation | U20: =M20 -> 7198.5436 | V20: =N20 -> 15339.542 | W20: =O20 -> 21812.595
T21: Finance Cost | U21: =M24 -> 17937.057 | V21: =N24 -> 28214.235 | W21: =O24 -> 37842.85
B22: EBIT | D22: =D15+D19-D20 -> 6061.16 | E22: =E15+E19-E20 -> 10115.06 | F22: =F15+F19-F20 -> 10261.51 | G22: =G15+G19-G20 -> 11494.54 | H22: =H15+H19-H20 -> 7688.71 | I22: =I15+I19-I20 -> 7542.6 | J22: =J15+J19-J20 -> 9280.27 | K22: =K15+K19-K20 -> 11181.97 | ... P22: =P15+P19-P20 -> 81024.538 | T22: Capex | U22: =-M143 -> 197107.33 | V22: =-N143 -> 218628.95 | W22: =-O143 -> 139541.89
T23: Other Income | U23: =+M19 -> 4246.5051 | V23: =+N19 -> 5795.6285 | W23: =+O19 -> 7246.9913
B24: Finance Expenses | D24: 6503.15 | E24: 10173.2 | F24: 12368.28 | G24: 11505.63 | H24: 9960.08 | I24: 8090.97 | J24: 7672.93 | K24: 7592.07 | L24: 11229.88 | M24: =M237 -> 17937.057 | N24: =N237 -> 28214.235 | O24: =O237 -> 37842.85 | P24: =P237 -> 42004.948
T25: Revenue | U25: =+U16/U6-1 -> 0.059323764 | V25: =+V16/V6-1 -> -0.0095821157 | W25: =+W16/W6-1 -> -0.0054581007
T26: EBITDA | U26: =+U17/U7-1 -> 0.044143224 | V26: =+V17/V7-1 -> 0.021511078 | W26: =+W17/W7-1 -> 0.024125755
B27: PBT Before Exceptionals | D27: =D22-D24 -> -441.99 | E27: =E22-E24 -> -58.14 | F27: =F22-F24 -> -2106.77 | G27: =G22-G24 -> -11.09 | H27: =H22-H24 -> -2271.37 | I27: =I22-I24 -> -548.37 | J27: =J22-J24 -> 1607.34 | K27: =K22-K24-K25 -> 3589.9 | L27: =L22-L24-L25 -> 6741.47 | M27: =M22-M24 -> 12086.827 | N27: =N22-N24-N25 -> 23058.194 | O27: =O22-O24-O25 -> 31418.654 | P27: =P22-P24-P25 -> 39019.59 | T27: PAT | U27: =+U19/U9-1 -> 0.089202679 | V27: =+V19/V9-1 -> 0.057014936 | W27: =+W19/W9-1 -> 0.031481919
B28: Exceptional item | D28: 0 | E28: 0 | F28: 0 | G28: 0 | H28: 3295.63 | I28: 394.36 | J28: 7486.91 | K28: -209.84 | L28: 26.77 | T28: Depreciation | U28: =+U20/U10-1 -> -0.06472817 | V28: =+V20/V10-1 -> 0.087821474 | W28: =+W20/W10-1 -> 0.11883001
T29: Finance Cost | U29: =+U21/U11-1 -> 0.045707358 | V29: =+V21/V11-1 -> -0.00070891655 | W29: =+W21/W11-1 -> 0.00024632272
B30: PBT after Exceptional | D30: =D27+D28 -> -441.99 | E30: =E27+E28 -> -58.14 | F30: =F27+F28 -> -2106.77 | G30: =G27+G28 -> -11.09 | H30: =H27+H28 -> 1024.26 | I30: =I27+I28 -> -154.01 | J30: =J27+J28 -> 9094.25 | K30: =K27+K28 -> 3380.06 | ... P30: =P27+P28 -> 39019.59 | T30: Capex | U30: =+U22/U12-1 -> 0.21531537 | V30: =+V22/V12-1 -> 0.2175022 | W30: =+W22/W12-1 -> 0.18910571
T31: Other Income | U31: =+U23/U13-1 -> -0.13999132 | V31: =+V23/V13-1 -> 0.081304887 | W31: =+W23/W13-1 -> 0.29160152
B32: Tax
B33: Current Tax | D33: 61.24 | E33: 223.35 | F33: 56.63 | G33: 215.17 | H33: 27.26 | I33: 55.48 | J33: 1069.21 | K33: 730.48 | L33: 1685.06
B34: Deferred Tax | D34: 1900.31 | E34: 187.17 | F34: -3019.77 | G34: -378.39 | H34: 511.92 | I34: -179.21 | J34: 1046.38 | K34: 141.67 | L34: 104.33
B35: Prior Period Tax | D35: 0 | E35: 0 | F35: 0 | G35: 0 | H35: -135.02 | I35: 1.46 | J35: 0.85
B36: Total Tax | D36: =SUM(D33:D35) -> 1961.55 | E36: =SUM(E33:E35) -> 410.52 | F36: =SUM(F33:F35) -> -2963.14 | G36: =SUM(G33:G35) -> -163.22 | H36: =SUM(H33:H35) -> 404.16 | I36: =SUM(I33:I35) -> -122.27 | J36: =SUM(J33:J35) -> 2116.44 | K36: =SUM(K33:K35) -> 872.15 | L36: =SUM(L33:L35) -> 1789.39 | M36: =M30*M37 -> 3195.5201 | N36: =N30*N37 -> 6096.1346 | O36: =O30*O37 -> 8306.4762 | P36: =P30*P37 -> 10316.015
B37: Effective tax rate, % | D37: =IF(ISERROR(D36/D30)," ",D36/D30) -> -4.4379963 | E37: =IF(ISERROR(E36/E30)," ",E36/E30) -> -7.0608875 | F37: =IF(ISERROR(F36/F30)," ",F36/F30) -> 1.4064848 | G37: =IF(ISERROR(G36/G30)," ",G36/G30) -> 14.717764 | H37: =IF(ISERROR(H36/H30)," ",H36/H30) -> 0.39458731 | I37: =IF(ISERROR(I36/I30)," ",I36/I30) -> 0.79390949 | J37: =IF(ISERROR(J36/J30)," ",J36/J30) -> 0.23272287 | K37: =IF(ISERROR(K36/K30)," ",K36/K30) -> 0.25802796 | L37: =IF(ISERROR(L36/L30)," ",L36/L30) -> 0.2643804 | M37: =L37 -> 0.2643804 | N37: =M37 -> 0.2643804 | O37: =N37 -> 0.2643804 | P37: =O37 -> 0.2643804
B39: PAT before Minority | D39: =D30-D36 -> -2403.54 | E39: =E30-E36 -> -468.66 | F39: =F30-F36 -> 856.37 | G39: =G30-G36 -> 152.13 | H39: =H30-H36 -> 620.1 | I39: =I30-I36 -> -31.74 | J39: =J30-J36 -> 6977.81 | K39: =K30-K36 -> 2507.91 | ... P39: =P30-P36 -> 28703.575
B41: Minority share | D41: 0 | E41: 0 | F41: 0 | G41: 0 | H41: -0.24 | I41: -0.33 | J41: -0.17 | K41: -12.87 | L41: -10.3
B43: PAT after Minority | D43: =D39-D41 -> -2403.54 | E43: =E39-E41 -> -468.66 | F43: =F39-F41 -> 856.37 | G43: =G39-G41 -> 152.13 | H43: =H39-H41 -> 620.34 | I43: =I39-I41 -> -31.41 | J43: =J39-J41 -> 6977.98 | K43: =K39-K41 -> 2520.78 | ... P43: =P39-P41 -> 28703.575
B44: margin, % | D44: =IF(ISERROR(D43/D5)," ",D43/D5) -> -0.21927429 | E44: =IF(ISERROR(E43/E5)," ",E43/E5) -> -0.028031598 | F44: =IF(ISERROR(F43/F5)," ",F43/F5) -> 0.048185009 | G44: =IF(ISERROR(G43/G5)," ",G43/G5) -> 0.00899249 | H44: =IF(ISERROR(H43/H5)," ",H43/H5) -> 0.041692262 | I44: =IF(ISERROR(I43/I5)," ",I43/I5) -> -0.0024256624 | J44: =IF(ISERROR(J43/J5)," ",J43/J5) -> 0.52893538 | K44: =IF(ISERROR(K43/K5)," ",K43/K5) -> 0.17939822 | ... P44: =IF(ISERROR(P43/P5)," ",P43/P5) -> 0.25268838
B45: growth, %
B46: Adjusted PAT | D46: =D43-D28 -> -2403.54 | E46: =E43-E28 -> -468.66 | F46: =F43-F28 -> 856.37 | G46: =G43-G28 -> 152.13 | H46: =H43-H28 -> -2675.29 | I46: =I43-I28 -> -425.77 | J46: =J43-J28 -> -508.93 | K46: =K43-K28 -> 2730.62 | ... P46: =P43-P28 -> 28703.575 | Q46: =(N46/K46)^(1/3)-1 -> 0.83825507 | R46: =(P46/K46)^(1/5)-1 -> 0.60079215
B47: margin, % | D47: =D46/D5 -> -0.21927429 | E47: =E46/E5 -> -0.028031598 | F47: =F46/F5 -> 0.048185009 | G47: =G46/G5 -> 0.00899249 | H47: =H46/H5 -> -0.17980284 | I47: =I46/I5 -> -0.03288043 | J47: =J46/J5 -> -0.038577222 | K47: =K46/K5 -> 0.19433206 | ... P47: =P46/P5 -> 0.25268838
...

Sheet Assumptions
BN1: =IF(AND($J360>DG$304,$J360<=DI$304),IF($I360>DG$304,$J360-$I360,$J360-DG$304),IF($J360<=DG$304,0,IF(AND($I360>DG$304,$I360<=DI$304),DI$304-$I360,IF($I360>DI$304,0,DI$304-DG$304)))) -> 0
B2: Operational metrics | C2: Units | D2: FY24A | E2: FY25A | F2: FY26A | G2: FY27E | H2: FY28E | I2: FY29E | J2: FY30E | K2: FY31E | Y2: Year of operation
B3: REVENUE | C3: INR mn | R3: BESS assumptions
B4: Generation | E4: 14051.31 | F4: 20233.79 | G4: {=SUMPRODUCT(($D$53:$D$133<>"BESS")*FX$53:FX$133*AZ$53:AZ$133)} -> 25063.567 | H4: {=SUMPRODUCT(($D$53:$D$133<>"BESS")*FY$53:FY$133*BA$53:BA$133)} -> 52196.35 | I4: {=SUMPRODUCT(($D$53:$D$133<>"BESS")*FZ$53:FZ$133*BB$53:BB$133)} -> 75437.119 | J4: {=SUMPRODUCT(($D$53:$D$133<>"BESS")*GA$53:GA$133*BC$53:BC$133)} -> 97636.751 | K4: {=SUMPRODUCT(($D$53:$D$133<>"BESS")*GB$53:GB$133*BD$53:BD$133)} -> 97636.751 | R4: Storage sizing — FDRE (MWh/MW) | S4: 4
B5: BESS | G5: {=SUMPRODUCT(($D$53:$D$133="BESS")*FX$53:FX$133*AZ$53:AZ$133)} -> 14996.668 | H5: {=SUMPRODUCT(($D$53:$D$133="BESS")*FY$53:FY$133*BA$53:BA$133)} -> 16990.81 | I5: {=SUMPRODUCT(($D$53:$D$133="BESS")*FZ$53:FZ$133*BB$53:BB$133)} -> 19643.688 | J5: {=SUMPRODUCT(($D$53:$D$133="BESS")*GA$53:GA$133*BC$53:BC$133)} -> 15956.028 | K5: {=SUMPRODUCT(($D$53:$D$133="BESS")*GB$53:GB$133*BD$53:BD$133)} -> 15956.028 | R5: Storage sizing — Hybrid (MWh/MW) | S5: 1
B6: Total | E6: =E4+E5 -> 14051.31 | F6: =F4+F5 -> 20233.79 | G6: =G4+G5 -> 40060.235 | H6: =H4+H5 -> 69187.16 | I6: =I4+I5 -> 95080.807 | J6: =J4+J5 -> 113592.78 | K6: =K4+K5 -> 113592.78 | R6: Capex (INR mn/MWh) | S6: 9.3
B7: Growth | C7: % | F7: =IFERROR(F6/E6-1,"–") -> 0.43999314 | G7: =IFERROR(G6/F6-1,"–") -> 0.97986808 | H7: =IFERROR(H6/G6-1,"–") -> 0.72707824 | I7: =IFERROR(I6/H6-1,"–") -> 0.37425509 | J7: =IFERROR(J6/I6-1,"–") -> 0.19469726 | K7: =IFERROR(K6/J6-1,"–") -> 0 | R7: Cycles per day | S7: 1
B9: Fiscal year (helper) | D9: 2024 | E9: 2025 | F9: 2026 | G9: 2027 | H9: 2028 | I9: 2029 | J9: 2030 | K9: 2031 | R9: Depth of discharge | S9: 0.93
B10: OPERATIONAL CAPACITY (year-end) | R10: Round-trip efficiency | S10: 0.89
B11: Solar | C11: MW | D11: 1340 | E11: 2540 | F11: 2840 | G11: =SUMIFS($F$53:$F$133,$D$53:$D$133,$B11,$I$53:$I$133,"<="&G$9) -> 2840 | H11: =SUMIFS($F$53:$F$133,$D$53:$D$133,$B11,$I$53:$I$133,"<="&H$9) -> 3140 | I11: =SUMIFS($F$53:$F$133,$D$53:$D$133,$B11,$I$53:$I$133,"<="&I$9) -> 3140 | J11: =SUMIFS($F$53:$F$133,$D$53:$D$133,$B11,$I$53:$I$133,"<="&J$9) -> 3140 | K11: =SUMIFS($F$53:$F$133,$D$53:$D$133,$B11,$I$53:$I$133,"<="&K$9) -> 3140 | R11: Availability | S11: 0.99
B12: Wind | C12: MW | D12: 0 | E12: 0 | F12: 142 | G12: =SUMIFS($F$53:$F$133,$D$53:$D$133,$B12,$I$53:$I$133,"<="&G$9) -> 150 | H12: =SUMIFS($F$53:$F$133,$D$53:$D$133,$B12,$I$53:$I$133,"<="&H$9) -> 150 | I12: =SUMIFS($F$53:$F$133,$D$53:$D$133,$B12,$I$53:$I$133,"<="&I$9) -> 150 | J12: =SUMIFS($F$53:$F$133,$D$53:$D$133,$B12,$I$53:$I$133,"<="&J$9) -> 150 | K12: =SUMIFS($F$53:$F$133,$D$53:$D$133,$B12,$I$53:$I$133,"<="&K$9) -> 150 | R12: Discharge duration (hours) | S12: 4
B13: BESS (MWh) | D13: 0 | E13: 0 | F13: 1324 | G13: =SUMIFS($F$53:$F$133,$D$53:$D$133,"BESS",$I$53:$I$133,"<="&G$9) -> 11508 | H13: =SUMIFS($F$53:$F$133,$D$53:$D$133,"BESS",$I$53:$I$133,"<="&H$9) -> 16508 | I13: =SUMIFS($F$53:$F$133,$D$53:$D$133,"BESS",$I$53:$I$133,"<="&I$9) -> 23958 | J13: =SUMIFS($F$53:$F$133,$D$53:$D$133,"BESS",$I$53:$I$133,"<="&J$9) -> 23958 | K13: =SUMIFS($F$53:$F$133,$D$53:$D$133,"BESS",$I$53:$I$133,"<="&K$9) -> 23958 | R13: Tariff — short term (INR/kWh) | S13: 9
B14: Complex | C14: MW | D14: =D15+D16 -> 0 | E14: =E15+E16 -> 0 | F14: =F15+F16 -> 0 | G14: =G15+G16 -> 1030 | H14: =H15+H16 -> 2580 | I14: =I15+I16 -> 4780 | J14: =J15+J16 -> 5580 | K14: =K15+K16 -> 5980 | R14: Charging power cost (INR/kWh) | S14: 1.4
B15: Hybrid | C15: MW | D15: 0 | E15: 0 | F15: 0 | G15: =SUMIFS($F$53:$F$133,$D$53:$D$133,$B15,$I$53:$I$133,"<="&G$9) -> 0 | H15: =SUMIFS($F$53:$F$133,$D$53:$D$133,$B15,$I$53:$I$133,"<="&H$9) -> 300 | I15: =SUMIFS($F$53:$F$133,$D$53:$D$133,$B15,$I$53:$I$133,"<="&I$9) -> 750 | J15: =SUMIFS($F$53:$F$133,$D$53:$D$133,$B15,$I$53:$I$133,"<="&J$9) -> 750 | K15: =SUMIFS($F$53:$F$133,$D$53:$D$133,$B15,$I$53:$I$133,"<="&K$9) -> 750 | R15: Capacity charge — contracted (INR lakh/MW/month) | S15: 2.22
B16: FDRE | C16: MW | D16: 0 | E16: 0 | F16: 0 | G16: =SUMIFS($F$53:$F$133,$D$53:$D$133,$B16,$I$53:$I$133,"<="&G$9) -> 1030 | H16: =SUMIFS($F$53:$F$133,$D$53:$D$133,$B16,$I$53:$I$133,"<="&H$9) -> 2280 | I16: =SUMIFS($F$53:$F$133,$D$53:$D$133,$B16,$I$53:$I$133,"<="&I$9) -> 4030 | J16: =SUMIFS($F$53:$F$133,$D$53:$D$133,$B16,$I$53:$I$133,"<="&J$9) -> 4830 | K16: =SUMIFS($F$53:$F$133,$D$53:$D$133,$B16,$I$53:$I$133,"<="&K$9) -> 5230 | R16: O&M (INR mn/MWh/yr) | S16: 0.09
B17: Installed Capacity | C17: MW | D17: =D11+D12+D14 -> 1340 | E17: =E11+E12+E14 -> 2540 | F17: =F11+F12+F14 -> 2982 | G17: =G11+G12+G14 -> 4020 | H17: =H11+H12+H14 -> 5870 | I17: =I11+I12+I14 -> 8070 | J17: =J11+J12+J14 -> 8870 | K17: =K11+K12+K14 -> 9270 | R17: Depreciation life (years) | S17: 20
R18: Years on short-term before PPA | S18: 1
B19: CAPACITY ADDITIONS | C19: MW | R19: Construction period — BESS (months) | S19: 9
B20: Solar | D20: =SUMIFS($F$53:$F$133,$D$53:$D$133,$B20,$I$53:$I$133,D$9) -> 250 | E20: =SUMIFS($F$53:$F$133,$D$53:$D$133,$B20,$I$53:$I$133,E$9) -> 1200 | F20: =SUMIFS($F$53:$F$133,$D$53:$D$133,$B20,$I$53:$I$133,F$9) -> 300 | G20: =SUMIFS($F$53:$F$133,$D$53:$D$133,$B20,$I$53:$I$133,G$9) -> 0 | H20: =SUMIFS($F$53:$F$133,$D$53:$D$133,$B20,$I$53:$I$133,H$9) -> 300 | I20: =SUMIFS($F$53:$F$133,$D$53:$D$133,$B20,$I$53:$I$133,I$9) -> 0 | J20: =SUMIFS($F$53:$F$133,$D$53:$D$133,$B20,$I$53:$I$133,J$9) -> 0 | K20: =SUMIFS($F$53:$F$133,$D$53:$D$133,$B20,$I$53:$I$133,K$9) -> 0 | R20: Equivalent CUF | S20: =365*S7*S9*S11/8760 -> 0.0383625
B21: Wind | D21: =SUMIFS($F$53:$F$133,$D$53:$D$133,$B21,$I$53:$I$133,D$9) -> 0 | E21: =SUMIFS($F$53:$F$133,$D$53:$D$133,$B21,$I$53:$I$133,E$9) -> 0 | F21: =SUMIFS($F$53:$F$133,$D$53:$D$133,$B21,$I$53:$I$133,F$9) -> 142 | G21: =SUMIFS($F$53:$F$133,$D$53:$D$133,$B21,$I$53:$I$133,G$9) -> 8 | H21: =SUMIFS($F$53:$F$133,$D$53:$D$133,$B21,$I$53:$I$133,H$9) -> 0 | I21: =SUMIFS($F$53:$F$133,$D$53:$D$133,$B21,$I$53:$I$133,I$9) -> 0 | J21: =SUMIFS($F$53:$F$133,$D$53:$D$133,$B21,$I$53:$I$133,J$9) -> 0 | K21: =SUMIFS($F$53:$F$133,$D$53:$D$133,$B21,$I$53:$I$133,K$9) -> 0 | R21: Tariff — contracted equivalent (INR/kWh) | S21: =(S15/10*12/S12)/(8.766*S20) -> 1.980459
B22: BESS (MWh) | D22: =SUMIFS($F$53:$F$133,$D$53:$D$133,"BESS",$I$53:$I$133,D$9) -> 0 | E22: =SUMIFS($F$53:$F$133,$D$53:$D$133,"BESS",$I$53:$I$133,E$9) -> 0 | F22: =SUMIFS($F$53:$F$133,$D$53:$D$133,"BESS",$I$53:$I$133,F$9) -> 1324 | G22: =SUMIFS($F$53:$F$133,$D$53:$D$133,"BESS",$I$53:$I$133,G$9) -> 10184 | H22: =SUMIFS($F$53:$F$133,$D$53:$D$133,"BESS",$I$53:$I$133,H$9) -> 5000 | I22: =SUMIFS($F$53:$F$133,$D$53:$D$133,"BESS",$I$53:$I$133,I$9) -> 7450 | J22: =SUMIFS($F$53:$F$133,$D$53:$D$133,"BESS",$I$53:$I$133,J$9) -> 0 | K22: =SUMIFS($F$53:$F$133,$D$53:$D$133,"BESS",$I$53:$I$133,K$9) -> 0 | R22: Capex spend calibration
B23: Complex | D23: =D24+D25 -> 0 | E23: =E24+E25 -> 0 | F23: =F24+F25 -> 0 | G23: =G24+G25 -> 1030 | H23: =H24+H25 -> 1550 | I23: =I24+I25 -> 2200 | J23: =J24+J25 -> 800 | K23: =K24+K25 -> 400 | R23: Spend factor vs elapsed time | S23: 0.4109
B24: Hybrid | D24: =SUMIFS($F$53:$F$133,$D$53:$D$133,$B24,$I$53:$I$133,D$9) -> 0 | E24: =SUMIFS($F$53:$F$133,$D$53:$D$133,$B24,$I$53:$I$133,E$9) -> 0 | F24: =SUMIFS($F$53:$F$133,$D$53:$D$133,$B24,$I$53:$I$133,F$9) -> 0 | G24: =SUMIFS($F$53:$F$133,$D$53:$D$133,$B24,$I$53:$I$133,G$9) -> 0 | H24: =SUMIFS($F$53:$F$133,$D$53:$D$133,$B24,$I$53:$I$133,H$9) -> 300 | I24: =SUMIFS($F$53:$F$133,$D$53:$D$133,$B24,$I$53:$I$133,I$9) -> 450 | J24: =SUMIFS($F$53:$F$133,$D$53:$D$133,$B24,$I$53:$I$133,J$9) -> 0 | K24: =SUMIFS($F$53:$F$133,$D$53:$D$133,$B24,$I$53:$I$133,K$9) -> 0 | R24: CWIP implied by spend factor (INR mn) | S24: =SUMPRODUCT($K$53:$K$133,$O$53:$O$133) -> 48317.393
B25: FDRE | D25: =SUMIFS($F$53:$F$133,$D$53:$D$133,$B25,$I$53:$I$133,D$9) -> 0 | E25: =SUMIFS($F$53:$F$133,$D$53:$D$133,$B25,$I$53:$I$133,E$9) -> 0 | F25: =SUMIFS($F$53:$F$133,$D$53:$D$133,$B25,$I$53:$I$133,F$9) -> 0 | G25: =SUMIFS($F$53:$F$133,$D$53:$D$133,$B25,$I$53:$I$133,G$9) -> 1030 | H25: =SUMIFS($F$53:$F$133,$D$53:$D$133,$B25,$I$53:$I$133,H$9) -> 1250 | I25: =SUMIFS($F$53:$F$133,$D$53:$D$133,$B25,$I$53:$I$133,I$9) -> 1750 | J25: =SUMIFS($F$53:$F$133,$D$53:$D$133,$B25,$I$53:$I$133,J$9) -> 800 | K25: =SUMIFS($F$53:$F$133,$D$53:$D$133,$B25,$I$53:$I$133,K$9) -> 400 | R25: CWIP actual at 31-Mar-26 (INR mn) | S25: 43577
B26: Total Additions | D26: =D20+D21+D23 -> 250 | E26: =E20+E21+E23 -> 1200 | F26: =F20+F21+F23 -> 442 | G26: =G20+G21+G23 -> 1038 | H26: =H20+H21+H23 -> 1850 | I26: =I20+I21+I23 -> 2200 | J26: =J20+J21+J23 -> 800 | K26: =K20+K21+K23 -> 400 | R26: Construction period — generation (months) | S26: 24
R27: Cost escalation (p.a.) | S27: 0.05
B28: SEGMENT FINANCIALS
B29: Revenue — RE generation | C29: INR mn | D29: =D4 -> 0 | E29: =E4 -> 14051.31 | F29: =F4 -> 20233.79 | G29: =G4 -> 25063.567 | H29: =H4 -> 52196.35 | I29: =I4 -> 75437.119 | J29: =J4 -> 97636.751 | K29: =K4 -> 97636.751
B30: Revenue — BESS | C30: INR mn | D30: =D5 -> 0 | E30: =E5 -> 0 | F30: =F5 -> 0 | G30: =G5 -> 14996.668 | H30: =H5 -> 16990.81 | I30: =I5 -> 19643.688 | J30: =J5 -> 15956.028 | K30: =K5 -> 15956.028
B31: Total revenue | C31: INR mn | D31: =D29+D30 -> 0 | E31: =E29+E30 -> 14051.31 | F31: =F29+F30 -> 20233.79 | G31: =G29+G30 -> 40060.235 | H31: =H29+H30 -> 69187.16 | I31: =I29+I30 -> 95080.807 | J31: =J29+J30 -> 113592.78 | K31: =K29+K30 -> 113592.78
B33: Cost of power purchased — BESS charging | C33: INR mn | D33: {=IFERROR(SUMPRODUCT(($D$53:$D$133="BESS")*(Y$53:Y$133>0)*(Y$53:Y$133<=$S$18)*AW$53:AW$133)*D34/$S$10,0)} -> 0 | E33: {=IFERROR(SUMPRODUCT(($D$53:$D$133="BESS")*(Z$53:Z$133>0)*(Z$53:Z$133<=$S$18)*AX$53:AX$133)*E34/$S$10,0)} -> 0 | F33: {=IFERROR(SUMPRODUCT(($D$53:$D$133="BESS")*(AA$53:AA$133>0)*(AA$53:AA$133<=$S$18)*AY$53:AY$133)*F34/$S$10,0)} -> 0 | G33: {=IFERROR(SUMPRODUCT(($D$53:$D$133="BESS")*(AB$53:AB$133>0)*(AB$53:AB$133<=$S$18)*AZ$53:AZ$133)*G34/$S$10,0)} -> 2621.1405 | H33: {=IFERROR(SUMPRODUCT(($D$53:$D$133="BESS")*(AC$53:AC$133>0)*(AC$53:AC$133<=$S$18)*BA$53:BA$133)*H34/$S$10,0)} -> 1630.0968 | I33: {=IFERROR(SUMPRODUCT(($D$53:$D$133="BESS")*(AD$53:AD$133>0)*(AD$53:AD$133<=$S$18)*BB$53:BB$133)*I34/$S$10,0)} -> 1511.7483 | J33: {=IFERROR(SUMPRODUCT(($D$53:$D$133="BESS")*(AE$53:AE$133>0)*(AE$53:AE$133<=$S$18)*BC$53:BC$133)*J34/$S$10,0)} -> 0 | K33: {=IFERROR(SUMPRODUCT(($D$53:$D$133="BESS")*(AF$53:AF$133>0)*(AF$53:AF$133<=$S$18)*BD$53:BD$133)*K34/$S$10,0)} -> 0
B34: charging cost | C34: INR / kWh | E34: =$S$14 -> 1.4 | F34: =$S$14 -> 1.4 | G34: =$S$14 -> 1.4 | H34: =$S$14 -> 1.4 | I34: =$S$14 -> 1.4 | J34: =$S$14 -> 1.4 | K34: =$S$14 -> 1.4
B35: Employee benefit expenses | C35: INR mn | D35: =D36*D17 -> 0 | E35: =E36*E17 -> 528.32 | F35: =F36*F17 -> 620.256 | G35: =G36*G17 -> 877.968 | H35: =H36*H17 -> 1346.1084 | I35: =I36*I17 -> 1943.143 | J35: =J36*J17 -> 2242.5604 | K35: =K36*K17 -> 2460.8751
B36: employee cost per MW | C36: INR mn / MW | D36: =D29*D33 -> 0 | E36: 0.208 | F36: 0.208 | G36: =F36*(1+$S$27) -> 0.2184 | H36: =G36*(1+$S$27) -> 0.22932 | I36: =H36*(1+$S$27) -> 0.240786 | J36: =I36*(1+$S$27) -> 0.2528253 | K36: =J36*(1+$S$27) -> 0.26546657
B37: Other expenses (O&M, insurance, admin) | C37: INR mn | D37: =D38*D17+D13*$S$16 -> 0 | E37: =E38*E17+E13*$S$16 -> 1534.16 | F37: =F38*F17+F13*$S$16 -> 1920.288 | G37: =G38*G17+G13*$S$16 -> 3585.204 | H37: =H38*H17+H13*$S$16 -> 5394.6117 | I37: =I38*I17+I13*$S$16 -> 7798.8084 | J37: =J38*J17+J13*$S$16 -> 8668.2704 | K37: =K38*K17+K13*$S$16 -> 9302.2226
B38: other expenses per MW | C38: INR mn / MW | D38: =D36+D37 -> 0 | E38: 0.604 | F38: 0.604 | G38: =F38*(1+$S$27) -> 0.6342 | H38: =G38*(1+$S$27) -> 0.66591 | I38: =H38*(1+$S$27) -> 0.6992055 | J38: =I38*(1+$S$27) -> 0.73416578 | K38: =J38*(1+$S$27) -> 0.77087406
B39: Total expenses | C39: INR mn | D39: =D33+D35+D37 -> 0 | E39: =E33+E35+E37 -> 2062.48 | F39: =F33+F35+F37 -> 2540.544 | G39: =G33+G35+G37 -> 7084.3125 | H39: =H33+H35+H37 -> 8370.8169 | I39: =I33+I35+I37 -> 11253.7 | J39: =J33+J35+J37 -> 10910.831 | K39: =K33+K35+K37 -> 11763.098
B41: EBITDA | C41: INR mn | D41: =D31-D39 -> 0 | E41: =E31-E39 -> 11988.83 | F41: =F31-F39 -> 17693.246 | G41: =G31-G39 -> 32975.922 | H41: =H31-H39 -> 60816.343 | I41: =I31-I39 -> 83827.107 | J41: =J31-J39 -> 102681.95 | K41: =K31-K39 -> 101829.68
B42: EBITDA margin — blended | C42: % | D42: =IFERROR(D41/D31,"–") -> – | E42: =IFERROR(E41/E31,"–") -> 0.85321796 | F42: =IFERROR(F41/F31,"–") -> 0.87444053 | G42: =IFERROR(G41/G31,"–") -> 0.82315849 | H42: =IFERROR(H41/H31,"–") -> 0.87901199 | I42: =IFERROR(I41/I31,"–") -> 0.88164068 | J42: =IFERROR(J41/J31,"–") -> 0.90394785 | K42: =IFERROR(K41/K31,"–") -> 0.89644502
B44: EBITDA — RE generation | C44: INR mn | D44: =IFERROR(D29-(D35+D37)*D29/D31,0) -> 0 | E44: =IFERROR(E29-(E35+E37)*E29/E31,0) -> 11988.83 | F44: =IFERROR(F29-(F35+F37)*F29/F31,0) -> 17693.246 | G44: =IFERROR(G29-(G35+G37)*G29/G31,0) -> 22271.197 | H44: =IFERROR(H29-(H35+H37)*H29/H31,0) -> 47110.999 | I44: =IFERROR(I29-(I35+I37)*I29/I31,0) -> 67707.854 | J44: =IFERROR(J29-(J35+J37)*J29/J31,0) -> 88258.531 | K44: =IFERROR(K29-(K35+K37)*K29/K31,0) -> 87525.98
...

Sheet Valuation
B2: #VALUE!
B3: CMP | C3: {=_FV(B2,"Price")} -> 372.85 | E3: <<Please check>>
B4: No of Shares (In mn) | C4: {=_FV(B2,"Shares outstanding",TRUE)/10^6} -> 705.9847
B5: Market Cap | C5: =C3*C4 -> 263226.4
B7: Acme Solar - Valuation Matrix
D8: FY24 | E8: FY25 | F8: FY26E | G8: FY27E | H8: FY28E | I8: FY29E | J8: FY30E | K8: FY27E | L8: FY28E | M8: FY29E
B9: P/E methodology | K9: Upside | P9: Acme Solar
B10: Consolidated EPS | C10: Rs./ share | E10: =Consolidated!K46/$C$4 -> 3.8678175 | F10: =Consolidated!L46/$C$4 -> 7.0290192 | G10: =Consolidated!M46/$C$4 -> 12.594192 | H10: =Consolidated!N46/$C$4 -> 24.026101 | I10: =Consolidated!O46/$C$4 -> 32.737505 | J10: =Consolidated!P46/$C$4 -> 40.657503 | K10: FY25E | L10: FY26E | M10: FY27E
B11: =CONCATENATE("At CMP of Rs. ",ROUND(C3,0),"/share") -> At CMP of Rs. 373/share | C11: implied P/E | E11: =$C$3/E10 -> 96.398032 | F11: =$C$3/F10 -> 53.044385 | G11: =$C$3/G10 -> 29.604917 | H11: =$C$3/H10 -> 15.51854 | I11: =$C$3/I10 -> 11.389078 | J11: =$C$3/J10 -> 9.170509 | P11: Till FY28
A12: 10 | B12: =CONCATENATE("-Target Price @",ROUND(A12,0),"x P/E") -> -Target Price @10x P/E | C12: Rs./ share | E12: =E$10*$A12 -> 38.678175 | F12: =F$10*$A12 -> 70.290192 | G12: =G$10*$A12 -> 125.94192 | H12: =H$10*$A12 -> 240.26101 | I12: =I$10*$A12 -> 327.37505 | J12: =J$10*$A12 -> 406.57503 | K12: =G12/$C$3-1 -> -0.66221827 | L12: =H12/$C$3-1 -> -0.35560947 | M12: =I12/$C$3-1 -> -0.12196582 | P12: Slide 1
A13: 15 | B13: =CONCATENATE("-Target Price @",ROUND(A13,0),"x P/E") -> -Target Price @15x P/E | C13: Rs./ share | E13: =E$10*$A13 -> 58.017263 | F13: =F$10*$A13 -> 105.43529 | G13: =G$10*$A13 -> 188.91288 | H13: =H$10*$A13 -> 360.39151 | I13: =I$10*$A13 -> 491.06257 | J13: =J$10*$A13 -> 609.86255 | K13: =G13/$C$3-1 -> -0.49332741 | L13: =H13/$C$3-1 -> -0.033414207 | M13: =I13/$C$3-1 -> 0.31705128 | P13: Installed Capacity by type
A14: 20 | B14: =CONCATENATE("-Target Price @",ROUND(A14,0),"x P/E") -> -Target Price @20x P/E | C14: Rs./ share | E14: =E$10*$A14 -> 77.356351 | F14: =F$10*$A14 -> 140.58038 | G14: =G$10*$A14 -> 251.88384 | H14: =H$10*$A14 -> 480.52202 | I14: =I$10*$A14 -> 654.75009 | J14: =J$10*$A14 -> 813.15007 | K14: =G14/$C$3-1 -> -0.32443654 | L14: =H14/$C$3-1 -> 0.28878106 | M14: =I14/$C$3-1 -> 0.75606837 | P14: Capacity additions by type
P15: Revenue
B16: P/BV methodology | P16: EBITDA
B17: Consolidated BVPS | C17: Rs./ share | D17: =(Consolidated!J56+Consolidated!J57+Consolidated!J58)/Valuation!$C$4 -> 36.698657 | E17: =(Consolidated!K56+Consolidated!K57+Consolidated!K58)/Valuation!$C$4 -> 63.89062 | F17: =(Consolidated!L56+Consolidated!L57+Consolidated!L58)/Valuation!$C$4 -> 71.693933 | G17: =(Consolidated!M56+Consolidated!M57+Consolidated!M58)/Valuation!$C$4 -> 123.94904 | H17: =(Consolidated!N56+Consolidated!N57+Consolidated!N58)/Valuation!$C$4 -> 147.97514 | I17: =(Consolidated!O56+Consolidated!O57+Consolidated!O58)/Valuation!$C$4 -> 180.71265 | J17: =(Consolidated!P56+Consolidated!P57+Consolidated!P58)/Valuation!$C$4 -> 221.37015 | P17: PAT
B18: =CONCATENATE("At CMP of Rs. ",ROUND(C3,0),"/share") -> At CMP of Rs. 373/share | C18: implied P/BV | D18: =$C$3/D17 -> 10.159772 | E18: =$C$3/E17 -> 5.8357549 | F18: =$C$3/F17 -> 5.2005795 | G18: =$C$3/G17 -> 3.008091 | H18: =$C$3/H17 -> 2.51968 | I18: =$C$3/I17 -> 2.0632203 | J18: =$C$3/J17 -> 1.6842831
A19: 1.5 | B19: =CONCATENATE("-Target Price @",ROUND(A19,0),"x P/BV") -> -Target Price @2x P/BV | C19: Rs./ share | D19: =D$17*$A19 -> 55.047985 | E19: =E$17*$A19 -> 95.83593 | F19: =F$17*$A19 -> 107.5409 | G19: =G$17*$A19 -> 185.92356 | H19: =H$17*$A19 -> 221.96271 | I19: =I$17*$A19 -> 271.06897 | J19: =J$17*$A19 -> 332.05522 | K19: =G19/$C$3-1 -> -0.50134488 | L19: =H19/$C$3-1 -> -0.4046863 | M19: =I19/$C$3-1 -> -0.27298117 | P19: Slide 2
A20: 2 | B20: =CONCATENATE("-Target Price @",ROUND(A20,1),"x P/BV") -> -Target Price @2x P/BV | C20: Rs./ share | D20: =D$17*$A20 -> 73.397313 | E20: =E$17*$A20 -> 127.78124 | F20: =F$17*$A20 -> 143.38787 | G20: =G$17*$A20 -> 247.89808 | H20: =H$17*$A20 -> 295.95028 | I20: =I$17*$A20 -> 361.42529 | J20: =J$17*$A20 -> 442.7403 | K20: =G20/$C$3-1 -> -0.33512651 | L20: =H20/$C$3-1 -> -0.2062484 | M20: =I20/$C$3-1 -> -0.030641565 | P20: Cashflow
A21: 2.5 | B21: =CONCATENATE("-Target Price @",ROUND(A21,1),"x P/BV") -> -Target Price @2.5x P/BV | C21: Rs./ share | D21: =D$17*$A21 -> 91.746641 | E21: =E$17*$A21 -> 159.72655 | F21: =F$17*$A21 -> 179.23483 | G21: =G$17*$A21 -> 309.8726 | H21: =H$17*$A21 -> 369.93785 | I21: =I$17*$A21 -> 451.78162 | J21: =J$17*$A21 -> 553.42537 | K21: =G21/$C$3-1 -> -0.16890813 | L21: =H21/$C$3-1 -> -0.0078105019 | M21: =I21/$C$3-1 -> 0.21169804 | P21: CAPEX
P22: Net Debt/EBITDA
B23: EV/EBITDA methodology | P23: RoCE/RoE
B24: Consolidated EBITDA | C24: Rs. mn | D24: =Consolidated!J15 -> 10891.48 | E24: =Consolidated!K15 -> 12354 | F24: =Consolidated!L15 -> 17813.36 | G24: =Consolidated!M15 -> 32975.922 | H24: =Consolidated!N15 -> 60816.343 | I24: =Consolidated!O15 -> 83827.107 | J24: =Consolidated!P15 -> 102681.95
B25: Prev year Net Debt | C25: Rs. mn | D25: =+Consolidated!J68-Consolidated!J98 -> 69027.18 | E25: =+Consolidated!J68-Consolidated!J98 -> 69027.18 | F25: =+Consolidated!K68-Consolidated!K98 -> 75066.69 | G25: =+Consolidated!L68-Consolidated!L98 -> 128299.58 | H25: =+Consolidated!M68-Consolidated!M98 -> 275768.44 | I25: =+Consolidated!N68-Consolidated!N98 -> 460371.27 | J25: =+Consolidated!O68-Consolidated!O98 -> 553455.29 | P25: Slide 3
B26: EV | C26: Rs. mn | D26: =$C$5+D25 -> 332253.58 | E26: =$C$5+E25 -> 332253.58 | F26: =$C$5+F25 -> 338293.09 | G26: =$C$5+G25 -> 391525.98 | H26: =$C$5+H25 -> 538994.84 | I26: =$C$5+I25 -> 723597.66 | J26: =$C$5+J25 -> 816681.69 | P26: Valuation Matrix
B27: =CONCATENATE("At CMP of Rs. ",ROUND(C3,0),"/share") -> At CMP of Rs. 373/share | C27: implied EV/ EBITDA | D27: =D26/D24 -> 30.505824 | E27: =E26/E24 -> 26.894413 | F27: =F26/F24 -> 18.990976 | G27: =G26/G24 -> 11.873086 | H27: =H26/H24 -> 8.8626644 | I27: =I26/I24 -> 8.6320247 | J27: =J26/J24 -> 7.9535079 | K27: Upside
A28: 10 | B28: =CONCATENATE("-Target Price @",ROUND(A28,0),"x EV/EBITDA") -> -Target Price @10x EV/EBITDA | C28: Rs./ share | D28: =(($A28*D$24)-Consolidated!J$65+Consolidated!J$98)/DCF!$C$4 -> 56.49927 | E28: =(($A28*E$24)-Consolidated!J$68+Consolidated!J$98)/DCF!$C$4 -> 77.215299 | F28: =(($A28*F$24)-Consolidated!K$68+Consolidated!K$98)/DCF!$C$4 -> 145.99029 | G28: =(($A28*G$24)-Consolidated!L$68+Consolidated!L$98)/DCF!$C$4 -> 285.35979 | H28: =(($A28*H$24)-Consolidated!M$68+Consolidated!M$98)/DCF!$C$4 -> 470.82464 | I28: =(($A28*I$24)-Consolidated!N$68+Consolidated!N$98)/DCF!$C$4 -> 535.28045 | J28: =(($A28*J$24)-Consolidated!O$68+Consolidated!O$98)/DCF!$C$4 -> 670.50205 | K28: =G28/$C$3-1 -> -0.23465257 | L28: =H28/$C$3-1 -> 0.26277226 | M28: =I28/$C$3-1 -> 0.43564556
A29: 11 | B29: =CONCATENATE("-Target Price @",ROUND(A29,0),"x EV/EBITDA") -> -Target Price @11x EV/EBITDA | C29: Rs./ share | D29: =(($A29*D$24)-Consolidated!J$65+Consolidated!J$98)/DCF!$C$4 -> 71.92663 | E29: =(($A29*E$24)-Consolidated!J$68+Consolidated!J$98)/DCF!$C$4 -> 94.714262 | F29: =(($A29*F$24)-Consolidated!K$68+Consolidated!K$98)/DCF!$C$4 -> 171.22222 | G29: =(($A29*G$24)-Consolidated!L$68+Consolidated!L$98)/DCF!$C$4 -> 332.06891 | H29: =(($A29*H$24)-Consolidated!M$68+Consolidated!M$98)/DCF!$C$4 -> 556.96863 | I29: =(($A29*I$24)-Consolidated!N$68+Consolidated!N$98)/DCF!$C$4 -> 654.0183 | J29: =(($A29*J$24)-Consolidated!O$68+Consolidated!O$98)/DCF!$C$4 -> 815.94706 | K29: =G29/$C$3-1 -> -0.10937668 | L29: =H29/$C$3-1 -> 0.49381422 | M29: =I29/$C$3-1 -> 0.75410567
A30: 12 | B30: =CONCATENATE("-Target Price @",ROUND(A30,0),"x EV/EBITDA") -> -Target Price @12x EV/EBITDA | C30: Rs./ share | D30: =(($A30*D$24)-Consolidated!J$65+Consolidated!J$98)/DCF!$C$4 -> 87.353989 | E30: =(($A30*E$24)-Consolidated!J$68+Consolidated!J$98)/DCF!$C$4 -> 112.21323 | F30: =(($A30*F$24)-Consolidated!K$68+Consolidated!K$98)/DCF!$C$4 -> 196.45416 | G30: =(($A30*G$24)-Consolidated!L$68+Consolidated!L$98)/DCF!$C$4 -> 378.77802 | H30: =(($A30*H$24)-Consolidated!M$68+Consolidated!M$98)/DCF!$C$4 -> 643.11263 | I30: =(($A30*I$24)-Consolidated!N$68+Consolidated!N$98)/DCF!$C$4 -> 772.75615 | J30: =(($A30*J$24)-Consolidated!O$68+Consolidated!O$98)/DCF!$C$4 -> 961.39206 | K30: =G30/$C$3-1 -> 0.015899219 | L30: =H30/$C$3-1 -> 0.72485619 | M30: =I30/$C$3-1 -> 1.0725658
B35: QUALIFIED INSTITUTIONS PLACEMENT — JUNE 2026
B36: Shares allotted | C36: 100.17889
B37: Issue price | C37: 279.5
B38: Face value | C38: 2
