Workbook

Sheet P&L
Z1: <<Do not Delete this>>
A2: P&L Statement (Rs. crore) | B2: FY05 | C2: FY06 | D2: FY07 | E2: FY08 | F2: FY09 | G2: FY10 | H2: FY11 | I2: FY12 | J2: FY13 | K2: FY14 | L2: FY15 | M2: FY16 | N2: FY17 | O2: FY18 | P2: FY19 | Q2: FY20 | R2: FY21 | S2: FY22 | T2: FY23 | U2: FY24 | V2: FY25 | W2: FY26 | X2: FY27E | Y2: FY28E | Z2: FY29E | AA2: FY30E
A3: Net Sales | B3: 7.792 | C3: 10.3419 | D3: 27.3333 | E3: 46.099 | F3: 68.8106 | G3: 20.1678 | H3: 64.1328 | I3: 45.3417 | J3: 55.3772 | K3: 121.8294 | L3: 140.833 | M3: 77.6676 | N3: 124.3162 | O3: 222.2229 | P3: 193.8552 | Q3: 273.1538 | R3: 228.7898 | S3: 260.4711 | T3: 109.9514 | U3: 305.0648 | V3: 465.0381 | W3: 791.0474
A4: Growth, % | C4: =+C$3/B$3-1 -> 0.32724589 | D4: =+D$3/C$3-1 -> 1.642967 | E4: =+E$3/D$3-1 -> 0.68655084 | F4: =+F$3/E$3-1 -> 0.49267012 | G4: =+G$3/F$3-1 -> -0.70690853 | H4: =+H$3/G$3-1 -> 2.1799601 | I4: =+I$3/H$3-1 -> -0.29300296 | J4: =+J$3/I$3-1 -> 0.22133048 | ... W4: =+W$3/V$3-1 -> 0.70103783
A5: EXPENDITURE
A6: (Increase)/Decrease in Stock | B6: -0.052 | C6: 0.145 | D6: -0.0882 | E6: -0.0097 | F6: 0 | G6: 0 | H6: 0 | I6: 0 | J6: 0 | K6: 0 | L6: 0 | M6: 0 | N6: 0 | O6: 0 | P6: 0 | Q6: 0 | R6: 0 | S6: 0 | T6: 0 | U6: -0.2901 | V6: 0.1123 | W6: -0.1147
A7: Raw Material Consumed | B7: 0.0087 | C7: 0 | D7: 0 | E7: 0 | F7: 0 | G7: 0 | H7: 0 | I7: 0 | J7: 0 | K7: 0 | L7: 0 | M7: 0 | N7: 0 | O7: 0 | P7: 0 | Q7: 0 | R7: 0 | S7: 0 | T7: 0 | U7: 0 | V7: 0 | W7: 0
A8: Variable Cost | B8: =+B6+B7 -> -0.0433 | C8: =+C6+C7 -> 0.145 | D8: =+D6+D7 -> -0.0882 | E8: =+E6+E7 -> -0.0097 | F8: =+F6+F7 -> 0 | G8: =+G6+G7 -> 0 | H8: =+H6+H7 -> 0 | I8: =+I6+I7 -> 0 | ... W8: =+W6+W7 -> -0.1147
A9: Gross Profit | B9: =+B3-B8 -> 7.8353 | C9: =+C3-C8 -> 10.1969 | D9: =+D3-D8 -> 27.4215 | E9: =+E3-E8 -> 46.1087 | F9: =+F3-F8 -> 68.8106 | G9: =+G3-G8 -> 20.1678 | H9: =+H3-H8 -> 64.1328 | I9: =+I3-I8 -> 45.3417 | ... W9: =+W3-W8 -> 791.1621
A10: Gross Margin | B10: =+B9/B3 -> 1.005557 | C10: =+C9/C3 -> 0.98597937 | D10: =+D9/D3 -> 1.0032268 | E10: =+E9/E3 -> 1.0002104 | F10: =+F9/F3 -> 1 | G10: =+G9/G3 -> 1 | H10: =+H9/H3 -> 1 | I10: =+I9/I3 -> 1 | ... W10: =+W9/W3 -> 1.000145
A11: Power & Fuel Cost | B11: 0.0113 | C11: 0.0094 | D11: 0.0116 | E11: 0.0255 | F11: 0.0309 | G11: 0.3433 | H11: 1.646 | I11: 1.7599 | J11: 2.6158 | K11: 2.1969 | L11: 4.7593 | M11: 2.2245 | N11: 0.6942 | O11: 0.8584 | P11: 0.312 | Q11: 0.1863 | R11: 1.7866 | S11: 5.4573 | T11: 1.3327 | U11: 1.4511 | V11: 1.2851 | W11: 1.1548
A12: Employee Cost | B12: 0.2009 | C12: 0.2546 | D12: 0.3882 | E12: 1.7489 | F12: 2.8866 | G12: 3.6939 | H12: 10.2307 | I12: 10.6574 | J12: 12.5705 | K12: 15.6098 | L12: 22.9595 | M12: 17.461 | N12: 22.5332 | O12: 36.9253 | P12: 20.67 | Q12: 10.0333 | R12: 14.2757 | S12: 21.8715 | T12: 28.5933 | U12: 26.4386 | V12: 12.0414 | W12: 42.1453
A13: Other Manufacturing Expenses | B13: 6.1584 | C13: 7.8543 | D13: 17.3593 | E13: 25.665 | F13: 41.3242 | G13: 7.8215 | H13: 33.6653 | I13: 24.7249 | J13: 26.798 | K13: 82.259 | L13: 82.6211 | M13: 65.832 | N13: 16.0951 | O13: 75.6539 | P13: 110.2722 | Q13: 114.4034 | R13: 100.9672 | S13: 139.0727 | T13: 69.9947 | U13: 213.5349 | V13: 357.764 | W13: 607.6703
A14: General & Administration Expenses | B14: 0.4848 | C14: 0.6543 | D14: 1.1644 | E14: 3.2133 | F14: 11.5349 | G14: 5.5573 | H14: 12.4569 | I14: 12.7854 | J14: 15.4689 | K14: 13.868 | L14: 34.7563 | M14: 11.611 | N14: 58.8604 | O14: 66.5208 | P14: 27.9345 | Q14: 78.3647 | R14: 54.8935 | S14: 23.7932 | T14: 24.1306 | U14: 19.6858 | V14: 24.8796 | W14: 40.1986
A15: Selling & Distribution Expenses | B15: 0.0055 | C15: 0.0067 | D15: 0.0082 | E15: 0.0665 | F15: 0.0805 | G15: 0.0385 | H15: 0.0844 | I15: 0.1426 | J15: 0.6493 | K15: 8.9887 | L15: 0.6303 | M15: 0.079 | N15: 0.0363 | O15: 0.5893 | P15: 0.1322 | Q15: 0.043 | R15: 0.3676 | S15: 0.9364 | T15: 0.5568 | U15: 0.0502 | V15: 0.0706 | W15: 0
A16: Miscellaneous Expenses | B16: 0.0715 | C16: 0.05 | D16: 0.0245 | E16: 0.1717 | F16: 2.8141 | G16: 0.2217 | H16: 0.434 | I16: 1.3735 | J16: 0.6088 | K16: 1.3881 | L16: 0.6164 | M16: 5.5169 | N16: 44.3675 | O16: 0.985 | P16: 1.659 | Q16: 3.5754 | R16: 1.017 | S16: 3.0004 | T16: 4.1132 | U16: 2.3774 | V16: 2.7771 | W16: 4.6372
A17: Total Expenditure | B17: =SUM(B11:B16)+B8 -> 6.8891 | C17: =SUM(C11:C16)+C8 -> 8.9743 | D17: =SUM(D11:D16)+D8 -> 18.868 | E17: =SUM(E11:E16)+E8 -> 30.8812 | F17: =SUM(F11:F16)+F8 -> 58.6712 | G17: =SUM(G11:G16)+G8 -> 17.6762 | H17: =SUM(H11:H16)+H8 -> 58.5173 | I17: =SUM(I11:I16)+I8 -> 51.4437 | ... W17: =SUM(W11:W16)+W8 -> 695.6915
A19: EBITDA | B19: =B3-B17 -> 0.9029 | C19: =C3-C17 -> 1.3676 | D19: =D3-D17 -> 8.4653 | E19: =E3-E17 -> 15.2178 | F19: =F3-F17 -> 10.1394 | G19: =G3-G17 -> 2.4916 | H19: =H3-H17 -> 5.6155 | I19: =I3-I17 -> -6.102 | ... W19: =W3-W17 -> 95.3559
A20: Growth, % | C20: =IF(B19<=0,"n.m.",C19/B19-1) -> 0.51467494 | D20: =IF(C19<=0,"n.m.",D19/C19-1) -> 5.1898947 | E20: =IF(D19<=0,"n.m.",E19/D19-1) -> 0.79766813 | F20: =IF(E19<=0,"n.m.",F19/E19-1) -> -0.33371447 | G20: =IF(F19<=0,"n.m.",G19/F19-1) -> -0.75426554 | H20: =IF(G19<=0,"n.m.",H19/G19-1) -> 1.2537727 | I20: =IF(H19<=0,"n.m.",I19/H19-1) -> -2.0866352 | J20: =IF(I19<=0,"n.m.",J19/I19-1) -> n.m. | ... W20: =IF(V19<=0,"n.m.",W19/V19-1) -> 0.44242603
A21: Margin, % | B21: =+B19/B3 -> 0.11587526 | C21: =+C19/C3 -> 0.13223876 | D21: =+D19/D3 -> 0.30970648 | E21: =+E19/E3 -> 0.33011128 | F21: =+F19/F3 -> 0.1473523 | G21: =+G19/G3 -> 0.12354347 | H21: =+H19/H3 -> 0.087560499 | I21: =+I19/I3 -> -0.1345781 | ... W21: =+W19/W3 -> 0.12054385
A22: Other Income | B22: 0.1154 | C22: 0.2014 | D22: 0.2641 | E22: 1.8369 | F22: 2.4831 | G22: 0.8703 | H22: 3.6072 | I22: 4.4322 | J22: 6.3341 | K22: 3.4691 | L22: 6.5486 | M22: 28.5242 | N22: 3.8944 | O22: 3.524 | P22: 3.9772 | Q22: 3.4683 | R22: 5.4203 | S22: 2.8284 | T22: 4.0969 | U22: 6.22 | V22: 5.4144 | W22: 8.8908
A23: Depreciation | B23: 0.3666 | C23: 0.3404 | D23: 0.6558 | E23: 2.0428 | F23: 3.9044 | G23: 3.5659 | H23: 8.6267 | I23: 8.5149 | J23: 8.8169 | K23: 14.1454 | L23: 18.1089 | M23: 17.7781 | N23: 15.13 | O23: 17.0268 | P23: 19.4427 | Q23: 19.6594 | R23: 23.3298 | S23: 27.6881 | T23: 21.9704 | U23: 17.0187 | V23: 17.7066 | W23: 18.8635
A24: EBIT | B24: =B19+B22-B23 -> 0.6517 | C24: =C19+C22-C23 -> 1.2286 | D24: =D19+D22-D23 -> 8.0736 | E24: =E19+E22-E23 -> 15.0119 | F24: =F19+F22-F23 -> 8.7181 | G24: =G19+G22-G23 -> -0.204 | H24: =H19+H22-H23 -> 0.596 | I24: =I19+I22-I23 -> -10.1847 | ... W24: =W19+W22-W23 -> 85.3832
A25: Interest | B25: 0.1478 | C25: 0.227 | D25: 0.5023 | E25: 1.0213 | F25: 0.6507 | G25: 0.3162 | H25: 1.0053 | I25: 2.3447 | J25: 3.1862 | K25: 9.4699 | L25: 9.4525 | M25: 10.8918 | N25: 7.6827 | O25: 6.3407 | P25: 5.7206 | Q25: 2.852 | R25: 0.7134 | S25: 0.8092 | T25: 2.4636 | U25: 2.0613 | V25: 3.8255 | W25: 10.6512
A26: Share of Profit/(Loss) of JVs & Associates | B26: 0 | C26: 0 | D26: 0 | E26: 0 | F26: 0 | G26: 0 | H26: 0 | I26: 0 | J26: 0 | K26: 0 | L26: 0 | M26: 0 | N26: 0 | O26: 0 | P26: 0 | Q26: 0 | R26: 0 | S26: 0 | T26: 0.611 | U26: 1.5713 | V26: 6.1866 | W26: 3.5077
A27: Exceptional Income / (Expenses) | B27: 0 | C27: 0 | D27: -0.7947 | E27: -0.3402 | F27: 0 | G27: 0 | H27: -6.9808 | I27: -0.7394 | J27: -1.3842 | K27: -0.7823 | L27: -0.4492 | M27: 0 | N27: 19.1894 | O27: -10.3411 | P27: -2.5077 | Q27: -6.8655 | R27: -12.3446 | S27: 0 | T27: -6.0685 | U27: -1.851 | V27: 0 | W27: -9.4031
A28: PBT | B28: =+B24-B25+B26+B27 -> 0.5039 | C28: =+C24-C25+C26+C27 -> 1.0016 | D28: =+D24-D25+D26+D27 -> 6.7766 | E28: =+E24-E25+E26+E27 -> 13.6504 | F28: =+F24-F25+F26+F27 -> 8.0674 | G28: =+G24-G25+G26+G27 -> -0.5202 | H28: =+H24-H25+H26+H27 -> -7.3901 | I28: =+I24-I25+I26+I27 -> -13.2688 | ... W28: =+W24-W25+W26+W27 -> 68.8366
A29: Provision for Tax | B29: 0.1848 | C29: 0.3805 | D29: 2.4813 | E29: 4.0278 | F29: 2.8156 | G29: 0.3766 | H29: 0.1551 | I29: -4.2264 | J29: -0.0926 | K29: 0.0181 | L29: 0.039 | M29: 1.8531 | N29: 0.2052 | O29: 0.2017 | P29: 0.0808 | Q29: 11.4037 | R29: 1.9432 | S29: 1.8596 | T29: -0.1223 | U29: 3.1297 | V29: 14.0133 | W29: 16.9979
A30: Tax Rate % | B30: =IF(B28<=0,"n.m.",B29/B28) -> 0.36673943 | C30: =IF(C28<=0,"n.m.",C29/C28) -> 0.37989217 | D30: =IF(D28<=0,"n.m.",D29/D28) -> 0.36615707 | E30: =IF(E28<=0,"n.m.",E29/E28) -> 0.29506828 | F30: =IF(F28<=0,"n.m.",F29/F28) -> 0.34900959 | G30: =IF(G28<=0,"n.m.",G29/G28) -> n.m. | H30: =IF(H28<=0,"n.m.",H29/H28) -> n.m. | I30: =IF(I28<=0,"n.m.",I29/I28) -> n.m. | ... W30: =IF(W28<=0,"n.m.",W29/W28) -> 0.24693114
A31: PAT | B31: =+B28-B29 -> 0.3191 | C31: =+C28-C29 -> 0.6211 | D31: =+D28-D29 -> 4.2953 | E31: =+E28-E29 -> 9.6226 | F31: =+F28-F29 -> 5.2518 | G31: =+G28-G29 -> -0.8968 | H31: =+H28-H29 -> -7.5452 | I31: =+I28-I29 -> -9.0424 | ... W31: =+W28-W29 -> 51.8387
A32: Less: Minority Interest | B32: 0 | C32: 0 | D32: 0 | E32: 0 | F32: 0 | G32: 0 | H32: 0 | I32: 0 | J32: 0 | K32: 0 | L32: 0 | M32: 0 | N32: 0 | O32: 0 | P32: 0 | Q32: 0 | R32: 0 | S32: 0 | T32: -0.0852 | U32: 0.0802 | V32: 0.0405 | W32: 0.6816
A33: PAT attributable to owners | B33: =+B31-B32 -> 0.3191 | C33: =+C31-C32 -> 0.6211 | D33: =+D31-D32 -> 4.2953 | E33: =+E31-E32 -> 9.6226 | F33: =+F31-F32 -> 5.2518 | G33: =+G31-G32 -> -0.8968 | H33: =+H31-H32 -> -7.5452 | I33: =+I31-I32 -> -9.0424 | ... W33: =+W31-W32 -> 51.1571
A34: Growth, % | C34: =IF(B33<=0,"n.m.",C33/B33-1) -> 0.94641178 | D34: =IF(C33<=0,"n.m.",D33/C33-1) -> 5.9156336 | E34: =IF(D33<=0,"n.m.",E33/D33-1) -> 1.2402626 | F34: =IF(E33<=0,"n.m.",F33/E33-1) -> -0.45422235 | G34: =IF(F33<=0,"n.m.",G33/F33-1) -> -1.1707605 | H34: =IF(G33<=0,"n.m.",H33/G33-1) -> n.m. | I34: =IF(H33<=0,"n.m.",I33/H33-1) -> n.m. | J34: =IF(I33<=0,"n.m.",J33/I33-1) -> n.m. | ... W34: =IF(V33<=0,"n.m.",W33/V33-1) -> 0.21446665
A35: Margin, % | B35: =+B33/B3 -> 0.040952259 | C35: =+C33/C3 -> 0.060056663 | D35: =+D33/D3 -> 0.15714531 | E35: =+E33/E3 -> 0.20873772 | F35: =+F33/F3 -> 0.076322543 | G35: =+G33/G3 -> -0.044466923 | H35: =+H33/H3 -> -0.11764963 | I35: =+I33/I3 -> -0.1994279 | ... W35: =+W33/W3 -> 0.064670082
A36: No. of Shares (crore) | B36: =B43/10 -> 0.53571 | C36: =C43/10 -> 0.53571 | D36: =D43/10 -> 0.70071 | E36: =E43/10 -> 1.046 | F36: =F43/10 -> 1.12744 | G36: =G43/10 -> 1.53244 | H36: =H43/10 -> 1.53244 | I36: =I43/10 -> 1.53244 | ... W36: =W43/10 -> 4.49175
A37: EPS (Rs.) | B37: =+B33/B36 -> 0.5956581 | C37: =+C33/C36 -> 1.1593959 | D37: =+D33/D36 -> 6.1299254 | E37: =+E33/E36 -> 9.1994264 | F37: =+F33/F36 -> 4.6581636 | G37: =+G33/G36 -> -0.58521051 | H37: =+H33/H36 -> -4.9236512 | I37: =+I33/I36 -> -5.9006552 | ... W37: =+W33/W36 -> 11.389125
A38: Dividend (Rs. crore) | B38: =+B36*B39 -> 0 | C38: =+C36*C39 -> 0 | D38: =+D36*D39 -> 0 | E38: =+E36*E39 -> 0 | F38: =+F36*F39 -> 0 | G38: =+G36*G39 -> 0 | H38: =+H36*H39 -> 0 | I38: =+I36*I39 -> 0 | ... W38: =+W36*W39 -> 5.6146875
A39: DPS | B39: 0 | C39: 0 | D39: 0 | E39: 0 | F39: 0 | G39: 0 | H39: 0 | I39: 0 | J39: 0 | K39: 0 | L39: 0 | M39: 0 | N39: 0 | O39: 0 | P39: 0 | Q39: 0 | R39: 0 | S39: 0 | T39: 0 | U39: 0 | V39: 1 | W39: 1.25
A41: Balance Sheet (Rs. crore) | B41: =B$2 -> FY05 | C41: =C$2 -> FY06 | D41: =D$2 -> FY07 | E41: =E$2 -> FY08 | F41: =F$2 -> FY09 | G41: =G$2 -> FY10 | H41: =H$2 -> FY11 | I41: =I$2 -> FY12 | ... AA41: =AA$2 -> FY30E
A42: EQUITY AND LIABILITIES
...

Sheet Segments
A1: Segment Data (Rs. cr) - Ind AS 108, consolidated | B1: FY21 | C1: FY22 | D1: FY23 | E1: FY24 | F1: FY25 | G1: FY26 | H1: FY27E | I1: FY28E | J1: FY29E | K1: FY30E
A3: Revenue
A4: Oil & Gas services revenue | B4: 221.91 | C4: 188.87 | D4: 63.22 | E4: 191.91 | F4: 192.44 | G4: 632.68
A5: Growth, % | C5: =+C4/B4-1 -> -0.14888919 | D5: =+D4/C4-1 -> -0.66527241 | E5: =+E4/D4-1 -> 2.03559 | F5: =+F4/E4-1 -> 0.0027617112 | G5: =+G4/F4-1 -> 2.2876741
A6: Mineral & other energy (coal CHP, power) revenue | B6: 6.88 | C6: 71.6 | D6: 46.73 | E6: 113.16 | F6: 272.59 | G6: 158.37
A7: Growth, % | C7: =IF(B6<=0,"n.m.",C6/B6-1) -> 9.4069767 | D7: =IF(C6<=0,"n.m.",D6/C6-1) -> -0.34734637 | E7: =IF(D6<=0,"n.m.",E6/D6-1) -> 1.4215707 | F7: =IF(E6<=0,"n.m.",F6/E6-1) -> 1.4088901 | G7: =IF(F6<=0,"n.m.",G6/F6-1) -> -0.41901757
A8: Total Segment Revenue | B8: =+B6+B4 -> 228.79 | C8: =+C6+C4 -> 260.47 | D8: =+D6+D4 -> 109.95 | E8: =+E6+E4 -> 305.07 | F8: =+F6+F4 -> 465.03 | G8: =+G6+G4 -> 791.05
A9: Oil & Gas share of revenue | B9: =+B4/B8 -> 0.96992876 | C9: =+C4/C8 -> 0.7251123 | D9: =+D4/D8 -> 0.57498863 | E9: =+E4/E8 -> 0.62906874 | F9: =+F4/F8 -> 0.41382276 | G9: =+G4/G8 -> 0.79979774
A10: Check vs P&L Net Sales | B10: =ROUND(B8-'P&L'!R3,1) -> 0 | C10: =ROUND(C8-'P&L'!S3,1) -> 0 | D10: =ROUND(D8-'P&L'!T3,1) -> 0 | E10: =ROUND(E8-'P&L'!U3,1) -> 0 | F10: =ROUND(F8-'P&L'!V3,1) -> 0 | G10: =ROUND(G8-'P&L'!W3,1) -> 0
A12: SEGMENT RESULT (EBITDA level: before D&A, finance cost, other income, unallocable)
A13: Oil & Gas result | B13: 77.79 | C13: 54.52 | D13: -0.3 | E13: 40.97 | F13: 33.05 | G13: 101.96
A14: Mineral & other energy result | B14: -3.8 | C14: 32.96 | D14: 6.73 | E14: 18.63 | F14: 58.87 | G14: 31.6
A15: Total segment result | B15: =SUM(B13:B14) -> 73.99 | C15: =SUM(C13:C14) -> 87.48 | D15: =SUM(D13:D14) -> 6.43 | E15: =SUM(E13:E14) -> 59.6 | F15: =SUM(F13:F14) -> 91.92 | G15: =SUM(G13:G14) -> 133.56
A16: Less: Depreciation & amortisation | B16: 23.33 | C16: 27.69 | D16: 21.97 | E16: 17.02 | F16: 17.71 | G16: 18.86
A17: Add: Other income | B17: 5.42 | C17: 2.83 | D17: 4.1 | E17: 6.22 | F17: 5.41 | G17: 8.89
A18: Less: Finance costs | B18: 0.71 | C18: 0.81 | D18: 2.46 | E18: 2.06 | F18: 3.83 | G18: 10.65
A19: Less: Other unallocable expenses (corporate staff, admin) | B19: 18.5 | C19: 21.14 | D19: 25.2 | E19: 17.79 | F19: 25.81 | G19: 38.2
A20: Profit before JV share, exceptional items and tax | B20: =+B15-B16+B17-B18-B19 -> 36.87 | C20: =+C15-C16+C17-C18-C19 -> 40.67 | D20: =+D15-D16+D17-D18-D19 -> -39.1 | E20: =+E15-E16+E17-E18-E19 -> 28.95 | F20: =+F15-F16+F17-F18-F19 -> 49.98 | G20: =+G15-G16+G17-G18-G19 -> 74.74
A22: SEGMENT MARGINS (Result/Revenue)
A23: Oil & Gas margin % | B23: =IF(B4=0,"n.m.",B13/B4) -> 0.35054752 | C23: =IF(C4=0,"n.m.",C13/C4) -> 0.28866416 | D23: =IF(D4=0,"n.m.",D13/D4) -> -0.0047453338 | E23: =IF(E4=0,"n.m.",E13/E4) -> 0.21348549 | F23: =IF(F4=0,"n.m.",F13/F4) -> 0.17174184 | G23: =IF(G4=0,"n.m.",G13/G4) -> 0.16115572
A24: Mineral & other energy margin % | B24: =IF(B6=0,"n.m.",B14/B6) -> -0.55232558 | C24: =IF(C6=0,"n.m.",C14/C6) -> 0.4603352 | D24: =IF(D6=0,"n.m.",D14/D6) -> 0.14401883 | E24: =IF(E6=0,"n.m.",E14/E6) -> 0.16463415 | F24: =IF(F6=0,"n.m.",F14/F6) -> 0.21596537 | G24: =IF(G6=0,"n.m.",G14/G6) -> 0.19953274
A25: Blended segment margin % | B25: =+B15/B8 -> 0.323397 | C25: =+C15/C8 -> 0.33585442 | D25: =+D15/D8 -> 0.058481128 | E25: =+E15/E8 -> 0.195365 | F25: =+F15/F8 -> 0.19766467 | G25: =+G15/G8 -> 0.16883889
A27: Segment capital employed
A28: Not disclosed: the CODM does not review assets and liabilities by segment (AR FY26 Note 45 VII; same wording FY22-FY25).
A30: Geography and concentration (Rs. cr)
A31: Revenue outside India | F31: 0 | G31: 299.37
A32: Revenue from top customer | F32: 112.7 | G32: 142.96
A33: Revenue from top three customers | F33: 246.6 | G33: 264.36
A34: Customers >10% of revenue (number) | F34: 4 | G34: 3
A36: Sources: AR FY22 Note (segment), AR FY24 Note (segment, FY23 comparatives), AR FY26 Note 45 (FY25 & FY26). FY21 from AR FY22 comparatives. All converted from Rs. lakh. Segment definitions: (i) Oil & Gas = services to oil & gas customers (seismic, O&M, drilling services, E&P-related, Kuiper international O&M from FY26); (ii) Mineral & other energy = coal handling plants and other energy EPC/O&M (CIL subsidiaries, SCCL, power).
A37: FY27E-FY30E columns are for Stage 3 (forecast by order book x execution), not filled in Stage 1.

Sheet Valuations
B2: CMP | C2: 455 | D2: BSE close 16-Oct-2026 (ACE price sheet). Replace with Bloomberg CMP and date at Stage 3.
B3: No of Shares (crore) | C3: ='P&L'!W36 -> 4.49175 | D3: FY26 year-end; +0.37cr shares issued on warrant conversion in May-2026 not yet included.
B4: Market Cap (Rs. crore) | C4: =C2*C3 -> 2043.7462
B6: Asian Energy Services - Valuation Matrix
D7: FY26 | E7: FY27E | F7: FY28E | G7: FY29E | H7: FY30E
B8: EV/EBITDA methodology
B9: Consolidated EBITDA | C9: Rs. crore | D9: ='P&L'!W19 -> 95.3559 | E9: ='P&L'!X19 -> 0 | F9: ='P&L'!Y19 -> 0 | G9: ='P&L'!Z19 -> 0 | H9: ='P&L'!AA19 -> 0
B10: Net Debt: -ve implies Net Cash | D10: ='P&L'!W200 -> 11.2727 | E10: ='P&L'!X200 -> 0 | F10: ='P&L'!Y200 -> 0 | G10: ='P&L'!Z200 -> 0 | H10: ='P&L'!AA200 -> 0
B11: =CONCATENATE("-@CMP of Rs.",ROUND($C$2,0),"/share") -> -@CMP of Rs.455/share | C11: implied EV/EBITDA | D11: =IF(D9<=0,"",($C$4+D10)/D9) -> 21.551041 | E11: =IF(E9<=0,"",($C$4+E10)/E9) | F11: =IF(F9<=0,"",($C$4+F10)/F9) | G11: =IF(G9<=0,"",($C$4+G10)/G9) | H11: =IF(H9<=0,"",($C$4+H10)/H9)
A12: 8 | B12: =CONCATENATE("-Target Price @",ROUND(A12,0),"x EV/EBITDA") -> -Target Price @8x EV/EBITDA | C12: Rs./ share | E12: =IF(E$9<=0,"",((E$9*$A12)-(E$10))/$C$3) | F12: =IF(F$9<=0,"",((F$9*$A12)-(F$10))/$C$3) | G12: =IF(G$9<=0,"",((G$9*$A12)-(G$10))/$C$3) | H12: =IF(H$9<=0,"",((H$9*$A12)-(H$10))/$C$3)
A13: 10 | B13: =CONCATENATE("-Target Price @",ROUND(A13,0),"x EV/EBITDA") -> -Target Price @10x EV/EBITDA | C13: Rs./ share | E13: =IF(E$9<=0,"",((E$9*$A13)-(E$10))/$C$3) | F13: =IF(F$9<=0,"",((F$9*$A13)-(F$10))/$C$3) | G13: =IF(G$9<=0,"",((G$9*$A13)-(G$10))/$C$3) | H13: =IF(H$9<=0,"",((H$9*$A13)-(H$10))/$C$3)
A14: 12 | B14: =CONCATENATE("-Target Price @",ROUND(A14,0),"x EV/EBITDA") -> -Target Price @12x EV/EBITDA | C14: Rs./ share | E14: =IF(E$9<=0,"",((E$9*$A14)-(E$10))/$C$3) | F14: =IF(F$9<=0,"",((F$9*$A14)-(F$10))/$C$3) | G14: =IF(G$9<=0,"",((G$9*$A14)-(G$10))/$C$3) | H14: =IF(H$9<=0,"",((H$9*$A14)-(H$10))/$C$3)
B15: Upside / (downside) at 12x | E15: =IF(E14="","",E14/$C$2-1) | F15: =IF(F14="","",F14/$C$2-1) | G15: =IF(G14="","",G14/$C$2-1) | H15: =IF(H14="","",H14/$C$2-1)
B17: Trailing context (FY26A, at CMP)
B18: P/E on FY26 EPS | C18: =$C$2/'P&L'!W37 -> 39.950393
B19: P/B on FY26 book value | C19: =$C$4/'P&L'!W46 -> 4.1358572
B20: EV/Sales on FY26 | C20: =($C$4+D10)/'P&L'!W3 -> 2.5978455
B22: Stage 3 will add: peer table, EV-to-equity bridge (net debt at FY26 year-end, minorities, probable contingent liabilities), bull/base/bear with different operating assumptions, reverse check of CMP. Multiples in column A are placeholders, not a view.

Sheet Notes
A1: BASIS
A2: Entity / basis | B2: Asian Energy Services Ltd (NSE: ASIANENE, BSE: 530355). Consolidated basis for FY09-FY26 from the ACE Equity consolidated dump (received 18-Oct-2026). FY05-FY08 are STANDALONE ACE data (consolidated series not available) and are shaded orange; they are not comparable with FY09+.
A3: Why consolidated | B3: Standalone is misleading for this company: FY26 consolidated revenue Rs.791cr vs standalone Rs.492cr (Kuiper, DMCC and other subsidiaries); FY15 consolidated Rs.141cr vs standalone Rs.1.4cr (Kurdistan contracts sat in the DMCC subsidiary). See reconciliation below.
A4: Units / style | B4: Rs. crore. Blue = hardcoded from source; black = formula; orange fill = standalone-basis column. Cell comments on row labels explain mapping choices.
A6: DISCONTINUITIES (never spliced over)
A7: FY08 / FY09 / FY10 periods | B7: Financial-year change: FY08 is a 15-month period to 30-Jun-2008 (standalone); FY09 is 12 months to 30-Jun-2009; FY10 is 9 months to 31-Mar-2010 (ACE "No of months" row). Growth rates across FY07-FY11 are therefore not like-for-like.
A8: FY16 -> FY17 GAAP change | B8: Indian GAAP up to FY16; Ind AS from FY17 (FY17 AR presents FY16 restated under Ind AS). ACE carries the originally reported basis for each year.
A9: FY17 promoter change | B9: Oilmax Energy Pvt Ltd (Kapil Garg) acquired control in FY17 via preferential issue (Rs.88.6cr equity raised in FY17, Rs.48cr in FY18). Business re-based from this point; large ESOP charges in FY17-FY18 and FY21 (Rs.43cr, Rs.29cr, Rs.30cr per AR cash-flow notes) depress reported PAT in those years.
A10: FY23 reclassification | B10: FY24 AR restated FY23 expense lines: employee benefits Rs.28.68cr (own-year AR Rs.28.59cr) and other expenses Rs.18.82cr (Rs.18.91cr). Totals unchanged. ACE carries the FY23 AR version.
A11: FY19 cash-flow restatement | B11: FY19 AR: operating cash flow Rs.34.8cr, closing cash Rs.2.97cr. FY20 AR comparatives: Rs.26.9cr and Rs.0.97cr (bank overdraft netted / reclassification). ACE uses the FY19 AR figures.
A12: FY21 cash-flow restatement | B12: FY21 AR: operating cash flow Rs.-17.5cr, closing cash Rs.12.1cr. FY22 AR comparatives: Rs.-6.8cr and Rs.22.7cr. Check which version ACE carries before relying on FY21 cash conversion.
A13: FY26 Kuiper consolidation | B13: Kuiper Holdings / Kuiper Group (international O&M, acquired Apr-2025 for Rs.122.8cr net cash paid; Rs.72.1cr cash acquired) consolidated from acquisition date. Adds Rs.299cr of revenue outside India in FY26 (AR FY26 Note 45 III). FY26 vs FY25 growth is therefore mostly inorganic.
A14: Post-FY26 share count | B14: May-2026: 36.6 lakh shares issued on warrant conversion (Rs.92cr). Diluted count for valuation = 4.49cr + 0.37cr = 4.86cr. Not yet in the model.
A15: Oilmax merger (pending) | B15: Scheme of merger by absorption of Oilmax Energy Pvt Ltd (promoter entity, E&P assets) into AESL: NCLT final order 29-Sep-2026, certified copy received 15-Oct-2026. Will change share count, segment mix (adds E&P) and related-party profile from FY27. Not in historicals.
A17: STANDALONE vs CONSOLIDATED (Rs. crore)
A18: Year | B18: Standalone revenue | C18: Consolidated revenue | D18: Standalone PAT | E18: Consolidated PAT | F18: Standalone net worth | G18: Consolidated net worth
A19: FY26 | B19: 491.8 | C19: 791 | D19: 44.8 | E19: 51.8 | F19: 447.6 | G19: 494.2
A20: FY25 | B20: 464.1 | C20: 465 | D20: 41 | E20: 42.2 | F20: 396.7 | G20: 398.7
A21: FY24 | B21: 305.1 | C21: 305.1 | D21: 28.7 | E21: 25.5 | F21: 276.5 | G21: 277.9
A22: FY23 | B22: 109.9 | C22: 110 | D22: -29.3 | E22: -44.4 | F22: 193.6 | G22: 199.5
A23: FY22 | B23: 254.1 | C23: 260.5 | D23: 62.8 | E23: 38.8 | F23: 222 | G23: 241.8
A24: FY21 | B24: 140.7 | C24: 228.8 | D24: 21.6 | E24: 22.6 | F24: 160.8 | G24: 203.4
A25: FY20 | B25: 64.5 | C25: 273.2 | D25: 4.7 | E25: 29.2 | F25: 138.9 | G25: 181.5
A26: FY19 | B26: 156.8 | C26: 193.9 | D26: 1.6 | E26: 9.1 | F26: 136.8 | G26: 152
A27: FY18 | B27: 95.7 | C27: 222.2 | D27: -20.7 | E27: 10.3 | F27: 134.5 | G27: 140.5
A28: FY17 | B28: 43.4 | C28: 124.3 | D28: 0.8 | E28: -18.2 | F28: 106.8 | G28: 81.8
A29: FY16 | B29: 9.4 | C29: 77.7 | D29: -29.4 | E29: -27.1 | F29: 17.4 | G29: 10.1
A30: FY15 | B30: 1.4 | C30: 140.8 | D30: -16.8 | E30: -27 | F30: 46.8 | G30: 37.2
... A36: FY09 | B36: 68.8 | C36: 68.8 | D36: 5.3 | E36: 5.3 | F36: 75.1 | G36: 77.9
A39: SOURCES
A40: ACE consolidated dump | B40: Sheets: P&L (schedules), Balance Sheet (schedules), Cash Flow, Ratios, Valuation ratios. FY09-FY26. Tag [S] secondary, verified against [A] audited ARs for FY16-FY26 on revenue, PBT, PAT, total assets, OCF, closing cash (all tie).
A41: ACE standalone dump | B41: Used only for FY05-FY08 columns and the reconciliation table above. Also source of DPS and the share-price row (BSE daily closes to 16-Oct-2026).
A42: Annual reports | B42: AR FY16-FY26 (company website) for segment note (Ind AS 108), restatement checks, acquisition and ESOP details. AR FY15 text is font-garbled in the PDF and was not used.
A43: Document repository | B43: Full filing set (annual reports, results, decks, transcripts, orders, merger documents) in the two zips delivered 18-Oct-2026; see their README for coverage.
A45: LAYOUT CHANGES vs SAMPLE
A46: Rows added | B46: P&L: Share of Profit/(Loss) of JVs; Less: Minority Interest; PAT attributable to owners. Cash flow: Acquisition of Subsidiaries; Cash acquired on acquisition / FX. Working capital: Debtor + Unbilled Days. Key ratios: current-maturities memo, ROCE ex-cash, asset and gross-block turns, capex/depreciation. All other rows, formulas and formats follow the sample.
A47: Raw material row | B47: ACE reports no raw-material cost for a services company, so Variable Cost = stock change only and Gross Margin is near 100%. The economically meaningful variable cost is Other Manufacturing Expenses (project-related costs). Read EBITDA margin, not gross margin.
